[2022-04-27 20:19:38,027] INFO in _internal:  * Running on http://127.0.0.1:5000/ (Press CTRL+C to quit)
[2022-04-27 20:19:38,029] INFO in _internal:  * Restarting with stat
[2022-04-27 20:25:55,454] INFO in _internal:  * Running on http://127.0.0.1:5000/ (Press CTRL+C to quit)
[2022-04-27 20:25:55,455] INFO in _internal:  * Restarting with stat
[2022-04-27 20:30:33,100] INFO in _internal:  * Restarting with stat
INFO:werkzeug: * Running on http://127.0.0.1:5000/ (Press CTRL+C to quit)
INFO:werkzeug: * Running on http://127.0.0.1:5000/ (Press CTRL+C to quit)
INFO:werkzeug:127.0.0.1 - - [28/Apr/2022 16:26:45] "GET / HTTP/1.1" 200 -
INFO:werkzeug:127.0.0.1 - - [28/Apr/2022 16:26:45] "[36mGET /static/img/riot.png HTTP/1.1[0m" 304 -
INFO:werkzeug:127.0.0.1 - - [28/Apr/2022 16:26:46] "[33mGET /favicon.ico HTTP/1.1[0m" 404 -
DEBUG:urllib3.connectionpool:Starting new HTTPS connection (1): kr.api.riotgames.com:443
DEBUG:urllib3.connectionpool:https://kr.api.riotgames.com:443 "GET /lol/summoner/v4/summoners/by-name/%ED%95%AB%EC%83%81%EB%B2%94 HTTP/1.1" 403 None
DEBUG:urllib3.connectionpool:Starting new HTTPS connection (1): kr.api.riotgames.com:443
DEBUG:urllib3.connectionpool:https://kr.api.riotgames.com:443 "GET /lol/summoner/v4/summoners/by-name/%ED%95%AB%EC%83%81%EB%B2%94 HTTP/1.1" 200 None
DEBUG:urllib3.connectionpool:Starting new HTTPS connection (1): kr.api.riotgames.com:443
DEBUG:urllib3.connectionpool:https://kr.api.riotgames.com:443 "GET /lol/spectator/v4/active-games/by-summoner/XnhdEBDrdxzLMqJVhZBnhh6PI5WHJcbU7JZMncss1JBPiw HTTP/1.1" 403 None
DEBUG:urllib3.connectionpool:Starting new HTTPS connection (1): kr.api.riotgames.com:443
DEBUG:urllib3.connectionpool:https://kr.api.riotgames.com:443 "GET /lol/spectator/v4/active-games/by-summoner/XnhdEBDrdxzLMqJVhZBnhh6PI5WHJcbU7JZMncss1JBPiw HTTP/1.1" 503 None
ERROR:app:Exception on /result [GET]
Traceback (most recent call last):
  File "/Users/piat/opt/anaconda3/envs/cp1/lib/python3.8/site-packages/flask/app.py", line 2070, in wsgi_app
    response = self.full_dispatch_request()
  File "/Users/piat/opt/anaconda3/envs/cp1/lib/python3.8/site-packages/flask/app.py", line 1515, in full_dispatch_request
    rv = self.handle_user_exception(e)
  File "/Users/piat/opt/anaconda3/envs/cp1/lib/python3.8/site-packages/flask/app.py", line 1513, in full_dispatch_request
    rv = self.dispatch_request()
  File "/Users/piat/opt/anaconda3/envs/cp1/lib/python3.8/site-packages/flask/app.py", line 1499, in dispatch_request
    return self.ensure_sync(self.view_functions[rule.endpoint])(**req.view_args)
  File "/Users/piat/s5/cp1/New/app/views/main_views.py", line 114, in result
    summoner_Id = data['participants'][i]['summonerId']
KeyError: 'participants'
INFO:werkzeug:127.0.0.1 - - [28/Apr/2022 16:27:03] "[35m[1mGET /result?username=Ìï´ÏÉÅÎ≤î HTTP/1.1[0m" 500 -
INFO:werkzeug: * Running on http://127.0.0.1:5000/ (Press CTRL+C to quit)
DEBUG:urllib3.connectionpool:Starting new HTTPS connection (1): kr.api.riotgames.com:443
DEBUG:urllib3.connectionpool:https://kr.api.riotgames.com:443 "GET /lol/summoner/v4/summoners/by-name/%ED%95%AB%EC%83%81%EB%B2%94 HTTP/1.1" 200 None
DEBUG:urllib3.connectionpool:Starting new HTTPS connection (1): kr.api.riotgames.com:443
DEBUG:urllib3.connectionpool:https://kr.api.riotgames.com:443 "GET /lol/summoner/v4/summoners/by-name/%ED%95%AB%EC%83%81%EB%B2%94 HTTP/1.1" 200 None
DEBUG:urllib3.connectionpool:Starting new HTTPS connection (1): kr.api.riotgames.com:443
DEBUG:urllib3.connectionpool:https://kr.api.riotgames.com:443 "GET /lol/spectator/v4/active-games/by-summoner/XnhdEBDrdxzLMqJVhZBnhh6PI5WHJcbU7JZMncss1JBPiw HTTP/1.1" 503 None
INFO:werkzeug:127.0.0.1 - - [28/Apr/2022 16:33:20] "GET /result?username=Ìï´ÏÉÅÎ≤î HTTP/1.1" 200 -
INFO:werkzeug:127.0.0.1 - - [28/Apr/2022 16:33:20] "[36mGET /static/img/riot.png HTTP/1.1[0m" 304 -
INFO:werkzeug:127.0.0.1 - - [28/Apr/2022 16:33:23] "GET / HTTP/1.1" 200 -
INFO:werkzeug:127.0.0.1 - - [28/Apr/2022 16:33:23] "[36mGET /static/img/riot.png HTTP/1.1[0m" 304 -
INFO:werkzeug: * Running on http://127.0.0.1:5000/ (Press CTRL+C to quit)
INFO:werkzeug:127.0.0.1 - - [28/Apr/2022 17:19:33] "GET / HTTP/1.1" 200 -
INFO:werkzeug:127.0.0.1 - - [28/Apr/2022 17:19:33] "[36mGET /static/img/riot.png HTTP/1.1[0m" 304 -
DEBUG:urllib3.connectionpool:Starting new HTTPS connection (1): kr.api.riotgames.com:443
DEBUG:urllib3.connectionpool:https://kr.api.riotgames.com:443 "GET /lol/summoner/v4/summoners/by-name/%ED%95%AB%EC%83%81%EB%B2%94 HTTP/1.1" 200 None
DEBUG:urllib3.connectionpool:Starting new HTTPS connection (1): kr.api.riotgames.com:443
DEBUG:urllib3.connectionpool:https://kr.api.riotgames.com:443 "GET /lol/summoner/v4/summoners/by-name/%ED%95%AB%EC%83%81%EB%B2%94 HTTP/1.1" 200 None
DEBUG:urllib3.connectionpool:Starting new HTTPS connection (1): kr.api.riotgames.com:443
DEBUG:urllib3.connectionpool:https://kr.api.riotgames.com:443 "GET /lol/spectator/v4/active-games/by-summoner/XnhdEBDrdxzLMqJVhZBnhh6PI5WHJcbU7JZMncss1JBPiw HTTP/1.1" 503 None
INFO:werkzeug:127.0.0.1 - - [28/Apr/2022 17:19:46] "GET /result?username=Ìï´ÏÉÅÎ≤î HTTP/1.1" 200 -
INFO:werkzeug:127.0.0.1 - - [28/Apr/2022 17:19:46] "[36mGET /static/img/riot.png HTTP/1.1[0m" 304 -
INFO:werkzeug: * Running on http://127.0.0.1:5000/ (Press CTRL+C to quit)
ERROR:app:Exception on /result [GET]
Traceback (most recent call last):
  File "/Users/piat/opt/anaconda3/envs/cp1/lib/python3.8/site-packages/flask/app.py", line 2070, in wsgi_app
    response = self.full_dispatch_request()
  File "/Users/piat/opt/anaconda3/envs/cp1/lib/python3.8/site-packages/flask/app.py", line 1515, in full_dispatch_request
    rv = self.handle_user_exception(e)
  File "/Users/piat/opt/anaconda3/envs/cp1/lib/python3.8/site-packages/flask/app.py", line 1513, in full_dispatch_request
    rv = self.dispatch_request()
  File "/Users/piat/opt/anaconda3/envs/cp1/lib/python3.8/site-packages/flask/app.py", line 1499, in dispatch_request
    return self.ensure_sync(self.view_functions[rule.endpoint])(**req.view_args)
  File "/Users/piat/s5/cp1/New/app/views/main_views.py", line 63, in result
    from riot_api.name import sumoners
  File "/Users/piat/s5/cp1/New/riot_api/name.py", line 1, in <module>
    from api import *
ModuleNotFoundError: No module named 'api'
INFO:werkzeug:127.0.0.1 - - [28/Apr/2022 17:45:41] "[35m[1mGET /result?username=Ìï´ÏÉÅÎ≤î HTTP/1.1[0m" 500 -
ERROR:app:Exception on /result [GET]
Traceback (most recent call last):
  File "/Users/piat/opt/anaconda3/envs/cp1/lib/python3.8/site-packages/flask/app.py", line 2070, in wsgi_app
    response = self.full_dispatch_request()
  File "/Users/piat/opt/anaconda3/envs/cp1/lib/python3.8/site-packages/flask/app.py", line 1515, in full_dispatch_request
    rv = self.handle_user_exception(e)
  File "/Users/piat/opt/anaconda3/envs/cp1/lib/python3.8/site-packages/flask/app.py", line 1513, in full_dispatch_request
    rv = self.dispatch_request()
  File "/Users/piat/opt/anaconda3/envs/cp1/lib/python3.8/site-packages/flask/app.py", line 1499, in dispatch_request
    return self.ensure_sync(self.view_functions[rule.endpoint])(**req.view_args)
  File "/Users/piat/s5/cp1/New/app/views/main_views.py", line 72, in result
    m = url_check(url_nick)
NameError: name 'url_check' is not defined
INFO:werkzeug:127.0.0.1 - - [28/Apr/2022 17:47:56] "[35m[1mGET /result?username=Ìï´ÏÉÅÎ≤î HTTP/1.1[0m" 500 -
ERROR:app:Exception on /result [GET]
Traceback (most recent call last):
  File "/Users/piat/opt/anaconda3/envs/cp1/lib/python3.8/site-packages/flask/app.py", line 2070, in wsgi_app
    response = self.full_dispatch_request()
  File "/Users/piat/opt/anaconda3/envs/cp1/lib/python3.8/site-packages/flask/app.py", line 1515, in full_dispatch_request
    rv = self.handle_user_exception(e)
  File "/Users/piat/opt/anaconda3/envs/cp1/lib/python3.8/site-packages/flask/app.py", line 1513, in full_dispatch_request
    rv = self.dispatch_request()
  File "/Users/piat/opt/anaconda3/envs/cp1/lib/python3.8/site-packages/flask/app.py", line 1499, in dispatch_request
    return self.ensure_sync(self.view_functions[rule.endpoint])(**req.view_args)
  File "/Users/piat/s5/cp1/New/app/views/main_views.py", line 72, in result
    m = url_check(url_nick)
NameError: name 'url_check' is not defined
INFO:werkzeug:127.0.0.1 - - [28/Apr/2022 17:48:28] "[35m[1mGET /result?username=Ìï´ÏÉÅÎ≤î HTTP/1.1[0m" 500 -
ERROR:app:Exception on /result [GET]
Traceback (most recent call last):
  File "/Users/piat/opt/anaconda3/envs/cp1/lib/python3.8/site-packages/flask/app.py", line 2070, in wsgi_app
    response = self.full_dispatch_request()
  File "/Users/piat/opt/anaconda3/envs/cp1/lib/python3.8/site-packages/flask/app.py", line 1515, in full_dispatch_request
    rv = self.handle_user_exception(e)
  File "/Users/piat/opt/anaconda3/envs/cp1/lib/python3.8/site-packages/flask/app.py", line 1513, in full_dispatch_request
    rv = self.dispatch_request()
  File "/Users/piat/opt/anaconda3/envs/cp1/lib/python3.8/site-packages/flask/app.py", line 1499, in dispatch_request
    return self.ensure_sync(self.view_functions[rule.endpoint])(**req.view_args)
  File "/Users/piat/s5/cp1/New/app/views/main_views.py", line 72, in result
    m = url_check(url_nick)
NameError: name 'url_check' is not defined
INFO:werkzeug:127.0.0.1 - - [28/Apr/2022 17:48:56] "[35m[1mGET /result?username=Ìï´ÏÉÅÎ≤î HTTP/1.1[0m" 500 -
INFO:werkzeug: * Running on http://127.0.0.1:5000/ (Press CTRL+C to quit)
DEBUG:urllib3.connectionpool:Starting new HTTPS connection (1): kr.api.riotgames.com:443
DEBUG:urllib3.connectionpool:https://kr.api.riotgames.com:443 "GET /lol/summoner/v4/summoners/by-name/%ED%95%AB%EC%83%81%EB%B2%94 HTTP/1.1" 200 None
DEBUG:urllib3.connectionpool:Starting new HTTPS connection (1): kr.api.riotgames.com:443
DEBUG:urllib3.connectionpool:https://kr.api.riotgames.com:443 "GET /lol/summoner/v4/summoners/by-name/%ED%95%AB%EC%83%81%EB%B2%94 HTTP/1.1" 200 None
DEBUG:urllib3.connectionpool:Starting new HTTPS connection (1): kr.api.riotgames.com:443
DEBUG:urllib3.connectionpool:https://kr.api.riotgames.com:443 "GET /lol/champion-mastery/v4/champion-masteries/by-summoner/XnhdEBDrdxzLMqJVhZBnhh6PI5WHJcbU7JZMncss1JBPiw HTTP/1.1" 200 None
ERROR:app:Exception on /result [GET]
Traceback (most recent call last):
  File "/Users/piat/opt/anaconda3/envs/cp1/lib/python3.8/site-packages/flask/app.py", line 2070, in wsgi_app
    response = self.full_dispatch_request()
  File "/Users/piat/opt/anaconda3/envs/cp1/lib/python3.8/site-packages/flask/app.py", line 1515, in full_dispatch_request
    rv = self.handle_user_exception(e)
  File "/Users/piat/opt/anaconda3/envs/cp1/lib/python3.8/site-packages/flask/app.py", line 1513, in full_dispatch_request
    rv = self.dispatch_request()
  File "/Users/piat/opt/anaconda3/envs/cp1/lib/python3.8/site-packages/flask/app.py", line 1499, in dispatch_request
    return self.ensure_sync(self.view_functions[rule.endpoint])(**req.view_args)
  File "/Users/piat/s5/cp1/New/app/views/main_views.py", line 96, in result
    save_userinfo(user_info_data) # Ïú†Ï†ÄÏ†ïÎ≥¥ mongodbÏ†ÄÏû•
NameError: name 'save_userinfo' is not defined
INFO:werkzeug:127.0.0.1 - - [28/Apr/2022 17:49:37] "[35m[1mGET /result?username=Ìï´ÏÉÅÎ≤î HTTP/1.1[0m" 500 -
INFO:werkzeug: * Running on http://127.0.0.1:5000/ (Press CTRL+C to quit)
DEBUG:urllib3.connectionpool:Starting new HTTPS connection (1): kr.api.riotgames.com:443
DEBUG:urllib3.connectionpool:https://kr.api.riotgames.com:443 "GET /lol/summoner/v4/summoners/by-name/%ED%95%AB%EC%83%81%EB%B2%94 HTTP/1.1" 200 None
DEBUG:urllib3.connectionpool:Starting new HTTPS connection (1): kr.api.riotgames.com:443
DEBUG:urllib3.connectionpool:https://kr.api.riotgames.com:443 "GET /lol/summoner/v4/summoners/by-name/%ED%95%AB%EC%83%81%EB%B2%94 HTTP/1.1" 200 None
DEBUG:urllib3.connectionpool:Starting new HTTPS connection (1): kr.api.riotgames.com:443
DEBUG:urllib3.connectionpool:https://kr.api.riotgames.com:443 "GET /lol/champion-mastery/v4/champion-masteries/by-summoner/XnhdEBDrdxzLMqJVhZBnhh6PI5WHJcbU7JZMncss1JBPiw HTTP/1.1" 200 None
ERROR:app:Exception on /result [GET]
Traceback (most recent call last):
  File "/Users/piat/opt/anaconda3/envs/cp1/lib/python3.8/site-packages/flask/app.py", line 2070, in wsgi_app
    response = self.full_dispatch_request()
  File "/Users/piat/opt/anaconda3/envs/cp1/lib/python3.8/site-packages/flask/app.py", line 1515, in full_dispatch_request
    rv = self.handle_user_exception(e)
  File "/Users/piat/opt/anaconda3/envs/cp1/lib/python3.8/site-packages/flask/app.py", line 1513, in full_dispatch_request
    rv = self.dispatch_request()
  File "/Users/piat/opt/anaconda3/envs/cp1/lib/python3.8/site-packages/flask/app.py", line 1499, in dispatch_request
    return self.ensure_sync(self.view_functions[rule.endpoint])(**req.view_args)
  File "/Users/piat/s5/cp1/New/app/views/main_views.py", line 96, in result
    save_userinfo(user_info_data) # Ïú†Ï†ÄÏ†ïÎ≥¥ mongodbÏ†ÄÏû•
  File "/Users/piat/s5/cp1/New/riot_api/mongodb.py", line 55, in save_userinfo
    col.insert_one(data_name)
  File "/Users/piat/opt/anaconda3/envs/cp1/lib/python3.8/site-packages/pymongo/collection.py", line 698, in insert_one
    self._insert(document,
  File "/Users/piat/opt/anaconda3/envs/cp1/lib/python3.8/site-packages/pymongo/collection.py", line 613, in _insert
    return self._insert_one(
  File "/Users/piat/opt/anaconda3/envs/cp1/lib/python3.8/site-packages/pymongo/collection.py", line 602, in _insert_one
    self.__database.client._retryable_write(
  File "/Users/piat/opt/anaconda3/envs/cp1/lib/python3.8/site-packages/pymongo/mongo_client.py", line 1498, in _retryable_write
    return self._retry_with_session(retryable, func, s, None)
  File "/Users/piat/opt/anaconda3/envs/cp1/lib/python3.8/site-packages/pymongo/mongo_client.py", line 1384, in _retry_with_session
    return self._retry_internal(retryable, func, session, bulk)
  File "/Users/piat/opt/anaconda3/envs/cp1/lib/python3.8/site-packages/pymongo/mongo_client.py", line 1416, in _retry_internal
    return func(session, sock_info, retryable)
  File "/Users/piat/opt/anaconda3/envs/cp1/lib/python3.8/site-packages/pymongo/collection.py", line 600, in _insert_command
    _check_write_command_response(result)
  File "/Users/piat/opt/anaconda3/envs/cp1/lib/python3.8/site-packages/pymongo/helpers.py", line 226, in _check_write_command_response
    _raise_last_write_error(write_errors)
  File "/Users/piat/opt/anaconda3/envs/cp1/lib/python3.8/site-packages/pymongo/helpers.py", line 207, in _raise_last_write_error
    raise DuplicateKeyError(error.get("errmsg"), 11000, error)
pymongo.errors.DuplicateKeyError: E11000 duplicate key error collection: loldata.userinfo index: _id_ dup key: { _id: "XnhdEBDrdxzLMqJVhZBnhh6PI5WHJcbU7JZMncss1JBPiw" }, full error: {'index': 0, 'code': 11000, 'keyPattern': {'_id': 1}, 'keyValue': {'_id': 'XnhdEBDrdxzLMqJVhZBnhh6PI5WHJcbU7JZMncss1JBPiw'}, 'errmsg': 'E11000 duplicate key error collection: loldata.userinfo index: _id_ dup key: { _id: "XnhdEBDrdxzLMqJVhZBnhh6PI5WHJcbU7JZMncss1JBPiw" }'}
INFO:werkzeug:127.0.0.1 - - [28/Apr/2022 17:50:21] "[35m[1mGET /result?username=Ìï´ÏÉÅÎ≤î HTTP/1.1[0m" 500 -
INFO:werkzeug: * Running on http://127.0.0.1:5000/ (Press CTRL+C to quit)
ERROR:app:Exception on /result [GET]
Traceback (most recent call last):
  File "/Users/piat/opt/anaconda3/envs/cp1/lib/python3.8/site-packages/flask/app.py", line 2070, in wsgi_app
    response = self.full_dispatch_request()
  File "/Users/piat/opt/anaconda3/envs/cp1/lib/python3.8/site-packages/flask/app.py", line 1515, in full_dispatch_request
    rv = self.handle_user_exception(e)
  File "/Users/piat/opt/anaconda3/envs/cp1/lib/python3.8/site-packages/flask/app.py", line 1513, in full_dispatch_request
    rv = self.dispatch_request()
  File "/Users/piat/opt/anaconda3/envs/cp1/lib/python3.8/site-packages/flask/app.py", line 1499, in dispatch_request
    return self.ensure_sync(self.view_functions[rule.endpoint])(**req.view_args)
  File "/Users/piat/s5/cp1/New/app/views/main_views.py", line 63, in result
    from riot_api.name import sumoners
  File "/Users/piat/s5/cp1/New/riot_api/name.py", line 1, in <module>
    from api import *
ModuleNotFoundError: No module named 'api'
INFO:werkzeug:127.0.0.1 - - [28/Apr/2022 19:21:32] "[35m[1mGET /result?username=Ìï´ÏÉÅÎ≤î HTTP/1.1[0m" 500 -
INFO:werkzeug: * Running on http://127.0.0.1:5000/ (Press CTRL+C to quit)
DEBUG:urllib3.connectionpool:Starting new HTTPS connection (1): kr.api.riotgames.com:443
DEBUG:urllib3.connectionpool:https://kr.api.riotgames.com:443 "GET /lol/summoner/v4/summoners/by-name/%ED%95%AB%EC%83%81%EB%B2%94 HTTP/1.1" 200 None
DEBUG:urllib3.connectionpool:Starting new HTTPS connection (1): kr.api.riotgames.com:443
DEBUG:urllib3.connectionpool:https://kr.api.riotgames.com:443 "GET /lol/summoner/v4/summoners/by-name/%ED%95%AB%EC%83%81%EB%B2%94 HTTP/1.1" 200 None
DEBUG:urllib3.connectionpool:Starting new HTTPS connection (1): kr.api.riotgames.com:443
DEBUG:urllib3.connectionpool:https://kr.api.riotgames.com:443 "GET /lol/champion-mastery/v4/champion-masteries/by-summoner/XnhdEBDrdxzLMqJVhZBnhh6PI5WHJcbU7JZMncss1JBPiw HTTP/1.1" 200 None
ERROR:app:Exception on /result [GET]
Traceback (most recent call last):
  File "/Users/piat/opt/anaconda3/envs/cp1/lib/python3.8/site-packages/flask/app.py", line 2070, in wsgi_app
    response = self.full_dispatch_request()
  File "/Users/piat/opt/anaconda3/envs/cp1/lib/python3.8/site-packages/flask/app.py", line 1515, in full_dispatch_request
    rv = self.handle_user_exception(e)
  File "/Users/piat/opt/anaconda3/envs/cp1/lib/python3.8/site-packages/flask/app.py", line 1513, in full_dispatch_request
    rv = self.dispatch_request()
  File "/Users/piat/opt/anaconda3/envs/cp1/lib/python3.8/site-packages/flask/app.py", line 1499, in dispatch_request
    return self.ensure_sync(self.view_functions[rule.endpoint])(**req.view_args)
  File "/Users/piat/s5/cp1/New/app/views/main_views.py", line 96, in result
    save_userinfo(user_info_data) # Ïú†Ï†ÄÏ†ïÎ≥¥ mongodbÏ†ÄÏû•
  File "/Users/piat/s5/cp1/New/riot_api/mongodb.py", line 54, in save_userinfo
    if list(col.find_one({'_id':data_name['_id']}).values()) in data_name['_id']:
TypeError: 'in <string>' requires string as left operand, not list
INFO:werkzeug:127.0.0.1 - - [28/Apr/2022 19:22:21] "[35m[1mGET /result?username=Ìï´ÏÉÅÎ≤î HTTP/1.1[0m" 500 -
DEBUG:urllib3.connectionpool:Starting new HTTPS connection (1): kr.api.riotgames.com:443
DEBUG:urllib3.connectionpool:https://kr.api.riotgames.com:443 "GET /lol/summoner/v4/summoners/by-name/%ED%95%AB%EC%83%81%EB%B2%94 HTTP/1.1" 200 None
DEBUG:urllib3.connectionpool:Starting new HTTPS connection (1): kr.api.riotgames.com:443
DEBUG:urllib3.connectionpool:https://kr.api.riotgames.com:443 "GET /lol/summoner/v4/summoners/by-name/%ED%95%AB%EC%83%81%EB%B2%94 HTTP/1.1" 200 None
DEBUG:urllib3.connectionpool:Starting new HTTPS connection (1): kr.api.riotgames.com:443
DEBUG:urllib3.connectionpool:https://kr.api.riotgames.com:443 "GET /lol/champion-mastery/v4/champion-masteries/by-summoner/XnhdEBDrdxzLMqJVhZBnhh6PI5WHJcbU7JZMncss1JBPiw HTTP/1.1" 200 None
ERROR:app:Exception on /result [GET]
Traceback (most recent call last):
  File "/Users/piat/opt/anaconda3/envs/cp1/lib/python3.8/site-packages/flask/app.py", line 2070, in wsgi_app
    response = self.full_dispatch_request()
  File "/Users/piat/opt/anaconda3/envs/cp1/lib/python3.8/site-packages/flask/app.py", line 1515, in full_dispatch_request
    rv = self.handle_user_exception(e)
  File "/Users/piat/opt/anaconda3/envs/cp1/lib/python3.8/site-packages/flask/app.py", line 1513, in full_dispatch_request
    rv = self.dispatch_request()
  File "/Users/piat/opt/anaconda3/envs/cp1/lib/python3.8/site-packages/flask/app.py", line 1499, in dispatch_request
    return self.ensure_sync(self.view_functions[rule.endpoint])(**req.view_args)
  File "/Users/piat/s5/cp1/New/app/views/main_views.py", line 96, in result
    save_userinfo(user_info_data) # Ïú†Ï†ÄÏ†ïÎ≥¥ mongodbÏ†ÄÏû•
  File "/Users/piat/s5/cp1/New/riot_api/mongodb.py", line 54, in save_userinfo
    if data_name['_id'] in list(col.find_one({'_id':data_name['_id']}).values()):
TypeError: 'in <string>' requires string as left operand, not list
INFO:werkzeug:127.0.0.1 - - [28/Apr/2022 19:23:15] "[35m[1mGET /result?username=Ìï´ÏÉÅÎ≤î HTTP/1.1[0m" 500 -
INFO:werkzeug: * Running on http://127.0.0.1:5000/ (Press CTRL+C to quit)
DEBUG:urllib3.connectionpool:Starting new HTTPS connection (1): kr.api.riotgames.com:443
DEBUG:urllib3.connectionpool:https://kr.api.riotgames.com:443 "GET /lol/summoner/v4/summoners/by-name/%ED%95%AB%EC%83%81%EB%B2%94 HTTP/1.1" 200 None
DEBUG:urllib3.connectionpool:Starting new HTTPS connection (1): kr.api.riotgames.com:443
DEBUG:urllib3.connectionpool:https://kr.api.riotgames.com:443 "GET /lol/summoner/v4/summoners/by-name/%ED%95%AB%EC%83%81%EB%B2%94 HTTP/1.1" 200 None
DEBUG:urllib3.connectionpool:Starting new HTTPS connection (1): kr.api.riotgames.com:443
DEBUG:urllib3.connectionpool:https://kr.api.riotgames.com:443 "GET /lol/champion-mastery/v4/champion-masteries/by-summoner/XnhdEBDrdxzLMqJVhZBnhh6PI5WHJcbU7JZMncss1JBPiw HTTP/1.1" 200 None
ERROR:app:Exception on /result [GET]
Traceback (most recent call last):
  File "/Users/piat/opt/anaconda3/envs/cp1/lib/python3.8/site-packages/flask/app.py", line 2070, in wsgi_app
    response = self.full_dispatch_request()
  File "/Users/piat/opt/anaconda3/envs/cp1/lib/python3.8/site-packages/flask/app.py", line 1515, in full_dispatch_request
    rv = self.handle_user_exception(e)
  File "/Users/piat/opt/anaconda3/envs/cp1/lib/python3.8/site-packages/flask/app.py", line 1513, in full_dispatch_request
    rv = self.dispatch_request()
  File "/Users/piat/opt/anaconda3/envs/cp1/lib/python3.8/site-packages/flask/app.py", line 1499, in dispatch_request
    return self.ensure_sync(self.view_functions[rule.endpoint])(**req.view_args)
  File "/Users/piat/s5/cp1/New/app/views/main_views.py", line 96, in result
    save_userinfo(user_info_data) # Ïú†Ï†ÄÏ†ïÎ≥¥ mongodbÏ†ÄÏû•
  File "/Users/piat/s5/cp1/New/riot_api/mongodb.py", line 55, in save_userinfo
    col.update(data_name)
TypeError: update() missing 1 required positional argument: 'document'
INFO:werkzeug:127.0.0.1 - - [28/Apr/2022 19:26:05] "[35m[1mGET /result?username=Ìï´ÏÉÅÎ≤î HTTP/1.1[0m" 500 -
INFO:werkzeug: * Running on http://127.0.0.1:5000/ (Press CTRL+C to quit)
DEBUG:urllib3.connectionpool:Starting new HTTPS connection (1): kr.api.riotgames.com:443
DEBUG:urllib3.connectionpool:https://kr.api.riotgames.com:443 "GET /lol/summoner/v4/summoners/by-name/%ED%95%AB%EC%83%81%EB%B2%94 HTTP/1.1" 200 None
DEBUG:urllib3.connectionpool:Starting new HTTPS connection (1): kr.api.riotgames.com:443
DEBUG:urllib3.connectionpool:https://kr.api.riotgames.com:443 "GET /lol/summoner/v4/summoners/by-name/%ED%95%AB%EC%83%81%EB%B2%94 HTTP/1.1" 200 None
DEBUG:urllib3.connectionpool:Starting new HTTPS connection (1): kr.api.riotgames.com:443
DEBUG:urllib3.connectionpool:https://kr.api.riotgames.com:443 "GET /lol/champion-mastery/v4/champion-masteries/by-summoner/XnhdEBDrdxzLMqJVhZBnhh6PI5WHJcbU7JZMncss1JBPiw HTTP/1.1" 200 None
ERROR:app:Exception on /result [GET]
Traceback (most recent call last):
  File "/Users/piat/opt/anaconda3/envs/cp1/lib/python3.8/site-packages/flask/app.py", line 2070, in wsgi_app
    response = self.full_dispatch_request()
  File "/Users/piat/opt/anaconda3/envs/cp1/lib/python3.8/site-packages/flask/app.py", line 1515, in full_dispatch_request
    rv = self.handle_user_exception(e)
  File "/Users/piat/opt/anaconda3/envs/cp1/lib/python3.8/site-packages/flask/app.py", line 1513, in full_dispatch_request
    rv = self.dispatch_request()
  File "/Users/piat/opt/anaconda3/envs/cp1/lib/python3.8/site-packages/flask/app.py", line 1499, in dispatch_request
    return self.ensure_sync(self.view_functions[rule.endpoint])(**req.view_args)
  File "/Users/piat/s5/cp1/New/app/views/main_views.py", line 97, in result
    save_mastery(makedata(user.mastery)) # Ïú†Ï†Ä Ï±îÌîºÏñ∏ Ï†ïÎ≥¥ mongodbÏ†ÄÏû•
TypeError: makedata() missing 1 required positional argument: 'data'
INFO:werkzeug:127.0.0.1 - - [28/Apr/2022 19:30:04] "[35m[1mGET /result?username=Ìï´ÏÉÅÎ≤î HTTP/1.1[0m" 500 -
INFO:werkzeug: * Running on http://127.0.0.1:5000/ (Press CTRL+C to quit)
DEBUG:urllib3.connectionpool:Starting new HTTPS connection (1): kr.api.riotgames.com:443
DEBUG:urllib3.connectionpool:https://kr.api.riotgames.com:443 "GET /lol/summoner/v4/summoners/by-name/%ED%95%AB%EC%83%81%EB%B2%94 HTTP/1.1" 200 None
DEBUG:urllib3.connectionpool:Starting new HTTPS connection (1): kr.api.riotgames.com:443
DEBUG:urllib3.connectionpool:https://kr.api.riotgames.com:443 "GET /lol/summoner/v4/summoners/by-name/%ED%95%AB%EC%83%81%EB%B2%94 HTTP/1.1" 200 None
DEBUG:urllib3.connectionpool:Starting new HTTPS connection (1): kr.api.riotgames.com:443
DEBUG:urllib3.connectionpool:https://kr.api.riotgames.com:443 "GET /lol/champion-mastery/v4/champion-masteries/by-summoner/XnhdEBDrdxzLMqJVhZBnhh6PI5WHJcbU7JZMncss1JBPiw HTTP/1.1" 200 None
DEBUG:urllib3.connectionpool:Starting new HTTPS connection (1): kr.api.riotgames.com:443
DEBUG:urllib3.connectionpool:https://kr.api.riotgames.com:443 "GET /lol/summoner/v4/summoners/by-name/%ED%95%AB%EC%83%81%EB%B2%94 HTTP/1.1" 200 None
DEBUG:urllib3.connectionpool:Starting new HTTPS connection (1): kr.api.riotgames.com:443
DEBUG:urllib3.connectionpool:https://kr.api.riotgames.com:443 "GET /lol/spectator/v4/active-games/by-summoner/XnhdEBDrdxzLMqJVhZBnhh6PI5WHJcbU7JZMncss1JBPiw HTTP/1.1" 503 None
INFO:werkzeug:127.0.0.1 - - [28/Apr/2022 19:31:43] "GET /result?username=Ìï´ÏÉÅÎ≤î HTTP/1.1" 200 -
INFO:werkzeug:127.0.0.1 - - [28/Apr/2022 19:31:43] "[36mGET /static/img/riot.png HTTP/1.1[0m" 304 -
INFO:werkzeug: * Running on http://127.0.0.1:5000/ (Press CTRL+C to quit)
INFO:werkzeug: * Running on http://127.0.0.1:5000/ (Press CTRL+C to quit)
ERROR:app:Exception on /result [GET]
Traceback (most recent call last):
  File "/Users/piat/opt/anaconda3/envs/cp1/lib/python3.8/site-packages/flask/app.py", line 2070, in wsgi_app
    response = self.full_dispatch_request()
  File "/Users/piat/opt/anaconda3/envs/cp1/lib/python3.8/site-packages/flask/app.py", line 1515, in full_dispatch_request
    rv = self.handle_user_exception(e)
  File "/Users/piat/opt/anaconda3/envs/cp1/lib/python3.8/site-packages/flask/app.py", line 1513, in full_dispatch_request
    rv = self.dispatch_request()
  File "/Users/piat/opt/anaconda3/envs/cp1/lib/python3.8/site-packages/flask/app.py", line 1499, in dispatch_request
    return self.ensure_sync(self.view_functions[rule.endpoint])(**req.view_args)
  File "/Users/piat/s5/cp1/New/app/views/main_views.py", line 66, in result
    from riot_api.name import sumoners
  File "/Users/piat/s5/cp1/New/riot_api/name.py", line 1, in <module>
    from api import *
ModuleNotFoundError: No module named 'api'
INFO:werkzeug:127.0.0.1 - - [28/Apr/2022 20:56:21] "[35m[1mGET /result?username= HTTP/1.1[0m" 500 -
DEBUG:urllib3.connectionpool:Starting new HTTPS connection (1): kr.api.riotgames.com:443
DEBUG:urllib3.connectionpool:https://kr.api.riotgames.com:443 "GET /lol/summoner/v4/summoners/by-name/ HTTP/1.1" 403 None
INFO:werkzeug:127.0.0.1 - - [28/Apr/2022 20:56:46] "GET /result?username= HTTP/1.1" 200 -
INFO:werkzeug:127.0.0.1 - - [28/Apr/2022 20:56:46] "[36mGET /static/img/riot.png HTTP/1.1[0m" 304 -
INFO:werkzeug: * Running on http://127.0.0.1:5000/ (Press CTRL+C to quit)
INFO:werkzeug:127.0.0.1 - - [28/Apr/2022 21:13:36] "GET / HTTP/1.1" 200 -
INFO:werkzeug:127.0.0.1 - - [28/Apr/2022 21:13:36] "[36mGET /static/img/riot.png HTTP/1.1[0m" 304 -
DEBUG:urllib3.connectionpool:Starting new HTTPS connection (1): kr.api.riotgames.com:443
DEBUG:urllib3.connectionpool:https://kr.api.riotgames.com:443 "GET /lol/summoner/v4/summoners/by-name/ HTTP/1.1" 403 None
INFO:werkzeug:127.0.0.1 - - [28/Apr/2022 21:13:42] "GET /result?username= HTTP/1.1" 200 -
INFO:werkzeug:127.0.0.1 - - [28/Apr/2022 21:13:42] "[36mGET /static/img/riot.png HTTP/1.1[0m" 304 -
INFO:werkzeug: * Running on http://127.0.0.1:5000/ (Press CTRL+C to quit)
INFO:werkzeug:127.0.0.1 - - [28/Apr/2022 21:14:53] "GET / HTTP/1.1" 200 -
INFO:werkzeug:127.0.0.1 - - [28/Apr/2022 21:14:53] "[36mGET /static/img/riot.png HTTP/1.1[0m" 304 -
DEBUG:urllib3.connectionpool:Starting new HTTPS connection (1): kr.api.riotgames.com:443
DEBUG:urllib3.connectionpool:https://kr.api.riotgames.com:443 "GET /lol/summoner/v4/summoners/by-name/ HTTP/1.1" 403 None
INFO:werkzeug:127.0.0.1 - - [28/Apr/2022 21:14:57] "GET /result?username= HTTP/1.1" 200 -
INFO:werkzeug:127.0.0.1 - - [28/Apr/2022 21:14:57] "[36mGET /static/img/riot.png HTTP/1.1[0m" 304 -
INFO:werkzeug:127.0.0.1 - - [28/Apr/2022 21:15:13] "GET / HTTP/1.1" 200 -
INFO:werkzeug:127.0.0.1 - - [28/Apr/2022 21:15:13] "[36mGET /static/img/riot.png HTTP/1.1[0m" 304 -
INFO:werkzeug: * Running on http://127.0.0.1:5000/ (Press CTRL+C to quit)
DEBUG:urllib3.connectionpool:Starting new HTTPS connection (1): kr.api.riotgames.com:443
DEBUG:urllib3.connectionpool:https://kr.api.riotgames.com:443 "GET /lol/summoner/v4/summoners/by-name/%ED%95%AB%EC%83%81%EB%B2%94 HTTP/1.1" 200 None
DEBUG:urllib3.connectionpool:Starting new HTTPS connection (1): kr.api.riotgames.com:443
DEBUG:urllib3.connectionpool:https://kr.api.riotgames.com:443 "GET /lol/summoner/v4/summoners/by-name/%ED%95%AB%EC%83%81%EB%B2%94 HTTP/1.1" 200 None
DEBUG:urllib3.connectionpool:Starting new HTTPS connection (1): kr.api.riotgames.com:443
DEBUG:urllib3.connectionpool:https://kr.api.riotgames.com:443 "GET /lol/champion-mastery/v4/champion-masteries/by-summoner/XnhdEBDrdxzLMqJVhZBnhh6PI5WHJcbU7JZMncss1JBPiw HTTP/1.1" 200 None
ERROR:app:Exception on /result [GET]
Traceback (most recent call last):
  File "/Users/piat/opt/anaconda3/envs/cp1/lib/python3.8/site-packages/flask/app.py", line 2070, in wsgi_app
    response = self.full_dispatch_request()
  File "/Users/piat/opt/anaconda3/envs/cp1/lib/python3.8/site-packages/flask/app.py", line 1515, in full_dispatch_request
    rv = self.handle_user_exception(e)
  File "/Users/piat/opt/anaconda3/envs/cp1/lib/python3.8/site-packages/flask/app.py", line 1513, in full_dispatch_request
    rv = self.dispatch_request()
  File "/Users/piat/opt/anaconda3/envs/cp1/lib/python3.8/site-packages/flask/app.py", line 1499, in dispatch_request
    return self.ensure_sync(self.view_functions[rule.endpoint])(**req.view_args)
  File "/Users/piat/s5/cp1/New/app/views/main_views.py", line 109, in result
    save_mastery(makedata(user.id, user.mastery)) # Ïú†Ï†Ä Ï±îÌîºÏñ∏ Ï†ïÎ≥¥ mongodbÏ†ÄÏû•
  File "/Users/piat/s5/cp1/New/riot_api/mongodb.py", line 83, in save_mastery
    col.insert_one(data_name)
  File "/Users/piat/opt/anaconda3/envs/cp1/lib/python3.8/site-packages/pymongo/collection.py", line 698, in insert_one
    self._insert(document,
  File "/Users/piat/opt/anaconda3/envs/cp1/lib/python3.8/site-packages/pymongo/collection.py", line 613, in _insert
    return self._insert_one(
  File "/Users/piat/opt/anaconda3/envs/cp1/lib/python3.8/site-packages/pymongo/collection.py", line 602, in _insert_one
    self.__database.client._retryable_write(
  File "/Users/piat/opt/anaconda3/envs/cp1/lib/python3.8/site-packages/pymongo/mongo_client.py", line 1498, in _retryable_write
    return self._retry_with_session(retryable, func, s, None)
  File "/Users/piat/opt/anaconda3/envs/cp1/lib/python3.8/site-packages/pymongo/mongo_client.py", line 1384, in _retry_with_session
    return self._retry_internal(retryable, func, session, bulk)
  File "/Users/piat/opt/anaconda3/envs/cp1/lib/python3.8/site-packages/pymongo/mongo_client.py", line 1416, in _retry_internal
    return func(session, sock_info, retryable)
  File "/Users/piat/opt/anaconda3/envs/cp1/lib/python3.8/site-packages/pymongo/collection.py", line 600, in _insert_command
    _check_write_command_response(result)
  File "/Users/piat/opt/anaconda3/envs/cp1/lib/python3.8/site-packages/pymongo/helpers.py", line 226, in _check_write_command_response
    _raise_last_write_error(write_errors)
  File "/Users/piat/opt/anaconda3/envs/cp1/lib/python3.8/site-packages/pymongo/helpers.py", line 207, in _raise_last_write_error
    raise DuplicateKeyError(error.get("errmsg"), 11000, error)
pymongo.errors.DuplicateKeyError: E11000 duplicate key error collection: loldata.user_mastery index: _id_ dup key: { _id: "XnhdEBDrdxzLMqJVhZBnhh6PI5WHJcbU7JZMncss1JBPiw" }, full error: {'index': 0, 'code': 11000, 'keyPattern': {'_id': 1}, 'keyValue': {'_id': 'XnhdEBDrdxzLMqJVhZBnhh6PI5WHJcbU7JZMncss1JBPiw'}, 'errmsg': 'E11000 duplicate key error collection: loldata.user_mastery index: _id_ dup key: { _id: "XnhdEBDrdxzLMqJVhZBnhh6PI5WHJcbU7JZMncss1JBPiw" }'}
INFO:werkzeug:127.0.0.1 - - [28/Apr/2022 21:20:48] "[35m[1mGET /result?username=Ìï´ÏÉÅÎ≤î HTTP/1.1[0m" 500 -
INFO:werkzeug: * Running on http://127.0.0.1:5000/ (Press CTRL+C to quit)
DEBUG:urllib3.connectionpool:Starting new HTTPS connection (1): kr.api.riotgames.com:443
DEBUG:urllib3.connectionpool:https://kr.api.riotgames.com:443 "GET /lol/summoner/v4/summoners/by-name/%ED%95%AB%EC%83%81%EB%B2%94 HTTP/1.1" 200 None
DEBUG:urllib3.connectionpool:Starting new HTTPS connection (1): kr.api.riotgames.com:443
DEBUG:urllib3.connectionpool:https://kr.api.riotgames.com:443 "GET /lol/summoner/v4/summoners/by-name/%ED%95%AB%EC%83%81%EB%B2%94 HTTP/1.1" 200 None
DEBUG:urllib3.connectionpool:Starting new HTTPS connection (1): kr.api.riotgames.com:443
DEBUG:urllib3.connectionpool:https://kr.api.riotgames.com:443 "GET /lol/champion-mastery/v4/champion-masteries/by-summoner/XnhdEBDrdxzLMqJVhZBnhh6PI5WHJcbU7JZMncss1JBPiw HTTP/1.1" 200 None
DEBUG:urllib3.connectionpool:Starting new HTTPS connection (1): kr.api.riotgames.com:443
DEBUG:urllib3.connectionpool:https://kr.api.riotgames.com:443 "GET /lol/summoner/v4/summoners/by-name/%ED%95%AB%EC%83%81%EB%B2%94 HTTP/1.1" 200 None
DEBUG:urllib3.connectionpool:Starting new HTTPS connection (1): kr.api.riotgames.com:443
DEBUG:urllib3.connectionpool:https://kr.api.riotgames.com:443 "GET /lol/spectator/v4/active-games/by-summoner/XnhdEBDrdxzLMqJVhZBnhh6PI5WHJcbU7JZMncss1JBPiw HTTP/1.1" 503 None
INFO:werkzeug:127.0.0.1 - - [28/Apr/2022 21:22:27] "GET /result?username=Ìï´ÏÉÅÎ≤î HTTP/1.1" 200 -
INFO:werkzeug:127.0.0.1 - - [28/Apr/2022 21:22:27] "[36mGET /static/img/riot.png HTTP/1.1[0m" 304 -
INFO:werkzeug: * Running on http://127.0.0.1:5000/ (Press CTRL+C to quit)
INFO:werkzeug:127.0.0.1 - - [28/Apr/2022 21:25:01] "GET / HTTP/1.1" 200 -
INFO:werkzeug:127.0.0.1 - - [28/Apr/2022 21:25:01] "[36mGET /static/img/riot.png HTTP/1.1[0m" 304 -
DEBUG:urllib3.connectionpool:Starting new HTTPS connection (1): kr.api.riotgames.com:443
DEBUG:urllib3.connectionpool:https://kr.api.riotgames.com:443 "GET /lol/summoner/v4/summoners/by-name/%ED%95%AB%EC%83%81%EB%B2%94 HTTP/1.1" 200 None
DEBUG:urllib3.connectionpool:Starting new HTTPS connection (1): kr.api.riotgames.com:443
DEBUG:urllib3.connectionpool:https://kr.api.riotgames.com:443 "GET /lol/summoner/v4/summoners/by-name/%ED%95%AB%EC%83%81%EB%B2%94 HTTP/1.1" 200 None
DEBUG:urllib3.connectionpool:Starting new HTTPS connection (1): kr.api.riotgames.com:443
DEBUG:urllib3.connectionpool:https://kr.api.riotgames.com:443 "GET /lol/champion-mastery/v4/champion-masteries/by-summoner/XnhdEBDrdxzLMqJVhZBnhh6PI5WHJcbU7JZMncss1JBPiw HTTP/1.1" 200 None
DEBUG:urllib3.connectionpool:Starting new HTTPS connection (1): kr.api.riotgames.com:443
DEBUG:urllib3.connectionpool:https://kr.api.riotgames.com:443 "GET /lol/summoner/v4/summoners/by-name/%ED%95%AB%EC%83%81%EB%B2%94 HTTP/1.1" 200 None
DEBUG:urllib3.connectionpool:Starting new HTTPS connection (1): kr.api.riotgames.com:443
DEBUG:urllib3.connectionpool:https://kr.api.riotgames.com:443 "GET /lol/spectator/v4/active-games/by-summoner/XnhdEBDrdxzLMqJVhZBnhh6PI5WHJcbU7JZMncss1JBPiw HTTP/1.1" 503 None
INFO:werkzeug:127.0.0.1 - - [28/Apr/2022 21:25:12] "GET /result?username=Ìï´ÏÉÅÎ≤î HTTP/1.1" 200 -
INFO:werkzeug:127.0.0.1 - - [28/Apr/2022 21:25:12] "[36mGET /static/img/riot.png HTTP/1.1[0m" 304 -
INFO:werkzeug: * Running on http://127.0.0.1:5000/ (Press CTRL+C to quit)
INFO:werkzeug:127.0.0.1 - - [28/Apr/2022 21:27:07] "GET / HTTP/1.1" 200 -
INFO:werkzeug:127.0.0.1 - - [28/Apr/2022 21:27:08] "[36mGET /static/img/riot.png HTTP/1.1[0m" 304 -
DEBUG:urllib3.connectionpool:Starting new HTTPS connection (1): kr.api.riotgames.com:443
DEBUG:urllib3.connectionpool:https://kr.api.riotgames.com:443 "GET /lol/summoner/v4/summoners/by-name/%ED%95%AB%EC%83%81%EB%B2%94 HTTP/1.1" 200 None
DEBUG:urllib3.connectionpool:Starting new HTTPS connection (1): kr.api.riotgames.com:443
DEBUG:urllib3.connectionpool:https://kr.api.riotgames.com:443 "GET /lol/summoner/v4/summoners/by-name/%ED%95%AB%EC%83%81%EB%B2%94 HTTP/1.1" 200 None
DEBUG:urllib3.connectionpool:Starting new HTTPS connection (1): kr.api.riotgames.com:443
DEBUG:urllib3.connectionpool:https://kr.api.riotgames.com:443 "GET /lol/champion-mastery/v4/champion-masteries/by-summoner/XnhdEBDrdxzLMqJVhZBnhh6PI5WHJcbU7JZMncss1JBPiw HTTP/1.1" 200 None
DEBUG:urllib3.connectionpool:Starting new HTTPS connection (1): kr.api.riotgames.com:443
DEBUG:urllib3.connectionpool:https://kr.api.riotgames.com:443 "GET /lol/summoner/v4/summoners/by-name/%ED%95%AB%EC%83%81%EB%B2%94 HTTP/1.1" 200 None
DEBUG:urllib3.connectionpool:Starting new HTTPS connection (1): kr.api.riotgames.com:443
DEBUG:urllib3.connectionpool:https://kr.api.riotgames.com:443 "GET /lol/spectator/v4/active-games/by-summoner/XnhdEBDrdxzLMqJVhZBnhh6PI5WHJcbU7JZMncss1JBPiw HTTP/1.1" 503 None
INFO:werkzeug:127.0.0.1 - - [28/Apr/2022 21:27:17] "GET /result?username=Ìï´ÏÉÅÎ≤î HTTP/1.1" 200 -
INFO:werkzeug:127.0.0.1 - - [28/Apr/2022 21:27:17] "[36mGET /static/img/riot.png HTTP/1.1[0m" 304 -
INFO:werkzeug: * Running on http://127.0.0.1:5000/ (Press CTRL+C to quit)
INFO:werkzeug:127.0.0.1 - - [28/Apr/2022 21:35:39] "GET / HTTP/1.1" 200 -
INFO:werkzeug:127.0.0.1 - - [28/Apr/2022 21:35:39] "[36mGET /static/img/riot.png HTTP/1.1[0m" 304 -
DEBUG:urllib3.connectionpool:Starting new HTTPS connection (1): kr.api.riotgames.com:443
DEBUG:urllib3.connectionpool:https://kr.api.riotgames.com:443 "GET /lol/summoner/v4/summoners/by-name/%ED%95%AB%EC%83%81%EB%B2%94 HTTP/1.1" 200 None
DEBUG:urllib3.connectionpool:Starting new HTTPS connection (1): kr.api.riotgames.com:443
DEBUG:urllib3.connectionpool:https://kr.api.riotgames.com:443 "GET /lol/summoner/v4/summoners/by-name/%ED%95%AB%EC%83%81%EB%B2%94 HTTP/1.1" 200 None
DEBUG:urllib3.connectionpool:Starting new HTTPS connection (1): kr.api.riotgames.com:443
DEBUG:urllib3.connectionpool:https://kr.api.riotgames.com:443 "GET /lol/champion-mastery/v4/champion-masteries/by-summoner/XnhdEBDrdxzLMqJVhZBnhh6PI5WHJcbU7JZMncss1JBPiw HTTP/1.1" 429 None
ERROR:app:Exception on /result [GET]
Traceback (most recent call last):
  File "/Users/piat/opt/anaconda3/envs/cp1/lib/python3.8/site-packages/flask/app.py", line 2070, in wsgi_app
    response = self.full_dispatch_request()
  File "/Users/piat/opt/anaconda3/envs/cp1/lib/python3.8/site-packages/flask/app.py", line 1515, in full_dispatch_request
    rv = self.handle_user_exception(e)
  File "/Users/piat/opt/anaconda3/envs/cp1/lib/python3.8/site-packages/flask/app.py", line 1513, in full_dispatch_request
    rv = self.dispatch_request()
  File "/Users/piat/opt/anaconda3/envs/cp1/lib/python3.8/site-packages/flask/app.py", line 1499, in dispatch_request
    return self.ensure_sync(self.view_functions[rule.endpoint])(**req.view_args)
  File "/Users/piat/s5/cp1/New/app/views/main_views.py", line 109, in result
    save_mastery(makedata(user.id, user.mastery)) # Ïú†Ï†Ä Ï±îÌîºÏñ∏ Ï†ïÎ≥¥ mongodbÏ†ÄÏû•
  File "/Users/piat/s5/cp1/New/riot_api/mongodb.py", line 66, in makedata
    championId = f"{data[i]['championId']}"
KeyError: 0
INFO:werkzeug:127.0.0.1 - - [28/Apr/2022 21:35:45] "[35m[1mGET /result?username=Ìï´ÏÉÅÎ≤î HTTP/1.1[0m" 500 -
DEBUG:urllib3.connectionpool:Starting new HTTPS connection (1): kr.api.riotgames.com:443
DEBUG:urllib3.connectionpool:https://kr.api.riotgames.com:443 "GET /lol/summoner/v4/summoners/by-name/%ED%95%AB%EC%83%81%EB%B2%94 HTTP/1.1" 200 None
DEBUG:urllib3.connectionpool:Starting new HTTPS connection (1): kr.api.riotgames.com:443
DEBUG:urllib3.connectionpool:https://kr.api.riotgames.com:443 "GET /lol/summoner/v4/summoners/by-name/%ED%95%AB%EC%83%81%EB%B2%94 HTTP/1.1" 200 None
DEBUG:urllib3.connectionpool:Starting new HTTPS connection (1): kr.api.riotgames.com:443
DEBUG:urllib3.connectionpool:https://kr.api.riotgames.com:443 "GET /lol/champion-mastery/v4/champion-masteries/by-summoner/XnhdEBDrdxzLMqJVhZBnhh6PI5WHJcbU7JZMncss1JBPiw HTTP/1.1" 200 None
DEBUG:urllib3.connectionpool:Starting new HTTPS connection (1): kr.api.riotgames.com:443
DEBUG:urllib3.connectionpool:https://kr.api.riotgames.com:443 "GET /lol/summoner/v4/summoners/by-name/%ED%95%AB%EC%83%81%EB%B2%94 HTTP/1.1" 200 None
DEBUG:urllib3.connectionpool:Starting new HTTPS connection (1): kr.api.riotgames.com:443
DEBUG:urllib3.connectionpool:https://kr.api.riotgames.com:443 "GET /lol/spectator/v4/active-games/by-summoner/XnhdEBDrdxzLMqJVhZBnhh6PI5WHJcbU7JZMncss1JBPiw HTTP/1.1" 503 None
INFO:werkzeug:127.0.0.1 - - [28/Apr/2022 21:36:51] "GET /result?username=Ìï´ÏÉÅÎ≤î HTTP/1.1" 200 -
INFO:werkzeug:127.0.0.1 - - [28/Apr/2022 21:36:51] "[36mGET /static/img/riot.png HTTP/1.1[0m" 304 -
