[2022-04-27 20:19:38,027] INFO in _internal:  * Running on http://127.0.0.1:5000/ (Press CTRL+C to quit)
[2022-04-27 20:19:38,029] INFO in _internal:  * Restarting with stat
[2022-04-27 20:25:55,454] INFO in _internal:  * Running on http://127.0.0.1:5000/ (Press CTRL+C to quit)
[2022-04-27 20:25:55,455] INFO in _internal:  * Restarting with stat
[2022-04-27 20:30:33,100] INFO in _internal:  * Restarting with stat
INFO:werkzeug: * Running on http://127.0.0.1:5000/ (Press CTRL+C to quit)
INFO:werkzeug: * Running on http://127.0.0.1:5000/ (Press CTRL+C to quit)
INFO:werkzeug:127.0.0.1 - - [28/Apr/2022 16:26:45] "GET / HTTP/1.1" 200 -
INFO:werkzeug:127.0.0.1 - - [28/Apr/2022 16:26:45] "[36mGET /static/img/riot.png HTTP/1.1[0m" 304 -
INFO:werkzeug:127.0.0.1 - - [28/Apr/2022 16:26:46] "[33mGET /favicon.ico HTTP/1.1[0m" 404 -
DEBUG:urllib3.connectionpool:Starting new HTTPS connection (1): kr.api.riotgames.com:443
DEBUG:urllib3.connectionpool:https://kr.api.riotgames.com:443 "GET /lol/summoner/v4/summoners/by-name/%ED%95%AB%EC%83%81%EB%B2%94 HTTP/1.1" 403 None
DEBUG:urllib3.connectionpool:Starting new HTTPS connection (1): kr.api.riotgames.com:443
DEBUG:urllib3.connectionpool:https://kr.api.riotgames.com:443 "GET /lol/summoner/v4/summoners/by-name/%ED%95%AB%EC%83%81%EB%B2%94 HTTP/1.1" 200 None
DEBUG:urllib3.connectionpool:Starting new HTTPS connection (1): kr.api.riotgames.com:443
DEBUG:urllib3.connectionpool:https://kr.api.riotgames.com:443 "GET /lol/spectator/v4/active-games/by-summoner/XnhdEBDrdxzLMqJVhZBnhh6PI5WHJcbU7JZMncss1JBPiw HTTP/1.1" 403 None
DEBUG:urllib3.connectionpool:Starting new HTTPS connection (1): kr.api.riotgames.com:443
DEBUG:urllib3.connectionpool:https://kr.api.riotgames.com:443 "GET /lol/spectator/v4/active-games/by-summoner/XnhdEBDrdxzLMqJVhZBnhh6PI5WHJcbU7JZMncss1JBPiw HTTP/1.1" 503 None
ERROR:app:Exception on /result [GET]
Traceback (most recent call last):
  File "/Users/piat/opt/anaconda3/envs/cp1/lib/python3.8/site-packages/flask/app.py", line 2070, in wsgi_app
    response = self.full_dispatch_request()
  File "/Users/piat/opt/anaconda3/envs/cp1/lib/python3.8/site-packages/flask/app.py", line 1515, in full_dispatch_request
    rv = self.handle_user_exception(e)
  File "/Users/piat/opt/anaconda3/envs/cp1/lib/python3.8/site-packages/flask/app.py", line 1513, in full_dispatch_request
    rv = self.dispatch_request()
  File "/Users/piat/opt/anaconda3/envs/cp1/lib/python3.8/site-packages/flask/app.py", line 1499, in dispatch_request
    return self.ensure_sync(self.view_functions[rule.endpoint])(**req.view_args)
  File "/Users/piat/s5/cp1/New/app/views/main_views.py", line 114, in result
    summoner_Id = data['participants'][i]['summonerId']
KeyError: 'participants'
INFO:werkzeug:127.0.0.1 - - [28/Apr/2022 16:27:03] "[35m[1mGET /result?username=Ìï´ÏÉÅÎ≤î HTTP/1.1[0m" 500 -
INFO:werkzeug: * Running on http://127.0.0.1:5000/ (Press CTRL+C to quit)
DEBUG:urllib3.connectionpool:Starting new HTTPS connection (1): kr.api.riotgames.com:443
DEBUG:urllib3.connectionpool:https://kr.api.riotgames.com:443 "GET /lol/summoner/v4/summoners/by-name/%ED%95%AB%EC%83%81%EB%B2%94 HTTP/1.1" 200 None
DEBUG:urllib3.connectionpool:Starting new HTTPS connection (1): kr.api.riotgames.com:443
DEBUG:urllib3.connectionpool:https://kr.api.riotgames.com:443 "GET /lol/summoner/v4/summoners/by-name/%ED%95%AB%EC%83%81%EB%B2%94 HTTP/1.1" 200 None
DEBUG:urllib3.connectionpool:Starting new HTTPS connection (1): kr.api.riotgames.com:443
DEBUG:urllib3.connectionpool:https://kr.api.riotgames.com:443 "GET /lol/spectator/v4/active-games/by-summoner/XnhdEBDrdxzLMqJVhZBnhh6PI5WHJcbU7JZMncss1JBPiw HTTP/1.1" 503 None
INFO:werkzeug:127.0.0.1 - - [28/Apr/2022 16:33:20] "GET /result?username=Ìï´ÏÉÅÎ≤î HTTP/1.1" 200 -
INFO:werkzeug:127.0.0.1 - - [28/Apr/2022 16:33:20] "[36mGET /static/img/riot.png HTTP/1.1[0m" 304 -
INFO:werkzeug:127.0.0.1 - - [28/Apr/2022 16:33:23] "GET / HTTP/1.1" 200 -
INFO:werkzeug:127.0.0.1 - - [28/Apr/2022 16:33:23] "[36mGET /static/img/riot.png HTTP/1.1[0m" 304 -
INFO:werkzeug: * Running on http://127.0.0.1:5000/ (Press CTRL+C to quit)
INFO:werkzeug:127.0.0.1 - - [28/Apr/2022 17:19:33] "GET / HTTP/1.1" 200 -
INFO:werkzeug:127.0.0.1 - - [28/Apr/2022 17:19:33] "[36mGET /static/img/riot.png HTTP/1.1[0m" 304 -
DEBUG:urllib3.connectionpool:Starting new HTTPS connection (1): kr.api.riotgames.com:443
DEBUG:urllib3.connectionpool:https://kr.api.riotgames.com:443 "GET /lol/summoner/v4/summoners/by-name/%ED%95%AB%EC%83%81%EB%B2%94 HTTP/1.1" 200 None
DEBUG:urllib3.connectionpool:Starting new HTTPS connection (1): kr.api.riotgames.com:443
DEBUG:urllib3.connectionpool:https://kr.api.riotgames.com:443 "GET /lol/summoner/v4/summoners/by-name/%ED%95%AB%EC%83%81%EB%B2%94 HTTP/1.1" 200 None
DEBUG:urllib3.connectionpool:Starting new HTTPS connection (1): kr.api.riotgames.com:443
DEBUG:urllib3.connectionpool:https://kr.api.riotgames.com:443 "GET /lol/spectator/v4/active-games/by-summoner/XnhdEBDrdxzLMqJVhZBnhh6PI5WHJcbU7JZMncss1JBPiw HTTP/1.1" 503 None
INFO:werkzeug:127.0.0.1 - - [28/Apr/2022 17:19:46] "GET /result?username=Ìï´ÏÉÅÎ≤î HTTP/1.1" 200 -
INFO:werkzeug:127.0.0.1 - - [28/Apr/2022 17:19:46] "[36mGET /static/img/riot.png HTTP/1.1[0m" 304 -
INFO:werkzeug: * Running on http://127.0.0.1:5000/ (Press CTRL+C to quit)
ERROR:app:Exception on /result [GET]
Traceback (most recent call last):
  File "/Users/piat/opt/anaconda3/envs/cp1/lib/python3.8/site-packages/flask/app.py", line 2070, in wsgi_app
    response = self.full_dispatch_request()
  File "/Users/piat/opt/anaconda3/envs/cp1/lib/python3.8/site-packages/flask/app.py", line 1515, in full_dispatch_request
    rv = self.handle_user_exception(e)
  File "/Users/piat/opt/anaconda3/envs/cp1/lib/python3.8/site-packages/flask/app.py", line 1513, in full_dispatch_request
    rv = self.dispatch_request()
  File "/Users/piat/opt/anaconda3/envs/cp1/lib/python3.8/site-packages/flask/app.py", line 1499, in dispatch_request
    return self.ensure_sync(self.view_functions[rule.endpoint])(**req.view_args)
  File "/Users/piat/s5/cp1/New/app/views/main_views.py", line 63, in result
    from riot_api.name import sumoners
  File "/Users/piat/s5/cp1/New/riot_api/name.py", line 1, in <module>
    from api import *
ModuleNotFoundError: No module named 'api'
INFO:werkzeug:127.0.0.1 - - [28/Apr/2022 17:45:41] "[35m[1mGET /result?username=Ìï´ÏÉÅÎ≤î HTTP/1.1[0m" 500 -
ERROR:app:Exception on /result [GET]
Traceback (most recent call last):
  File "/Users/piat/opt/anaconda3/envs/cp1/lib/python3.8/site-packages/flask/app.py", line 2070, in wsgi_app
    response = self.full_dispatch_request()
  File "/Users/piat/opt/anaconda3/envs/cp1/lib/python3.8/site-packages/flask/app.py", line 1515, in full_dispatch_request
    rv = self.handle_user_exception(e)
  File "/Users/piat/opt/anaconda3/envs/cp1/lib/python3.8/site-packages/flask/app.py", line 1513, in full_dispatch_request
    rv = self.dispatch_request()
  File "/Users/piat/opt/anaconda3/envs/cp1/lib/python3.8/site-packages/flask/app.py", line 1499, in dispatch_request
    return self.ensure_sync(self.view_functions[rule.endpoint])(**req.view_args)
  File "/Users/piat/s5/cp1/New/app/views/main_views.py", line 72, in result
    m = url_check(url_nick)
NameError: name 'url_check' is not defined
INFO:werkzeug:127.0.0.1 - - [28/Apr/2022 17:47:56] "[35m[1mGET /result?username=Ìï´ÏÉÅÎ≤î HTTP/1.1[0m" 500 -
ERROR:app:Exception on /result [GET]
Traceback (most recent call last):
  File "/Users/piat/opt/anaconda3/envs/cp1/lib/python3.8/site-packages/flask/app.py", line 2070, in wsgi_app
    response = self.full_dispatch_request()
  File "/Users/piat/opt/anaconda3/envs/cp1/lib/python3.8/site-packages/flask/app.py", line 1515, in full_dispatch_request
    rv = self.handle_user_exception(e)
  File "/Users/piat/opt/anaconda3/envs/cp1/lib/python3.8/site-packages/flask/app.py", line 1513, in full_dispatch_request
    rv = self.dispatch_request()
  File "/Users/piat/opt/anaconda3/envs/cp1/lib/python3.8/site-packages/flask/app.py", line 1499, in dispatch_request
    return self.ensure_sync(self.view_functions[rule.endpoint])(**req.view_args)
  File "/Users/piat/s5/cp1/New/app/views/main_views.py", line 72, in result
    m = url_check(url_nick)
NameError: name 'url_check' is not defined
INFO:werkzeug:127.0.0.1 - - [28/Apr/2022 17:48:28] "[35m[1mGET /result?username=Ìï´ÏÉÅÎ≤î HTTP/1.1[0m" 500 -
ERROR:app:Exception on /result [GET]
Traceback (most recent call last):
  File "/Users/piat/opt/anaconda3/envs/cp1/lib/python3.8/site-packages/flask/app.py", line 2070, in wsgi_app
    response = self.full_dispatch_request()
  File "/Users/piat/opt/anaconda3/envs/cp1/lib/python3.8/site-packages/flask/app.py", line 1515, in full_dispatch_request
    rv = self.handle_user_exception(e)
  File "/Users/piat/opt/anaconda3/envs/cp1/lib/python3.8/site-packages/flask/app.py", line 1513, in full_dispatch_request
    rv = self.dispatch_request()
  File "/Users/piat/opt/anaconda3/envs/cp1/lib/python3.8/site-packages/flask/app.py", line 1499, in dispatch_request
    return self.ensure_sync(self.view_functions[rule.endpoint])(**req.view_args)
  File "/Users/piat/s5/cp1/New/app/views/main_views.py", line 72, in result
    m = url_check(url_nick)
NameError: name 'url_check' is not defined
INFO:werkzeug:127.0.0.1 - - [28/Apr/2022 17:48:56] "[35m[1mGET /result?username=Ìï´ÏÉÅÎ≤î HTTP/1.1[0m" 500 -
INFO:werkzeug: * Running on http://127.0.0.1:5000/ (Press CTRL+C to quit)
DEBUG:urllib3.connectionpool:Starting new HTTPS connection (1): kr.api.riotgames.com:443
DEBUG:urllib3.connectionpool:https://kr.api.riotgames.com:443 "GET /lol/summoner/v4/summoners/by-name/%ED%95%AB%EC%83%81%EB%B2%94 HTTP/1.1" 200 None
DEBUG:urllib3.connectionpool:Starting new HTTPS connection (1): kr.api.riotgames.com:443
DEBUG:urllib3.connectionpool:https://kr.api.riotgames.com:443 "GET /lol/summoner/v4/summoners/by-name/%ED%95%AB%EC%83%81%EB%B2%94 HTTP/1.1" 200 None
DEBUG:urllib3.connectionpool:Starting new HTTPS connection (1): kr.api.riotgames.com:443
DEBUG:urllib3.connectionpool:https://kr.api.riotgames.com:443 "GET /lol/champion-mastery/v4/champion-masteries/by-summoner/XnhdEBDrdxzLMqJVhZBnhh6PI5WHJcbU7JZMncss1JBPiw HTTP/1.1" 200 None
ERROR:app:Exception on /result [GET]
Traceback (most recent call last):
  File "/Users/piat/opt/anaconda3/envs/cp1/lib/python3.8/site-packages/flask/app.py", line 2070, in wsgi_app
    response = self.full_dispatch_request()
  File "/Users/piat/opt/anaconda3/envs/cp1/lib/python3.8/site-packages/flask/app.py", line 1515, in full_dispatch_request
    rv = self.handle_user_exception(e)
  File "/Users/piat/opt/anaconda3/envs/cp1/lib/python3.8/site-packages/flask/app.py", line 1513, in full_dispatch_request
    rv = self.dispatch_request()
  File "/Users/piat/opt/anaconda3/envs/cp1/lib/python3.8/site-packages/flask/app.py", line 1499, in dispatch_request
    return self.ensure_sync(self.view_functions[rule.endpoint])(**req.view_args)
  File "/Users/piat/s5/cp1/New/app/views/main_views.py", line 96, in result
    save_userinfo(user_info_data) # Ïú†Ï†ÄÏ†ïÎ≥¥ mongodbÏ†ÄÏû•
NameError: name 'save_userinfo' is not defined
INFO:werkzeug:127.0.0.1 - - [28/Apr/2022 17:49:37] "[35m[1mGET /result?username=Ìï´ÏÉÅÎ≤î HTTP/1.1[0m" 500 -
INFO:werkzeug: * Running on http://127.0.0.1:5000/ (Press CTRL+C to quit)
DEBUG:urllib3.connectionpool:Starting new HTTPS connection (1): kr.api.riotgames.com:443
DEBUG:urllib3.connectionpool:https://kr.api.riotgames.com:443 "GET /lol/summoner/v4/summoners/by-name/%ED%95%AB%EC%83%81%EB%B2%94 HTTP/1.1" 200 None
DEBUG:urllib3.connectionpool:Starting new HTTPS connection (1): kr.api.riotgames.com:443
DEBUG:urllib3.connectionpool:https://kr.api.riotgames.com:443 "GET /lol/summoner/v4/summoners/by-name/%ED%95%AB%EC%83%81%EB%B2%94 HTTP/1.1" 200 None
DEBUG:urllib3.connectionpool:Starting new HTTPS connection (1): kr.api.riotgames.com:443
DEBUG:urllib3.connectionpool:https://kr.api.riotgames.com:443 "GET /lol/champion-mastery/v4/champion-masteries/by-summoner/XnhdEBDrdxzLMqJVhZBnhh6PI5WHJcbU7JZMncss1JBPiw HTTP/1.1" 200 None
ERROR:app:Exception on /result [GET]
Traceback (most recent call last):
  File "/Users/piat/opt/anaconda3/envs/cp1/lib/python3.8/site-packages/flask/app.py", line 2070, in wsgi_app
    response = self.full_dispatch_request()
  File "/Users/piat/opt/anaconda3/envs/cp1/lib/python3.8/site-packages/flask/app.py", line 1515, in full_dispatch_request
    rv = self.handle_user_exception(e)
  File "/Users/piat/opt/anaconda3/envs/cp1/lib/python3.8/site-packages/flask/app.py", line 1513, in full_dispatch_request
    rv = self.dispatch_request()
  File "/Users/piat/opt/anaconda3/envs/cp1/lib/python3.8/site-packages/flask/app.py", line 1499, in dispatch_request
    return self.ensure_sync(self.view_functions[rule.endpoint])(**req.view_args)
  File "/Users/piat/s5/cp1/New/app/views/main_views.py", line 96, in result
    save_userinfo(user_info_data) # Ïú†Ï†ÄÏ†ïÎ≥¥ mongodbÏ†ÄÏû•
  File "/Users/piat/s5/cp1/New/riot_api/mongodb.py", line 55, in save_userinfo
    col.insert_one(data_name)
  File "/Users/piat/opt/anaconda3/envs/cp1/lib/python3.8/site-packages/pymongo/collection.py", line 698, in insert_one
    self._insert(document,
  File "/Users/piat/opt/anaconda3/envs/cp1/lib/python3.8/site-packages/pymongo/collection.py", line 613, in _insert
    return self._insert_one(
  File "/Users/piat/opt/anaconda3/envs/cp1/lib/python3.8/site-packages/pymongo/collection.py", line 602, in _insert_one
    self.__database.client._retryable_write(
  File "/Users/piat/opt/anaconda3/envs/cp1/lib/python3.8/site-packages/pymongo/mongo_client.py", line 1498, in _retryable_write
    return self._retry_with_session(retryable, func, s, None)
  File "/Users/piat/opt/anaconda3/envs/cp1/lib/python3.8/site-packages/pymongo/mongo_client.py", line 1384, in _retry_with_session
    return self._retry_internal(retryable, func, session, bulk)
  File "/Users/piat/opt/anaconda3/envs/cp1/lib/python3.8/site-packages/pymongo/mongo_client.py", line 1416, in _retry_internal
    return func(session, sock_info, retryable)
  File "/Users/piat/opt/anaconda3/envs/cp1/lib/python3.8/site-packages/pymongo/collection.py", line 600, in _insert_command
    _check_write_command_response(result)
  File "/Users/piat/opt/anaconda3/envs/cp1/lib/python3.8/site-packages/pymongo/helpers.py", line 226, in _check_write_command_response
    _raise_last_write_error(write_errors)
  File "/Users/piat/opt/anaconda3/envs/cp1/lib/python3.8/site-packages/pymongo/helpers.py", line 207, in _raise_last_write_error
    raise DuplicateKeyError(error.get("errmsg"), 11000, error)
pymongo.errors.DuplicateKeyError: E11000 duplicate key error collection: loldata.userinfo index: _id_ dup key: { _id: "XnhdEBDrdxzLMqJVhZBnhh6PI5WHJcbU7JZMncss1JBPiw" }, full error: {'index': 0, 'code': 11000, 'keyPattern': {'_id': 1}, 'keyValue': {'_id': 'XnhdEBDrdxzLMqJVhZBnhh6PI5WHJcbU7JZMncss1JBPiw'}, 'errmsg': 'E11000 duplicate key error collection: loldata.userinfo index: _id_ dup key: { _id: "XnhdEBDrdxzLMqJVhZBnhh6PI5WHJcbU7JZMncss1JBPiw" }'}
INFO:werkzeug:127.0.0.1 - - [28/Apr/2022 17:50:21] "[35m[1mGET /result?username=Ìï´ÏÉÅÎ≤î HTTP/1.1[0m" 500 -
INFO:werkzeug: * Running on http://127.0.0.1:5000/ (Press CTRL+C to quit)
ERROR:app:Exception on /result [GET]
Traceback (most recent call last):
  File "/Users/piat/opt/anaconda3/envs/cp1/lib/python3.8/site-packages/flask/app.py", line 2070, in wsgi_app
    response = self.full_dispatch_request()
  File "/Users/piat/opt/anaconda3/envs/cp1/lib/python3.8/site-packages/flask/app.py", line 1515, in full_dispatch_request
    rv = self.handle_user_exception(e)
  File "/Users/piat/opt/anaconda3/envs/cp1/lib/python3.8/site-packages/flask/app.py", line 1513, in full_dispatch_request
    rv = self.dispatch_request()
  File "/Users/piat/opt/anaconda3/envs/cp1/lib/python3.8/site-packages/flask/app.py", line 1499, in dispatch_request
    return self.ensure_sync(self.view_functions[rule.endpoint])(**req.view_args)
  File "/Users/piat/s5/cp1/New/app/views/main_views.py", line 63, in result
    from riot_api.name import sumoners
  File "/Users/piat/s5/cp1/New/riot_api/name.py", line 1, in <module>
    from api import *
ModuleNotFoundError: No module named 'api'
INFO:werkzeug:127.0.0.1 - - [28/Apr/2022 19:21:32] "[35m[1mGET /result?username=Ìï´ÏÉÅÎ≤î HTTP/1.1[0m" 500 -
INFO:werkzeug: * Running on http://127.0.0.1:5000/ (Press CTRL+C to quit)
DEBUG:urllib3.connectionpool:Starting new HTTPS connection (1): kr.api.riotgames.com:443
DEBUG:urllib3.connectionpool:https://kr.api.riotgames.com:443 "GET /lol/summoner/v4/summoners/by-name/%ED%95%AB%EC%83%81%EB%B2%94 HTTP/1.1" 200 None
DEBUG:urllib3.connectionpool:Starting new HTTPS connection (1): kr.api.riotgames.com:443
DEBUG:urllib3.connectionpool:https://kr.api.riotgames.com:443 "GET /lol/summoner/v4/summoners/by-name/%ED%95%AB%EC%83%81%EB%B2%94 HTTP/1.1" 200 None
DEBUG:urllib3.connectionpool:Starting new HTTPS connection (1): kr.api.riotgames.com:443
DEBUG:urllib3.connectionpool:https://kr.api.riotgames.com:443 "GET /lol/champion-mastery/v4/champion-masteries/by-summoner/XnhdEBDrdxzLMqJVhZBnhh6PI5WHJcbU7JZMncss1JBPiw HTTP/1.1" 200 None
ERROR:app:Exception on /result [GET]
Traceback (most recent call last):
  File "/Users/piat/opt/anaconda3/envs/cp1/lib/python3.8/site-packages/flask/app.py", line 2070, in wsgi_app
    response = self.full_dispatch_request()
  File "/Users/piat/opt/anaconda3/envs/cp1/lib/python3.8/site-packages/flask/app.py", line 1515, in full_dispatch_request
    rv = self.handle_user_exception(e)
  File "/Users/piat/opt/anaconda3/envs/cp1/lib/python3.8/site-packages/flask/app.py", line 1513, in full_dispatch_request
    rv = self.dispatch_request()
  File "/Users/piat/opt/anaconda3/envs/cp1/lib/python3.8/site-packages/flask/app.py", line 1499, in dispatch_request
    return self.ensure_sync(self.view_functions[rule.endpoint])(**req.view_args)
  File "/Users/piat/s5/cp1/New/app/views/main_views.py", line 96, in result
    save_userinfo(user_info_data) # Ïú†Ï†ÄÏ†ïÎ≥¥ mongodbÏ†ÄÏû•
  File "/Users/piat/s5/cp1/New/riot_api/mongodb.py", line 54, in save_userinfo
    if list(col.find_one({'_id':data_name['_id']}).values()) in data_name['_id']:
TypeError: 'in <string>' requires string as left operand, not list
INFO:werkzeug:127.0.0.1 - - [28/Apr/2022 19:22:21] "[35m[1mGET /result?username=Ìï´ÏÉÅÎ≤î HTTP/1.1[0m" 500 -
DEBUG:urllib3.connectionpool:Starting new HTTPS connection (1): kr.api.riotgames.com:443
DEBUG:urllib3.connectionpool:https://kr.api.riotgames.com:443 "GET /lol/summoner/v4/summoners/by-name/%ED%95%AB%EC%83%81%EB%B2%94 HTTP/1.1" 200 None
DEBUG:urllib3.connectionpool:Starting new HTTPS connection (1): kr.api.riotgames.com:443
DEBUG:urllib3.connectionpool:https://kr.api.riotgames.com:443 "GET /lol/summoner/v4/summoners/by-name/%ED%95%AB%EC%83%81%EB%B2%94 HTTP/1.1" 200 None
DEBUG:urllib3.connectionpool:Starting new HTTPS connection (1): kr.api.riotgames.com:443
DEBUG:urllib3.connectionpool:https://kr.api.riotgames.com:443 "GET /lol/champion-mastery/v4/champion-masteries/by-summoner/XnhdEBDrdxzLMqJVhZBnhh6PI5WHJcbU7JZMncss1JBPiw HTTP/1.1" 200 None
ERROR:app:Exception on /result [GET]
Traceback (most recent call last):
  File "/Users/piat/opt/anaconda3/envs/cp1/lib/python3.8/site-packages/flask/app.py", line 2070, in wsgi_app
    response = self.full_dispatch_request()
  File "/Users/piat/opt/anaconda3/envs/cp1/lib/python3.8/site-packages/flask/app.py", line 1515, in full_dispatch_request
    rv = self.handle_user_exception(e)
  File "/Users/piat/opt/anaconda3/envs/cp1/lib/python3.8/site-packages/flask/app.py", line 1513, in full_dispatch_request
    rv = self.dispatch_request()
  File "/Users/piat/opt/anaconda3/envs/cp1/lib/python3.8/site-packages/flask/app.py", line 1499, in dispatch_request
    return self.ensure_sync(self.view_functions[rule.endpoint])(**req.view_args)
  File "/Users/piat/s5/cp1/New/app/views/main_views.py", line 96, in result
    save_userinfo(user_info_data) # Ïú†Ï†ÄÏ†ïÎ≥¥ mongodbÏ†ÄÏû•
  File "/Users/piat/s5/cp1/New/riot_api/mongodb.py", line 54, in save_userinfo
    if data_name['_id'] in list(col.find_one({'_id':data_name['_id']}).values()):
TypeError: 'in <string>' requires string as left operand, not list
INFO:werkzeug:127.0.0.1 - - [28/Apr/2022 19:23:15] "[35m[1mGET /result?username=Ìï´ÏÉÅÎ≤î HTTP/1.1[0m" 500 -
INFO:werkzeug: * Running on http://127.0.0.1:5000/ (Press CTRL+C to quit)
DEBUG:urllib3.connectionpool:Starting new HTTPS connection (1): kr.api.riotgames.com:443
DEBUG:urllib3.connectionpool:https://kr.api.riotgames.com:443 "GET /lol/summoner/v4/summoners/by-name/%ED%95%AB%EC%83%81%EB%B2%94 HTTP/1.1" 200 None
DEBUG:urllib3.connectionpool:Starting new HTTPS connection (1): kr.api.riotgames.com:443
DEBUG:urllib3.connectionpool:https://kr.api.riotgames.com:443 "GET /lol/summoner/v4/summoners/by-name/%ED%95%AB%EC%83%81%EB%B2%94 HTTP/1.1" 200 None
DEBUG:urllib3.connectionpool:Starting new HTTPS connection (1): kr.api.riotgames.com:443
DEBUG:urllib3.connectionpool:https://kr.api.riotgames.com:443 "GET /lol/champion-mastery/v4/champion-masteries/by-summoner/XnhdEBDrdxzLMqJVhZBnhh6PI5WHJcbU7JZMncss1JBPiw HTTP/1.1" 200 None
ERROR:app:Exception on /result [GET]
Traceback (most recent call last):
  File "/Users/piat/opt/anaconda3/envs/cp1/lib/python3.8/site-packages/flask/app.py", line 2070, in wsgi_app
    response = self.full_dispatch_request()
  File "/Users/piat/opt/anaconda3/envs/cp1/lib/python3.8/site-packages/flask/app.py", line 1515, in full_dispatch_request
    rv = self.handle_user_exception(e)
  File "/Users/piat/opt/anaconda3/envs/cp1/lib/python3.8/site-packages/flask/app.py", line 1513, in full_dispatch_request
    rv = self.dispatch_request()
  File "/Users/piat/opt/anaconda3/envs/cp1/lib/python3.8/site-packages/flask/app.py", line 1499, in dispatch_request
    return self.ensure_sync(self.view_functions[rule.endpoint])(**req.view_args)
  File "/Users/piat/s5/cp1/New/app/views/main_views.py", line 96, in result
    save_userinfo(user_info_data) # Ïú†Ï†ÄÏ†ïÎ≥¥ mongodbÏ†ÄÏû•
  File "/Users/piat/s5/cp1/New/riot_api/mongodb.py", line 55, in save_userinfo
    col.update(data_name)
TypeError: update() missing 1 required positional argument: 'document'
INFO:werkzeug:127.0.0.1 - - [28/Apr/2022 19:26:05] "[35m[1mGET /result?username=Ìï´ÏÉÅÎ≤î HTTP/1.1[0m" 500 -
INFO:werkzeug: * Running on http://127.0.0.1:5000/ (Press CTRL+C to quit)
DEBUG:urllib3.connectionpool:Starting new HTTPS connection (1): kr.api.riotgames.com:443
DEBUG:urllib3.connectionpool:https://kr.api.riotgames.com:443 "GET /lol/summoner/v4/summoners/by-name/%ED%95%AB%EC%83%81%EB%B2%94 HTTP/1.1" 200 None
DEBUG:urllib3.connectionpool:Starting new HTTPS connection (1): kr.api.riotgames.com:443
DEBUG:urllib3.connectionpool:https://kr.api.riotgames.com:443 "GET /lol/summoner/v4/summoners/by-name/%ED%95%AB%EC%83%81%EB%B2%94 HTTP/1.1" 200 None
DEBUG:urllib3.connectionpool:Starting new HTTPS connection (1): kr.api.riotgames.com:443
DEBUG:urllib3.connectionpool:https://kr.api.riotgames.com:443 "GET /lol/champion-mastery/v4/champion-masteries/by-summoner/XnhdEBDrdxzLMqJVhZBnhh6PI5WHJcbU7JZMncss1JBPiw HTTP/1.1" 200 None
ERROR:app:Exception on /result [GET]
Traceback (most recent call last):
  File "/Users/piat/opt/anaconda3/envs/cp1/lib/python3.8/site-packages/flask/app.py", line 2070, in wsgi_app
    response = self.full_dispatch_request()
  File "/Users/piat/opt/anaconda3/envs/cp1/lib/python3.8/site-packages/flask/app.py", line 1515, in full_dispatch_request
    rv = self.handle_user_exception(e)
  File "/Users/piat/opt/anaconda3/envs/cp1/lib/python3.8/site-packages/flask/app.py", line 1513, in full_dispatch_request
    rv = self.dispatch_request()
  File "/Users/piat/opt/anaconda3/envs/cp1/lib/python3.8/site-packages/flask/app.py", line 1499, in dispatch_request
    return self.ensure_sync(self.view_functions[rule.endpoint])(**req.view_args)
  File "/Users/piat/s5/cp1/New/app/views/main_views.py", line 97, in result
    save_mastery(makedata(user.mastery)) # Ïú†Ï†Ä Ï±îÌîºÏñ∏ Ï†ïÎ≥¥ mongodbÏ†ÄÏû•
TypeError: makedata() missing 1 required positional argument: 'data'
INFO:werkzeug:127.0.0.1 - - [28/Apr/2022 19:30:04] "[35m[1mGET /result?username=Ìï´ÏÉÅÎ≤î HTTP/1.1[0m" 500 -
INFO:werkzeug: * Running on http://127.0.0.1:5000/ (Press CTRL+C to quit)
DEBUG:urllib3.connectionpool:Starting new HTTPS connection (1): kr.api.riotgames.com:443
DEBUG:urllib3.connectionpool:https://kr.api.riotgames.com:443 "GET /lol/summoner/v4/summoners/by-name/%ED%95%AB%EC%83%81%EB%B2%94 HTTP/1.1" 200 None
DEBUG:urllib3.connectionpool:Starting new HTTPS connection (1): kr.api.riotgames.com:443
DEBUG:urllib3.connectionpool:https://kr.api.riotgames.com:443 "GET /lol/summoner/v4/summoners/by-name/%ED%95%AB%EC%83%81%EB%B2%94 HTTP/1.1" 200 None
DEBUG:urllib3.connectionpool:Starting new HTTPS connection (1): kr.api.riotgames.com:443
DEBUG:urllib3.connectionpool:https://kr.api.riotgames.com:443 "GET /lol/champion-mastery/v4/champion-masteries/by-summoner/XnhdEBDrdxzLMqJVhZBnhh6PI5WHJcbU7JZMncss1JBPiw HTTP/1.1" 200 None
DEBUG:urllib3.connectionpool:Starting new HTTPS connection (1): kr.api.riotgames.com:443
DEBUG:urllib3.connectionpool:https://kr.api.riotgames.com:443 "GET /lol/summoner/v4/summoners/by-name/%ED%95%AB%EC%83%81%EB%B2%94 HTTP/1.1" 200 None
DEBUG:urllib3.connectionpool:Starting new HTTPS connection (1): kr.api.riotgames.com:443
DEBUG:urllib3.connectionpool:https://kr.api.riotgames.com:443 "GET /lol/spectator/v4/active-games/by-summoner/XnhdEBDrdxzLMqJVhZBnhh6PI5WHJcbU7JZMncss1JBPiw HTTP/1.1" 503 None
INFO:werkzeug:127.0.0.1 - - [28/Apr/2022 19:31:43] "GET /result?username=Ìï´ÏÉÅÎ≤î HTTP/1.1" 200 -
INFO:werkzeug:127.0.0.1 - - [28/Apr/2022 19:31:43] "[36mGET /static/img/riot.png HTTP/1.1[0m" 304 -
INFO:werkzeug: * Running on http://127.0.0.1:5000/ (Press CTRL+C to quit)
INFO:werkzeug: * Running on http://127.0.0.1:5000/ (Press CTRL+C to quit)
ERROR:app:Exception on /result [GET]
Traceback (most recent call last):
  File "/Users/piat/opt/anaconda3/envs/cp1/lib/python3.8/site-packages/flask/app.py", line 2070, in wsgi_app
    response = self.full_dispatch_request()
  File "/Users/piat/opt/anaconda3/envs/cp1/lib/python3.8/site-packages/flask/app.py", line 1515, in full_dispatch_request
    rv = self.handle_user_exception(e)
  File "/Users/piat/opt/anaconda3/envs/cp1/lib/python3.8/site-packages/flask/app.py", line 1513, in full_dispatch_request
    rv = self.dispatch_request()
  File "/Users/piat/opt/anaconda3/envs/cp1/lib/python3.8/site-packages/flask/app.py", line 1499, in dispatch_request
    return self.ensure_sync(self.view_functions[rule.endpoint])(**req.view_args)
  File "/Users/piat/s5/cp1/New/app/views/main_views.py", line 66, in result
    from riot_api.name import sumoners
  File "/Users/piat/s5/cp1/New/riot_api/name.py", line 1, in <module>
    from api import *
ModuleNotFoundError: No module named 'api'
INFO:werkzeug:127.0.0.1 - - [28/Apr/2022 20:56:21] "[35m[1mGET /result?username= HTTP/1.1[0m" 500 -
DEBUG:urllib3.connectionpool:Starting new HTTPS connection (1): kr.api.riotgames.com:443
DEBUG:urllib3.connectionpool:https://kr.api.riotgames.com:443 "GET /lol/summoner/v4/summoners/by-name/ HTTP/1.1" 403 None
INFO:werkzeug:127.0.0.1 - - [28/Apr/2022 20:56:46] "GET /result?username= HTTP/1.1" 200 -
INFO:werkzeug:127.0.0.1 - - [28/Apr/2022 20:56:46] "[36mGET /static/img/riot.png HTTP/1.1[0m" 304 -
INFO:werkzeug: * Running on http://127.0.0.1:5000/ (Press CTRL+C to quit)
INFO:werkzeug:127.0.0.1 - - [28/Apr/2022 21:13:36] "GET / HTTP/1.1" 200 -
INFO:werkzeug:127.0.0.1 - - [28/Apr/2022 21:13:36] "[36mGET /static/img/riot.png HTTP/1.1[0m" 304 -
DEBUG:urllib3.connectionpool:Starting new HTTPS connection (1): kr.api.riotgames.com:443
DEBUG:urllib3.connectionpool:https://kr.api.riotgames.com:443 "GET /lol/summoner/v4/summoners/by-name/ HTTP/1.1" 403 None
INFO:werkzeug:127.0.0.1 - - [28/Apr/2022 21:13:42] "GET /result?username= HTTP/1.1" 200 -
INFO:werkzeug:127.0.0.1 - - [28/Apr/2022 21:13:42] "[36mGET /static/img/riot.png HTTP/1.1[0m" 304 -
INFO:werkzeug: * Running on http://127.0.0.1:5000/ (Press CTRL+C to quit)
INFO:werkzeug:127.0.0.1 - - [28/Apr/2022 21:14:53] "GET / HTTP/1.1" 200 -
INFO:werkzeug:127.0.0.1 - - [28/Apr/2022 21:14:53] "[36mGET /static/img/riot.png HTTP/1.1[0m" 304 -
DEBUG:urllib3.connectionpool:Starting new HTTPS connection (1): kr.api.riotgames.com:443
DEBUG:urllib3.connectionpool:https://kr.api.riotgames.com:443 "GET /lol/summoner/v4/summoners/by-name/ HTTP/1.1" 403 None
INFO:werkzeug:127.0.0.1 - - [28/Apr/2022 21:14:57] "GET /result?username= HTTP/1.1" 200 -
INFO:werkzeug:127.0.0.1 - - [28/Apr/2022 21:14:57] "[36mGET /static/img/riot.png HTTP/1.1[0m" 304 -
INFO:werkzeug:127.0.0.1 - - [28/Apr/2022 21:15:13] "GET / HTTP/1.1" 200 -
INFO:werkzeug:127.0.0.1 - - [28/Apr/2022 21:15:13] "[36mGET /static/img/riot.png HTTP/1.1[0m" 304 -
INFO:werkzeug: * Running on http://127.0.0.1:5000/ (Press CTRL+C to quit)
DEBUG:urllib3.connectionpool:Starting new HTTPS connection (1): kr.api.riotgames.com:443
DEBUG:urllib3.connectionpool:https://kr.api.riotgames.com:443 "GET /lol/summoner/v4/summoners/by-name/%ED%95%AB%EC%83%81%EB%B2%94 HTTP/1.1" 200 None
DEBUG:urllib3.connectionpool:Starting new HTTPS connection (1): kr.api.riotgames.com:443
DEBUG:urllib3.connectionpool:https://kr.api.riotgames.com:443 "GET /lol/summoner/v4/summoners/by-name/%ED%95%AB%EC%83%81%EB%B2%94 HTTP/1.1" 200 None
DEBUG:urllib3.connectionpool:Starting new HTTPS connection (1): kr.api.riotgames.com:443
DEBUG:urllib3.connectionpool:https://kr.api.riotgames.com:443 "GET /lol/champion-mastery/v4/champion-masteries/by-summoner/XnhdEBDrdxzLMqJVhZBnhh6PI5WHJcbU7JZMncss1JBPiw HTTP/1.1" 200 None
ERROR:app:Exception on /result [GET]
Traceback (most recent call last):
  File "/Users/piat/opt/anaconda3/envs/cp1/lib/python3.8/site-packages/flask/app.py", line 2070, in wsgi_app
    response = self.full_dispatch_request()
  File "/Users/piat/opt/anaconda3/envs/cp1/lib/python3.8/site-packages/flask/app.py", line 1515, in full_dispatch_request
    rv = self.handle_user_exception(e)
  File "/Users/piat/opt/anaconda3/envs/cp1/lib/python3.8/site-packages/flask/app.py", line 1513, in full_dispatch_request
    rv = self.dispatch_request()
  File "/Users/piat/opt/anaconda3/envs/cp1/lib/python3.8/site-packages/flask/app.py", line 1499, in dispatch_request
    return self.ensure_sync(self.view_functions[rule.endpoint])(**req.view_args)
  File "/Users/piat/s5/cp1/New/app/views/main_views.py", line 109, in result
    save_mastery(makedata(user.id, user.mastery)) # Ïú†Ï†Ä Ï±îÌîºÏñ∏ Ï†ïÎ≥¥ mongodbÏ†ÄÏû•
  File "/Users/piat/s5/cp1/New/riot_api/mongodb.py", line 83, in save_mastery
    col.insert_one(data_name)
  File "/Users/piat/opt/anaconda3/envs/cp1/lib/python3.8/site-packages/pymongo/collection.py", line 698, in insert_one
    self._insert(document,
  File "/Users/piat/opt/anaconda3/envs/cp1/lib/python3.8/site-packages/pymongo/collection.py", line 613, in _insert
    return self._insert_one(
  File "/Users/piat/opt/anaconda3/envs/cp1/lib/python3.8/site-packages/pymongo/collection.py", line 602, in _insert_one
    self.__database.client._retryable_write(
  File "/Users/piat/opt/anaconda3/envs/cp1/lib/python3.8/site-packages/pymongo/mongo_client.py", line 1498, in _retryable_write
    return self._retry_with_session(retryable, func, s, None)
  File "/Users/piat/opt/anaconda3/envs/cp1/lib/python3.8/site-packages/pymongo/mongo_client.py", line 1384, in _retry_with_session
    return self._retry_internal(retryable, func, session, bulk)
  File "/Users/piat/opt/anaconda3/envs/cp1/lib/python3.8/site-packages/pymongo/mongo_client.py", line 1416, in _retry_internal
    return func(session, sock_info, retryable)
  File "/Users/piat/opt/anaconda3/envs/cp1/lib/python3.8/site-packages/pymongo/collection.py", line 600, in _insert_command
    _check_write_command_response(result)
  File "/Users/piat/opt/anaconda3/envs/cp1/lib/python3.8/site-packages/pymongo/helpers.py", line 226, in _check_write_command_response
    _raise_last_write_error(write_errors)
  File "/Users/piat/opt/anaconda3/envs/cp1/lib/python3.8/site-packages/pymongo/helpers.py", line 207, in _raise_last_write_error
    raise DuplicateKeyError(error.get("errmsg"), 11000, error)
pymongo.errors.DuplicateKeyError: E11000 duplicate key error collection: loldata.user_mastery index: _id_ dup key: { _id: "XnhdEBDrdxzLMqJVhZBnhh6PI5WHJcbU7JZMncss1JBPiw" }, full error: {'index': 0, 'code': 11000, 'keyPattern': {'_id': 1}, 'keyValue': {'_id': 'XnhdEBDrdxzLMqJVhZBnhh6PI5WHJcbU7JZMncss1JBPiw'}, 'errmsg': 'E11000 duplicate key error collection: loldata.user_mastery index: _id_ dup key: { _id: "XnhdEBDrdxzLMqJVhZBnhh6PI5WHJcbU7JZMncss1JBPiw" }'}
INFO:werkzeug:127.0.0.1 - - [28/Apr/2022 21:20:48] "[35m[1mGET /result?username=Ìï´ÏÉÅÎ≤î HTTP/1.1[0m" 500 -
INFO:werkzeug: * Running on http://127.0.0.1:5000/ (Press CTRL+C to quit)
DEBUG:urllib3.connectionpool:Starting new HTTPS connection (1): kr.api.riotgames.com:443
DEBUG:urllib3.connectionpool:https://kr.api.riotgames.com:443 "GET /lol/summoner/v4/summoners/by-name/%ED%95%AB%EC%83%81%EB%B2%94 HTTP/1.1" 200 None
DEBUG:urllib3.connectionpool:Starting new HTTPS connection (1): kr.api.riotgames.com:443
DEBUG:urllib3.connectionpool:https://kr.api.riotgames.com:443 "GET /lol/summoner/v4/summoners/by-name/%ED%95%AB%EC%83%81%EB%B2%94 HTTP/1.1" 200 None
DEBUG:urllib3.connectionpool:Starting new HTTPS connection (1): kr.api.riotgames.com:443
DEBUG:urllib3.connectionpool:https://kr.api.riotgames.com:443 "GET /lol/champion-mastery/v4/champion-masteries/by-summoner/XnhdEBDrdxzLMqJVhZBnhh6PI5WHJcbU7JZMncss1JBPiw HTTP/1.1" 200 None
DEBUG:urllib3.connectionpool:Starting new HTTPS connection (1): kr.api.riotgames.com:443
DEBUG:urllib3.connectionpool:https://kr.api.riotgames.com:443 "GET /lol/summoner/v4/summoners/by-name/%ED%95%AB%EC%83%81%EB%B2%94 HTTP/1.1" 200 None
DEBUG:urllib3.connectionpool:Starting new HTTPS connection (1): kr.api.riotgames.com:443
DEBUG:urllib3.connectionpool:https://kr.api.riotgames.com:443 "GET /lol/spectator/v4/active-games/by-summoner/XnhdEBDrdxzLMqJVhZBnhh6PI5WHJcbU7JZMncss1JBPiw HTTP/1.1" 503 None
INFO:werkzeug:127.0.0.1 - - [28/Apr/2022 21:22:27] "GET /result?username=Ìï´ÏÉÅÎ≤î HTTP/1.1" 200 -
INFO:werkzeug:127.0.0.1 - - [28/Apr/2022 21:22:27] "[36mGET /static/img/riot.png HTTP/1.1[0m" 304 -
INFO:werkzeug: * Running on http://127.0.0.1:5000/ (Press CTRL+C to quit)
INFO:werkzeug:127.0.0.1 - - [28/Apr/2022 21:25:01] "GET / HTTP/1.1" 200 -
INFO:werkzeug:127.0.0.1 - - [28/Apr/2022 21:25:01] "[36mGET /static/img/riot.png HTTP/1.1[0m" 304 -
DEBUG:urllib3.connectionpool:Starting new HTTPS connection (1): kr.api.riotgames.com:443
DEBUG:urllib3.connectionpool:https://kr.api.riotgames.com:443 "GET /lol/summoner/v4/summoners/by-name/%ED%95%AB%EC%83%81%EB%B2%94 HTTP/1.1" 200 None
DEBUG:urllib3.connectionpool:Starting new HTTPS connection (1): kr.api.riotgames.com:443
DEBUG:urllib3.connectionpool:https://kr.api.riotgames.com:443 "GET /lol/summoner/v4/summoners/by-name/%ED%95%AB%EC%83%81%EB%B2%94 HTTP/1.1" 200 None
DEBUG:urllib3.connectionpool:Starting new HTTPS connection (1): kr.api.riotgames.com:443
DEBUG:urllib3.connectionpool:https://kr.api.riotgames.com:443 "GET /lol/champion-mastery/v4/champion-masteries/by-summoner/XnhdEBDrdxzLMqJVhZBnhh6PI5WHJcbU7JZMncss1JBPiw HTTP/1.1" 200 None
DEBUG:urllib3.connectionpool:Starting new HTTPS connection (1): kr.api.riotgames.com:443
DEBUG:urllib3.connectionpool:https://kr.api.riotgames.com:443 "GET /lol/summoner/v4/summoners/by-name/%ED%95%AB%EC%83%81%EB%B2%94 HTTP/1.1" 200 None
DEBUG:urllib3.connectionpool:Starting new HTTPS connection (1): kr.api.riotgames.com:443
DEBUG:urllib3.connectionpool:https://kr.api.riotgames.com:443 "GET /lol/spectator/v4/active-games/by-summoner/XnhdEBDrdxzLMqJVhZBnhh6PI5WHJcbU7JZMncss1JBPiw HTTP/1.1" 503 None
INFO:werkzeug:127.0.0.1 - - [28/Apr/2022 21:25:12] "GET /result?username=Ìï´ÏÉÅÎ≤î HTTP/1.1" 200 -
INFO:werkzeug:127.0.0.1 - - [28/Apr/2022 21:25:12] "[36mGET /static/img/riot.png HTTP/1.1[0m" 304 -
INFO:werkzeug: * Running on http://127.0.0.1:5000/ (Press CTRL+C to quit)
INFO:werkzeug:127.0.0.1 - - [28/Apr/2022 21:27:07] "GET / HTTP/1.1" 200 -
INFO:werkzeug:127.0.0.1 - - [28/Apr/2022 21:27:08] "[36mGET /static/img/riot.png HTTP/1.1[0m" 304 -
DEBUG:urllib3.connectionpool:Starting new HTTPS connection (1): kr.api.riotgames.com:443
DEBUG:urllib3.connectionpool:https://kr.api.riotgames.com:443 "GET /lol/summoner/v4/summoners/by-name/%ED%95%AB%EC%83%81%EB%B2%94 HTTP/1.1" 200 None
DEBUG:urllib3.connectionpool:Starting new HTTPS connection (1): kr.api.riotgames.com:443
DEBUG:urllib3.connectionpool:https://kr.api.riotgames.com:443 "GET /lol/summoner/v4/summoners/by-name/%ED%95%AB%EC%83%81%EB%B2%94 HTTP/1.1" 200 None
DEBUG:urllib3.connectionpool:Starting new HTTPS connection (1): kr.api.riotgames.com:443
DEBUG:urllib3.connectionpool:https://kr.api.riotgames.com:443 "GET /lol/champion-mastery/v4/champion-masteries/by-summoner/XnhdEBDrdxzLMqJVhZBnhh6PI5WHJcbU7JZMncss1JBPiw HTTP/1.1" 200 None
DEBUG:urllib3.connectionpool:Starting new HTTPS connection (1): kr.api.riotgames.com:443
DEBUG:urllib3.connectionpool:https://kr.api.riotgames.com:443 "GET /lol/summoner/v4/summoners/by-name/%ED%95%AB%EC%83%81%EB%B2%94 HTTP/1.1" 200 None
DEBUG:urllib3.connectionpool:Starting new HTTPS connection (1): kr.api.riotgames.com:443
DEBUG:urllib3.connectionpool:https://kr.api.riotgames.com:443 "GET /lol/spectator/v4/active-games/by-summoner/XnhdEBDrdxzLMqJVhZBnhh6PI5WHJcbU7JZMncss1JBPiw HTTP/1.1" 503 None
INFO:werkzeug:127.0.0.1 - - [28/Apr/2022 21:27:17] "GET /result?username=Ìï´ÏÉÅÎ≤î HTTP/1.1" 200 -
INFO:werkzeug:127.0.0.1 - - [28/Apr/2022 21:27:17] "[36mGET /static/img/riot.png HTTP/1.1[0m" 304 -
INFO:werkzeug: * Running on http://127.0.0.1:5000/ (Press CTRL+C to quit)
INFO:werkzeug:127.0.0.1 - - [28/Apr/2022 21:35:39] "GET / HTTP/1.1" 200 -
INFO:werkzeug:127.0.0.1 - - [28/Apr/2022 21:35:39] "[36mGET /static/img/riot.png HTTP/1.1[0m" 304 -
DEBUG:urllib3.connectionpool:Starting new HTTPS connection (1): kr.api.riotgames.com:443
DEBUG:urllib3.connectionpool:https://kr.api.riotgames.com:443 "GET /lol/summoner/v4/summoners/by-name/%ED%95%AB%EC%83%81%EB%B2%94 HTTP/1.1" 200 None
DEBUG:urllib3.connectionpool:Starting new HTTPS connection (1): kr.api.riotgames.com:443
DEBUG:urllib3.connectionpool:https://kr.api.riotgames.com:443 "GET /lol/summoner/v4/summoners/by-name/%ED%95%AB%EC%83%81%EB%B2%94 HTTP/1.1" 200 None
DEBUG:urllib3.connectionpool:Starting new HTTPS connection (1): kr.api.riotgames.com:443
DEBUG:urllib3.connectionpool:https://kr.api.riotgames.com:443 "GET /lol/champion-mastery/v4/champion-masteries/by-summoner/XnhdEBDrdxzLMqJVhZBnhh6PI5WHJcbU7JZMncss1JBPiw HTTP/1.1" 429 None
ERROR:app:Exception on /result [GET]
Traceback (most recent call last):
  File "/Users/piat/opt/anaconda3/envs/cp1/lib/python3.8/site-packages/flask/app.py", line 2070, in wsgi_app
    response = self.full_dispatch_request()
  File "/Users/piat/opt/anaconda3/envs/cp1/lib/python3.8/site-packages/flask/app.py", line 1515, in full_dispatch_request
    rv = self.handle_user_exception(e)
  File "/Users/piat/opt/anaconda3/envs/cp1/lib/python3.8/site-packages/flask/app.py", line 1513, in full_dispatch_request
    rv = self.dispatch_request()
  File "/Users/piat/opt/anaconda3/envs/cp1/lib/python3.8/site-packages/flask/app.py", line 1499, in dispatch_request
    return self.ensure_sync(self.view_functions[rule.endpoint])(**req.view_args)
  File "/Users/piat/s5/cp1/New/app/views/main_views.py", line 109, in result
    save_mastery(makedata(user.id, user.mastery)) # Ïú†Ï†Ä Ï±îÌîºÏñ∏ Ï†ïÎ≥¥ mongodbÏ†ÄÏû•
  File "/Users/piat/s5/cp1/New/riot_api/mongodb.py", line 66, in makedata
    championId = f"{data[i]['championId']}"
KeyError: 0
INFO:werkzeug:127.0.0.1 - - [28/Apr/2022 21:35:45] "[35m[1mGET /result?username=Ìï´ÏÉÅÎ≤î HTTP/1.1[0m" 500 -
DEBUG:urllib3.connectionpool:Starting new HTTPS connection (1): kr.api.riotgames.com:443
DEBUG:urllib3.connectionpool:https://kr.api.riotgames.com:443 "GET /lol/summoner/v4/summoners/by-name/%ED%95%AB%EC%83%81%EB%B2%94 HTTP/1.1" 200 None
DEBUG:urllib3.connectionpool:Starting new HTTPS connection (1): kr.api.riotgames.com:443
DEBUG:urllib3.connectionpool:https://kr.api.riotgames.com:443 "GET /lol/summoner/v4/summoners/by-name/%ED%95%AB%EC%83%81%EB%B2%94 HTTP/1.1" 200 None
DEBUG:urllib3.connectionpool:Starting new HTTPS connection (1): kr.api.riotgames.com:443
DEBUG:urllib3.connectionpool:https://kr.api.riotgames.com:443 "GET /lol/champion-mastery/v4/champion-masteries/by-summoner/XnhdEBDrdxzLMqJVhZBnhh6PI5WHJcbU7JZMncss1JBPiw HTTP/1.1" 200 None
DEBUG:urllib3.connectionpool:Starting new HTTPS connection (1): kr.api.riotgames.com:443
DEBUG:urllib3.connectionpool:https://kr.api.riotgames.com:443 "GET /lol/summoner/v4/summoners/by-name/%ED%95%AB%EC%83%81%EB%B2%94 HTTP/1.1" 200 None
DEBUG:urllib3.connectionpool:Starting new HTTPS connection (1): kr.api.riotgames.com:443
DEBUG:urllib3.connectionpool:https://kr.api.riotgames.com:443 "GET /lol/spectator/v4/active-games/by-summoner/XnhdEBDrdxzLMqJVhZBnhh6PI5WHJcbU7JZMncss1JBPiw HTTP/1.1" 503 None
INFO:werkzeug:127.0.0.1 - - [28/Apr/2022 21:36:51] "GET /result?username=Ìï´ÏÉÅÎ≤î HTTP/1.1" 200 -
INFO:werkzeug:127.0.0.1 - - [28/Apr/2022 21:36:51] "[36mGET /static/img/riot.png HTTP/1.1[0m" 304 -
INFO:werkzeug: * Running on http://127.0.0.1:5000/ (Press CTRL+C to quit)
DEBUG:urllib3.connectionpool:Starting new HTTPS connection (1): kr.api.riotgames.com:443
DEBUG:urllib3.connectionpool:https://kr.api.riotgames.com:443 "GET /lol/summoner/v4/summoners/by-name/%ED%95%AB%EC%83%81%EB%B2%94 HTTP/1.1" 200 None
DEBUG:urllib3.connectionpool:Starting new HTTPS connection (1): kr.api.riotgames.com:443
DEBUG:urllib3.connectionpool:https://kr.api.riotgames.com:443 "GET /lol/summoner/v4/summoners/by-name/%ED%95%AB%EC%83%81%EB%B2%94 HTTP/1.1" 200 None
DEBUG:urllib3.connectionpool:Starting new HTTPS connection (1): kr.api.riotgames.com:443
DEBUG:urllib3.connectionpool:https://kr.api.riotgames.com:443 "GET /lol/champion-mastery/v4/champion-masteries/by-summoner/XnhdEBDrdxzLMqJVhZBnhh6PI5WHJcbU7JZMncss1JBPiw HTTP/1.1" 200 None
DEBUG:urllib3.connectionpool:Starting new HTTPS connection (1): kr.api.riotgames.com:443
DEBUG:urllib3.connectionpool:https://kr.api.riotgames.com:443 "GET /lol/summoner/v4/summoners/by-name/%ED%95%AB%EC%83%81%EB%B2%94 HTTP/1.1" 200 None
DEBUG:urllib3.connectionpool:Starting new HTTPS connection (1): kr.api.riotgames.com:443
DEBUG:urllib3.connectionpool:https://kr.api.riotgames.com:443 "GET /lol/spectator/v4/active-games/by-summoner/XnhdEBDrdxzLMqJVhZBnhh6PI5WHJcbU7JZMncss1JBPiw HTTP/1.1" 503 None
INFO:werkzeug:127.0.0.1 - - [29/Apr/2022 00:42:02] "GET /result?username=Ìï´ÏÉÅÎ≤î HTTP/1.1" 200 -
INFO:werkzeug:127.0.0.1 - - [29/Apr/2022 00:42:02] "[36mGET /static/img/riot.png HTTP/1.1[0m" 304 -
INFO:werkzeug: * Running on http://127.0.0.1:5000/ (Press CTRL+C to quit)
INFO:werkzeug:127.0.0.1 - - [29/Apr/2022 00:50:05] "GET / HTTP/1.1" 200 -
INFO:werkzeug:127.0.0.1 - - [29/Apr/2022 00:50:05] "[36mGET /static/img/riot.png HTTP/1.1[0m" 304 -
DEBUG:urllib3.connectionpool:Starting new HTTPS connection (1): kr.api.riotgames.com:443
DEBUG:urllib3.connectionpool:https://kr.api.riotgames.com:443 "GET /lol/summoner/v4/summoners/by-name/%ED%95%AB%EC%83%81%EB%B2%94 HTTP/1.1" 200 None
DEBUG:urllib3.connectionpool:Starting new HTTPS connection (1): kr.api.riotgames.com:443
DEBUG:urllib3.connectionpool:https://kr.api.riotgames.com:443 "GET /lol/summoner/v4/summoners/by-name/%ED%95%AB%EC%83%81%EB%B2%94 HTTP/1.1" 200 None
DEBUG:urllib3.connectionpool:Starting new HTTPS connection (1): kr.api.riotgames.com:443
DEBUG:urllib3.connectionpool:https://kr.api.riotgames.com:443 "GET /lol/champion-mastery/v4/champion-masteries/by-summoner/XnhdEBDrdxzLMqJVhZBnhh6PI5WHJcbU7JZMncss1JBPiw HTTP/1.1" 200 None
DEBUG:urllib3.connectionpool:Starting new HTTPS connection (1): kr.api.riotgames.com:443
DEBUG:urllib3.connectionpool:https://kr.api.riotgames.com:443 "GET /lol/summoner/v4/summoners/by-name/%ED%95%AB%EC%83%81%EB%B2%94 HTTP/1.1" 200 None
DEBUG:urllib3.connectionpool:Starting new HTTPS connection (1): kr.api.riotgames.com:443
DEBUG:urllib3.connectionpool:https://kr.api.riotgames.com:443 "GET /lol/spectator/v4/active-games/by-summoner/XnhdEBDrdxzLMqJVhZBnhh6PI5WHJcbU7JZMncss1JBPiw HTTP/1.1" 503 None
INFO:werkzeug:127.0.0.1 - - [29/Apr/2022 00:50:27] "GET /result?username=Ìï´ÏÉÅÎ≤î HTTP/1.1" 200 -
INFO:werkzeug:127.0.0.1 - - [29/Apr/2022 00:50:27] "[36mGET /static/img/riot.png HTTP/1.1[0m" 304 -
INFO:werkzeug:127.0.0.1 - - [29/Apr/2022 00:50:54] "GET / HTTP/1.1" 200 -
INFO:werkzeug:127.0.0.1 - - [29/Apr/2022 00:50:54] "[36mGET /static/img/riot.png HTTP/1.1[0m" 304 -
DEBUG:urllib3.connectionpool:Starting new HTTPS connection (1): kr.api.riotgames.com:443
DEBUG:urllib3.connectionpool:https://kr.api.riotgames.com:443 "GET /lol/summoner/v4/summoners/by-name/%EA%B0%84%EB%8B%A4%EB%9D%BC%EC%BF%A4%EB%8B%A4 HTTP/1.1" 200 None
DEBUG:urllib3.connectionpool:Starting new HTTPS connection (1): kr.api.riotgames.com:443
DEBUG:urllib3.connectionpool:https://kr.api.riotgames.com:443 "GET /lol/summoner/v4/summoners/by-name/%EA%B0%84%EB%8B%A4%EB%9D%BC%EC%BF%A4%EB%8B%A4 HTTP/1.1" 200 None
DEBUG:urllib3.connectionpool:Starting new HTTPS connection (1): kr.api.riotgames.com:443
DEBUG:urllib3.connectionpool:https://kr.api.riotgames.com:443 "GET /lol/champion-mastery/v4/champion-masteries/by-summoner/-ldENra5yKwf37fC7h9Imx58-51kSetWk_E6VgMRSkEpL6Q HTTP/1.1" 200 None
ERROR:app:Exception on /result [GET]
Traceback (most recent call last):
  File "/Users/piat/opt/anaconda3/envs/cp1/lib/python3.8/site-packages/flask/app.py", line 2070, in wsgi_app
    response = self.full_dispatch_request()
  File "/Users/piat/opt/anaconda3/envs/cp1/lib/python3.8/site-packages/flask/app.py", line 1515, in full_dispatch_request
    rv = self.handle_user_exception(e)
  File "/Users/piat/opt/anaconda3/envs/cp1/lib/python3.8/site-packages/flask/app.py", line 1513, in full_dispatch_request
    rv = self.dispatch_request()
  File "/Users/piat/opt/anaconda3/envs/cp1/lib/python3.8/site-packages/flask/app.py", line 1499, in dispatch_request
    return self.ensure_sync(self.view_functions[rule.endpoint])(**req.view_args)
  File "/Users/piat/s5/cp1/New/app/views/main_views.py", line 109, in result
    save_userinfo(user_info_data) # Ïú†Ï†ÄÏ†ïÎ≥¥ mongodbÏ†ÄÏû•
  File "/Users/piat/s5/cp1/New/riot_api/mongodb.py", line 56, in save_userinfo
    if data_name['_id'] in list(col.find_one({'_id':data_name['_id']}).values()):
AttributeError: 'NoneType' object has no attribute 'values'
INFO:werkzeug:127.0.0.1 - - [29/Apr/2022 00:52:58] "[35m[1mGET /result?username=Í∞ÑÎã§ÎùºÏø§Îã§ HTTP/1.1[0m" 500 -
DEBUG:urllib3.connectionpool:Starting new HTTPS connection (1): kr.api.riotgames.com:443
DEBUG:urllib3.connectionpool:https://kr.api.riotgames.com:443 "GET /lol/summoner/v4/summoners/by-name/%EA%B0%84%EB%8B%A4%EB%9D%BC%EC%BF%A4%EB%8B%A4 HTTP/1.1" 200 None
DEBUG:urllib3.connectionpool:Starting new HTTPS connection (1): kr.api.riotgames.com:443
DEBUG:urllib3.connectionpool:https://kr.api.riotgames.com:443 "GET /lol/summoner/v4/summoners/by-name/%EA%B0%84%EB%8B%A4%EB%9D%BC%EC%BF%A4%EB%8B%A4 HTTP/1.1" 200 None
DEBUG:urllib3.connectionpool:Starting new HTTPS connection (1): kr.api.riotgames.com:443
DEBUG:urllib3.connectionpool:https://kr.api.riotgames.com:443 "GET /lol/champion-mastery/v4/champion-masteries/by-summoner/-ldENra5yKwf37fC7h9Imx58-51kSetWk_E6VgMRSkEpL6Q HTTP/1.1" 200 None
ERROR:app:Exception on /result [GET]
Traceback (most recent call last):
  File "/Users/piat/opt/anaconda3/envs/cp1/lib/python3.8/site-packages/flask/app.py", line 2070, in wsgi_app
    response = self.full_dispatch_request()
  File "/Users/piat/opt/anaconda3/envs/cp1/lib/python3.8/site-packages/flask/app.py", line 1515, in full_dispatch_request
    rv = self.handle_user_exception(e)
  File "/Users/piat/opt/anaconda3/envs/cp1/lib/python3.8/site-packages/flask/app.py", line 1513, in full_dispatch_request
    rv = self.dispatch_request()
  File "/Users/piat/opt/anaconda3/envs/cp1/lib/python3.8/site-packages/flask/app.py", line 1499, in dispatch_request
    return self.ensure_sync(self.view_functions[rule.endpoint])(**req.view_args)
  File "/Users/piat/s5/cp1/New/app/views/main_views.py", line 109, in result
    save_userinfo(user_info_data) # Ïú†Ï†ÄÏ†ïÎ≥¥ mongodbÏ†ÄÏû•
  File "/Users/piat/s5/cp1/New/riot_api/mongodb.py", line 56, in save_userinfo
    try:
AttributeError: 'NoneType' object has no attribute 'values'
INFO:werkzeug:127.0.0.1 - - [29/Apr/2022 00:54:32] "[35m[1mGET /result?username=Í∞ÑÎã§ÎùºÏø§Îã§ HTTP/1.1[0m" 500 -
INFO:werkzeug: * Running on http://127.0.0.1:5000/ (Press CTRL+C to quit)
DEBUG:urllib3.connectionpool:Starting new HTTPS connection (1): kr.api.riotgames.com:443
DEBUG:urllib3.connectionpool:https://kr.api.riotgames.com:443 "GET /lol/summoner/v4/summoners/by-name/%EA%B0%84%EB%8B%A4%EB%9D%BC%EC%BF%A4%EB%8B%A4 HTTP/1.1" 200 None
DEBUG:urllib3.connectionpool:Starting new HTTPS connection (1): kr.api.riotgames.com:443
DEBUG:urllib3.connectionpool:https://kr.api.riotgames.com:443 "GET /lol/summoner/v4/summoners/by-name/%EA%B0%84%EB%8B%A4%EB%9D%BC%EC%BF%A4%EB%8B%A4 HTTP/1.1" 200 None
DEBUG:urllib3.connectionpool:Starting new HTTPS connection (1): kr.api.riotgames.com:443
DEBUG:urllib3.connectionpool:https://kr.api.riotgames.com:443 "GET /lol/champion-mastery/v4/champion-masteries/by-summoner/-ldENra5yKwf37fC7h9Imx58-51kSetWk_E6VgMRSkEpL6Q HTTP/1.1" 200 None
ERROR:app:Exception on /result [GET]
Traceback (most recent call last):
  File "/Users/piat/opt/anaconda3/envs/cp1/lib/python3.8/site-packages/flask/app.py", line 2070, in wsgi_app
    response = self.full_dispatch_request()
  File "/Users/piat/opt/anaconda3/envs/cp1/lib/python3.8/site-packages/flask/app.py", line 1515, in full_dispatch_request
    rv = self.handle_user_exception(e)
  File "/Users/piat/opt/anaconda3/envs/cp1/lib/python3.8/site-packages/flask/app.py", line 1513, in full_dispatch_request
    rv = self.dispatch_request()
  File "/Users/piat/opt/anaconda3/envs/cp1/lib/python3.8/site-packages/flask/app.py", line 1499, in dispatch_request
    return self.ensure_sync(self.view_functions[rule.endpoint])(**req.view_args)
  File "/Users/piat/s5/cp1/New/app/views/main_views.py", line 110, in result
    save_mastery(makedata(user.id, user.mastery)) # Ïú†Ï†Ä Ï±îÌîºÏñ∏ Ï†ïÎ≥¥ mongodbÏ†ÄÏû•
  File "/Users/piat/s5/cp1/New/riot_api/mongodb.py", line 86, in save_mastery
    if data_name['_id'] in list(col.find_one({'_id':data_name['_id']}).values()):
AttributeError: 'NoneType' object has no attribute 'values'
INFO:werkzeug:127.0.0.1 - - [29/Apr/2022 00:55:03] "[35m[1mGET /result?username=Í∞ÑÎã§ÎùºÏø§Îã§ HTTP/1.1[0m" 500 -
INFO:werkzeug: * Running on http://127.0.0.1:5000/ (Press CTRL+C to quit)
INFO:werkzeug: * Running on http://127.0.0.1:5000/ (Press CTRL+C to quit)
INFO:werkzeug: * Running on http://127.0.0.1:5000/ (Press CTRL+C to quit)
INFO:werkzeug: * Running on http://127.0.0.1:5000/ (Press CTRL+C to quit)
INFO:werkzeug:127.0.0.1 - - [29/Apr/2022 00:58:15] "GET / HTTP/1.1" 200 -
INFO:werkzeug:127.0.0.1 - - [29/Apr/2022 00:58:15] "[36mGET /static/img/riot.png HTTP/1.1[0m" 304 -
DEBUG:urllib3.connectionpool:Starting new HTTPS connection (1): kr.api.riotgames.com:443
DEBUG:urllib3.connectionpool:https://kr.api.riotgames.com:443 "GET /lol/summoner/v4/summoners/by-name/%EC%96%91%EC%9E%AC%EC%8B%9C%EB%AF%BC%EC%9D%98%EC%88%B2 HTTP/1.1" 200 None
DEBUG:urllib3.connectionpool:Starting new HTTPS connection (1): kr.api.riotgames.com:443
DEBUG:urllib3.connectionpool:https://kr.api.riotgames.com:443 "GET /lol/summoner/v4/summoners/by-name/%EC%96%91%EC%9E%AC%EC%8B%9C%EB%AF%BC%EC%9D%98%EC%88%B2 HTTP/1.1" 200 None
DEBUG:urllib3.connectionpool:Starting new HTTPS connection (1): kr.api.riotgames.com:443
DEBUG:urllib3.connectionpool:https://kr.api.riotgames.com:443 "GET /lol/champion-mastery/v4/champion-masteries/by-summoner/R-7E5Fei-MyIc6PtPVX5kSV3Irc_WJQkU6PTVnKHP52X8wo HTTP/1.1" 200 None
DEBUG:urllib3.connectionpool:Starting new HTTPS connection (1): kr.api.riotgames.com:443
DEBUG:urllib3.connectionpool:https://kr.api.riotgames.com:443 "GET /lol/summoner/v4/summoners/by-name/%EC%96%91%EC%9E%AC%EC%8B%9C%EB%AF%BC%EC%9D%98%EC%88%B2 HTTP/1.1" 200 None
DEBUG:urllib3.connectionpool:Starting new HTTPS connection (1): kr.api.riotgames.com:443
DEBUG:urllib3.connectionpool:https://kr.api.riotgames.com:443 "GET /lol/spectator/v4/active-games/by-summoner/R-7E5Fei-MyIc6PtPVX5kSV3Irc_WJQkU6PTVnKHP52X8wo HTTP/1.1" 503 None
INFO:werkzeug:127.0.0.1 - - [29/Apr/2022 00:58:31] "GET /result?username=ÏñëÏû¨ÏãúÎØºÏùòÏà≤ HTTP/1.1" 200 -
INFO:werkzeug:127.0.0.1 - - [29/Apr/2022 00:58:31] "[36mGET /static/img/riot.png HTTP/1.1[0m" 304 -
INFO:werkzeug: * Running on http://127.0.0.1:5000/ (Press CTRL+C to quit)
INFO:werkzeug:127.0.0.1 - - [29/Apr/2022 01:35:26] "GET / HTTP/1.1" 200 -
INFO:werkzeug:127.0.0.1 - - [29/Apr/2022 01:35:26] "[36mGET /static/img/riot.png HTTP/1.1[0m" 304 -
DEBUG:urllib3.connectionpool:Starting new HTTPS connection (1): kr.api.riotgames.com:443
DEBUG:urllib3.connectionpool:https://kr.api.riotgames.com:443 "GET /lol/summoner/v4/summoners/by-name/%EC%9A%B0%EC%99%81%EA%B5%B3 HTTP/1.1" 200 None
DEBUG:urllib3.connectionpool:Starting new HTTPS connection (1): kr.api.riotgames.com:443
DEBUG:urllib3.connectionpool:https://kr.api.riotgames.com:443 "GET /lol/summoner/v4/summoners/by-name/%EC%9A%B0%EC%99%81%EA%B5%B3 HTTP/1.1" 200 None
DEBUG:urllib3.connectionpool:Starting new HTTPS connection (1): kr.api.riotgames.com:443
DEBUG:urllib3.connectionpool:https://kr.api.riotgames.com:443 "GET /lol/champion-mastery/v4/champion-masteries/by-summoner/w0BYZapuvW-irQrwCB7DWxxf6NeysD-5be3OC6Y0SqGA7ZU HTTP/1.1" 200 None
DEBUG:urllib3.connectionpool:Starting new HTTPS connection (1): kr.api.riotgames.com:443
DEBUG:urllib3.connectionpool:https://kr.api.riotgames.com:443 "GET /lol/summoner/v4/summoners/by-name/%EC%9A%B0%EC%99%81%EA%B5%B3 HTTP/1.1" 200 None
DEBUG:urllib3.connectionpool:Starting new HTTPS connection (1): kr.api.riotgames.com:443
DEBUG:urllib3.connectionpool:https://kr.api.riotgames.com:443 "GET /lol/spectator/v4/active-games/by-summoner/w0BYZapuvW-irQrwCB7DWxxf6NeysD-5be3OC6Y0SqGA7ZU HTTP/1.1" 503 None
INFO:werkzeug:127.0.0.1 - - [29/Apr/2022 01:35:35] "GET /result?username=Ïö∞ÏôÅÍµ≥ HTTP/1.1" 200 -
INFO:werkzeug:127.0.0.1 - - [29/Apr/2022 01:35:35] "[36mGET /static/img/riot.png HTTP/1.1[0m" 304 -
INFO:werkzeug:127.0.0.1 - - [29/Apr/2022 01:35:43] "GET / HTTP/1.1" 200 -
INFO:werkzeug:127.0.0.1 - - [29/Apr/2022 01:35:43] "[36mGET /static/img/riot.png HTTP/1.1[0m" 304 -
[2022-04-29 01:46:58,847] INFO in _internal:  * Running on http://127.0.0.1:5000/ (Press CTRL+C to quit)
[2022-04-29 01:47:05,138] INFO in _internal: 127.0.0.1 - - [29/Apr/2022 01:47:05] "GET / HTTP/1.1" 200 -
[2022-04-29 01:47:05,157] INFO in _internal: 127.0.0.1 - - [29/Apr/2022 01:47:05] "[36mGET /static/img/riot.png HTTP/1.1[0m" 304 -
[2022-04-29 01:47:23,892] INFO in _internal: 127.0.0.1 - - [29/Apr/2022 01:47:23] "GET /result?username=Ìï´ÏÉÅÎ≤î HTTP/1.1" 200 -
[2022-04-29 01:47:23,913] INFO in _internal: 127.0.0.1 - - [29/Apr/2022 01:47:23] "[36mGET /static/img/riot.png HTTP/1.1[0m" 304 -
[2022-04-29 01:51:52,596] INFO in _internal:  * Running on http://127.0.0.1:5000/ (Press CTRL+C to quit)
[2022-04-29 01:58:41,295] INFO in _internal:  * Running on http://127.0.0.1:5000/ (Press CTRL+C to quit)
[2022-04-29 01:58:45,967] ERROR in app: Exception on / [GET]
Traceback (most recent call last):
  File "/Users/piat/opt/anaconda3/envs/cp1/lib/python3.8/site-packages/flask/app.py", line 2070, in wsgi_app
    response = self.full_dispatch_request()
  File "/Users/piat/opt/anaconda3/envs/cp1/lib/python3.8/site-packages/flask/app.py", line 1515, in full_dispatch_request
    rv = self.handle_user_exception(e)
  File "/Users/piat/opt/anaconda3/envs/cp1/lib/python3.8/site-packages/flask/app.py", line 1513, in full_dispatch_request
    rv = self.dispatch_request()
  File "/Users/piat/opt/anaconda3/envs/cp1/lib/python3.8/site-packages/flask/app.py", line 1499, in dispatch_request
    return self.ensure_sync(self.view_functions[rule.endpoint])(**req.view_args)
  File "/Users/piat/s5/cp1/New/app/views/main_views.py", line 11, in index
    app.logger.info("INFO Î†àÎ≤®Î°ú Ï∂úÎ†•")
NameError: name 'app' is not defined
[2022-04-29 01:58:45,971] INFO in _internal: 127.0.0.1 - - [29/Apr/2022 01:58:45] "[35m[1mGET / HTTP/1.1[0m" 500 -
[2022-04-29 01:59:16,532] INFO in _internal:  * Running on http://127.0.0.1:5000/ (Press CTRL+C to quit)
[2022-04-29 01:59:19,227] ERROR in app: Exception on / [GET]
Traceback (most recent call last):
  File "/Users/piat/opt/anaconda3/envs/cp1/lib/python3.8/site-packages/flask/app.py", line 2070, in wsgi_app
    response = self.full_dispatch_request()
  File "/Users/piat/opt/anaconda3/envs/cp1/lib/python3.8/site-packages/flask/app.py", line 1515, in full_dispatch_request
    rv = self.handle_user_exception(e)
  File "/Users/piat/opt/anaconda3/envs/cp1/lib/python3.8/site-packages/flask/app.py", line 1513, in full_dispatch_request
    rv = self.dispatch_request()
  File "/Users/piat/opt/anaconda3/envs/cp1/lib/python3.8/site-packages/flask/app.py", line 1499, in dispatch_request
    return self.ensure_sync(self.view_functions[rule.endpoint])(**req.view_args)
  File "/Users/piat/s5/cp1/New/app/views/main_views.py", line 11, in index
    bp.logger.info("INFO Î†àÎ≤®Î°ú Ï∂úÎ†•")
AttributeError: 'Blueprint' object has no attribute 'logger'
[2022-04-29 01:59:19,232] INFO in _internal: 127.0.0.1 - - [29/Apr/2022 01:59:19] "[35m[1mGET / HTTP/1.1[0m" 500 -
[2022-04-29 02:12:48,260] INFO in _internal:  * Running on http://127.0.0.1:5000/ (Press CTRL+C to quit)
[2022-04-29 02:13:05,484] INFO in _internal: 127.0.0.1 - - [29/Apr/2022 02:13:05] "[35m[1mGET / HTTP/1.1[0m" 500 -
[2022-04-29 02:13:08,664] INFO in _internal: 127.0.0.1 - - [29/Apr/2022 02:13:08] "[35m[1mGET / HTTP/1.1[0m" 500 -
[2022-04-29 02:13:28,261] INFO in _internal: 127.0.0.1 - - [29/Apr/2022 02:13:28] "[35m[1mGET / HTTP/1.1[0m" 500 -
[2022-04-29 02:13:32,681] INFO in _internal: 127.0.0.1 - - [29/Apr/2022 02:13:32] "[35m[1mGET / HTTP/1.1[0m" 500 -
[2022-04-29 02:14:27,052] INFO in _internal:  * Running on http://127.0.0.1:5000/ (Press CTRL+C to quit)
[2022-04-29 02:14:30,199] INFO in _internal: 127.0.0.1 - - [29/Apr/2022 02:14:30] "[35m[1mGET / HTTP/1.1[0m" 500 -
[2022-04-29 02:14:31,366] INFO in _internal: 127.0.0.1 - - [29/Apr/2022 02:14:31] "[35m[1mGET / HTTP/1.1[0m" 500 -
[2022-04-29 02:15:19,033] INFO in _internal:  * Running on http://127.0.0.1:5000/ (Press CTRL+C to quit)
[2022-04-29 02:15:21,910] INFO in _internal: 127.0.0.1 - - [29/Apr/2022 02:15:21] "[35m[1mGET / HTTP/1.1[0m" 500 -
INFO:werkzeug: * Running on http://127.0.0.1:5000/ (Press CTRL+C to quit)
ERROR:app:Exception on / [GET]
Traceback (most recent call last):
  File "/Users/piat/opt/anaconda3/envs/cp1/lib/python3.8/site-packages/flask/app.py", line 2070, in wsgi_app
    response = self.full_dispatch_request()
  File "/Users/piat/opt/anaconda3/envs/cp1/lib/python3.8/site-packages/flask/app.py", line 1515, in full_dispatch_request
    rv = self.handle_user_exception(e)
  File "/Users/piat/opt/anaconda3/envs/cp1/lib/python3.8/site-packages/flask/app.py", line 1513, in full_dispatch_request
    rv = self.dispatch_request()
  File "/Users/piat/opt/anaconda3/envs/cp1/lib/python3.8/site-packages/flask/app.py", line 1499, in dispatch_request
    return self.ensure_sync(self.view_functions[rule.endpoint])(**req.view_args)
  File "/Users/piat/s5/cp1/New/app/views/main_views.py", line 11, in index
    with app.app_context():
NameError: name 'app' is not defined
INFO:werkzeug:127.0.0.1 - - [29/Apr/2022 02:16:05] "[35m[1mGET / HTTP/1.1[0m" 500 -
ERROR:app:Exception on / [GET]
Traceback (most recent call last):
  File "/Users/piat/opt/anaconda3/envs/cp1/lib/python3.8/site-packages/flask/app.py", line 2070, in wsgi_app
    response = self.full_dispatch_request()
  File "/Users/piat/opt/anaconda3/envs/cp1/lib/python3.8/site-packages/flask/app.py", line 1515, in full_dispatch_request
    rv = self.handle_user_exception(e)
  File "/Users/piat/opt/anaconda3/envs/cp1/lib/python3.8/site-packages/flask/app.py", line 1513, in full_dispatch_request
    rv = self.dispatch_request()
  File "/Users/piat/opt/anaconda3/envs/cp1/lib/python3.8/site-packages/flask/app.py", line 1499, in dispatch_request
    return self.ensure_sync(self.view_functions[rule.endpoint])(**req.view_args)
  File "/Users/piat/s5/cp1/New/app/views/main_views.py", line 11, in index
    with app.app_context():
NameError: name 'app' is not defined
INFO:werkzeug:127.0.0.1 - - [29/Apr/2022 02:16:06] "[35m[1mGET / HTTP/1.1[0m" 500 -
ERROR:app:Exception on / [GET]
Traceback (most recent call last):
  File "/Users/piat/opt/anaconda3/envs/cp1/lib/python3.8/site-packages/flask/app.py", line 2070, in wsgi_app
    response = self.full_dispatch_request()
  File "/Users/piat/opt/anaconda3/envs/cp1/lib/python3.8/site-packages/flask/app.py", line 1515, in full_dispatch_request
    rv = self.handle_user_exception(e)
  File "/Users/piat/opt/anaconda3/envs/cp1/lib/python3.8/site-packages/flask/app.py", line 1513, in full_dispatch_request
    rv = self.dispatch_request()
  File "/Users/piat/opt/anaconda3/envs/cp1/lib/python3.8/site-packages/flask/app.py", line 1499, in dispatch_request
    return self.ensure_sync(self.view_functions[rule.endpoint])(**req.view_args)
  File "/Users/piat/s5/cp1/New/app/views/main_views.py", line 11, in index
    with app.app_context():
NameError: name 'app' is not defined
INFO:werkzeug:127.0.0.1 - - [29/Apr/2022 02:16:08] "[35m[1mGET / HTTP/1.1[0m" 500 -
ERROR:app:Exception on / [GET]
Traceback (most recent call last):
  File "/Users/piat/opt/anaconda3/envs/cp1/lib/python3.8/site-packages/flask/app.py", line 2070, in wsgi_app
    response = self.full_dispatch_request()
  File "/Users/piat/opt/anaconda3/envs/cp1/lib/python3.8/site-packages/flask/app.py", line 1515, in full_dispatch_request
    rv = self.handle_user_exception(e)
  File "/Users/piat/opt/anaconda3/envs/cp1/lib/python3.8/site-packages/flask/app.py", line 1513, in full_dispatch_request
    rv = self.dispatch_request()
  File "/Users/piat/opt/anaconda3/envs/cp1/lib/python3.8/site-packages/flask/app.py", line 1499, in dispatch_request
    return self.ensure_sync(self.view_functions[rule.endpoint])(**req.view_args)
  File "/Users/piat/s5/cp1/New/app/views/main_views.py", line 11, in index
    #with app.app_context():
NameError: name 'app' is not defined
INFO:werkzeug:127.0.0.1 - - [29/Apr/2022 02:16:47] "[35m[1mGET / HTTP/1.1[0m" 500 -
INFO:werkzeug: * Running on http://127.0.0.1:5000/ (Press CTRL+C to quit)
INFO:werkzeug:127.0.0.1 - - [29/Apr/2022 02:16:52] "GET / HTTP/1.1" 200 -
INFO:werkzeug:127.0.0.1 - - [29/Apr/2022 02:16:52] "[36mGET /static/img/riot.png HTTP/1.1[0m" 304 -
[2022-04-29 02:17:12,218] INFO in _internal:  * Running on http://127.0.0.1:5000/ (Press CTRL+C to quit)
[2022-04-29 02:17:15,330] INFO in _internal: 127.0.0.1 - - [29/Apr/2022 02:17:15] "GET / HTTP/1.1" 200 -
[2022-04-29 02:17:15,348] INFO in _internal: 127.0.0.1 - - [29/Apr/2022 02:17:15] "[36mGET /static/img/riot.png HTTP/1.1[0m" 304 -
[2022-04-29 02:17:34,935] INFO in _internal:  * Running on http://127.0.0.1:5000/ (Press CTRL+C to quit)
[2022-04-29 02:17:36,865] INFO in _internal: 127.0.0.1 - - [29/Apr/2022 02:17:36] "GET / HTTP/1.1" 200 -
[2022-04-29 02:17:36,877] INFO in _internal: 127.0.0.1 - - [29/Apr/2022 02:17:36] "[36mGET /static/img/riot.png HTTP/1.1[0m" 304 -
[2022-04-29 02:17:39,477] DEBUG in connectionpool: Starting new HTTPS connection (1): kr.api.riotgames.com:443
[2022-04-29 02:17:39,749] DEBUG in connectionpool: https://kr.api.riotgames.com:443 "GET /lol/summoner/v4/summoners/by-name/%ED%95%AB%EC%83%81%EB%B2%94 HTTP/1.1" 200 None
[2022-04-29 02:17:39,755] DEBUG in connectionpool: Starting new HTTPS connection (1): kr.api.riotgames.com:443
[2022-04-29 02:17:40,014] DEBUG in connectionpool: https://kr.api.riotgames.com:443 "GET /lol/summoner/v4/summoners/by-name/%ED%95%AB%EC%83%81%EB%B2%94 HTTP/1.1" 200 None
[2022-04-29 02:17:40,017] DEBUG in connectionpool: Starting new HTTPS connection (1): kr.api.riotgames.com:443
[2022-04-29 02:17:40,280] DEBUG in connectionpool: https://kr.api.riotgames.com:443 "GET /lol/champion-mastery/v4/champion-masteries/by-summoner/XnhdEBDrdxzLMqJVhZBnhh6PI5WHJcbU7JZMncss1JBPiw HTTP/1.1" 200 None
[2022-04-29 02:17:40,949] DEBUG in connectionpool: Starting new HTTPS connection (1): kr.api.riotgames.com:443
[2022-04-29 02:17:41,202] DEBUG in connectionpool: https://kr.api.riotgames.com:443 "GET /lol/summoner/v4/summoners/by-name/%ED%95%AB%EC%83%81%EB%B2%94 HTTP/1.1" 200 None
[2022-04-29 02:17:41,204] DEBUG in connectionpool: Starting new HTTPS connection (1): kr.api.riotgames.com:443
[2022-04-29 02:17:44,554] DEBUG in connectionpool: https://kr.api.riotgames.com:443 "GET /lol/spectator/v4/active-games/by-summoner/XnhdEBDrdxzLMqJVhZBnhh6PI5WHJcbU7JZMncss1JBPiw HTTP/1.1" 503 None
[2022-04-29 02:17:44,908] INFO in _internal: 127.0.0.1 - - [29/Apr/2022 02:17:44] "GET /result?username=Ìï´ÏÉÅÎ≤î HTTP/1.1" 200 -
[2022-04-29 02:17:44,928] INFO in _internal: 127.0.0.1 - - [29/Apr/2022 02:17:44] "[36mGET /static/img/riot.png HTTP/1.1[0m" 304 -
[2022-04-29 02:18:36,190] INFO in _internal:  * Running on http://127.0.0.1:5000/ (Press CTRL+C to quit)
[2022-04-29 02:18:40,997] INFO in _internal: 127.0.0.1 - - [29/Apr/2022 02:18:40] "GET / HTTP/1.1" 200 -
[2022-04-29 02:18:41,005] INFO in _internal: 127.0.0.1 - - [29/Apr/2022 02:18:41] "[36mGET /static/img/riot.png HTTP/1.1[0m" 304 -
[2022-04-29 02:19:09,772] INFO in __init__: INFO Î†àÎ≤®Î°ú Ï∂úÎ†•
[2022-04-29 02:19:09,850] INFO in _internal:  * Running on http://127.0.0.1:5000/ (Press CTRL+C to quit)
[2022-04-29 02:19:11,647] INFO in _internal: 127.0.0.1 - - [29/Apr/2022 02:19:11] "GET / HTTP/1.1" 200 -
[2022-04-29 02:19:11,657] INFO in _internal: 127.0.0.1 - - [29/Apr/2022 02:19:11] "[36mGET /static/img/riot.png HTTP/1.1[0m" 304 -
[2022-04-29 02:20:12,110] INFO in __init__: INFO Î†àÎ≤®Î°ú Ï∂úÎ†•
[2022-04-29 02:20:12,188] INFO in _internal:  * Running on http://127.0.0.1:5000/ (Press CTRL+C to quit)
[2022-04-29 02:20:14,394] ERROR in app: Exception on / [GET]
Traceback (most recent call last):
  File "/Users/piat/opt/anaconda3/envs/cp1/lib/python3.8/site-packages/flask/app.py", line 2070, in wsgi_app
    response = self.full_dispatch_request()
  File "/Users/piat/opt/anaconda3/envs/cp1/lib/python3.8/site-packages/flask/app.py", line 1515, in full_dispatch_request
    rv = self.handle_user_exception(e)
  File "/Users/piat/opt/anaconda3/envs/cp1/lib/python3.8/site-packages/flask/app.py", line 1513, in full_dispatch_request
    rv = self.dispatch_request()
  File "/Users/piat/opt/anaconda3/envs/cp1/lib/python3.8/site-packages/flask/app.py", line 1499, in dispatch_request
    return self.ensure_sync(self.view_functions[rule.endpoint])(**req.view_args)
  File "/Users/piat/s5/cp1/New/app/views/main_views.py", line 11, in index
    with app.app_context():
NameError: name 'app' is not defined
[2022-04-29 02:20:14,396] INFO in _internal: 127.0.0.1 - - [29/Apr/2022 02:20:14] "[35m[1mGET / HTTP/1.1[0m" 500 -
[2022-04-29 02:20:30,586] INFO in __init__: INFO Î†àÎ≤®Î°ú Ï∂úÎ†•
[2022-04-29 02:20:30,646] INFO in _internal:  * Running on http://127.0.0.1:5000/ (Press CTRL+C to quit)
[2022-04-29 02:20:32,493] ERROR in app: Exception on / [GET]
Traceback (most recent call last):
  File "/Users/piat/opt/anaconda3/envs/cp1/lib/python3.8/site-packages/flask/app.py", line 2070, in wsgi_app
    response = self.full_dispatch_request()
  File "/Users/piat/opt/anaconda3/envs/cp1/lib/python3.8/site-packages/flask/app.py", line 1515, in full_dispatch_request
    rv = self.handle_user_exception(e)
  File "/Users/piat/opt/anaconda3/envs/cp1/lib/python3.8/site-packages/flask/app.py", line 1513, in full_dispatch_request
    rv = self.dispatch_request()
  File "/Users/piat/opt/anaconda3/envs/cp1/lib/python3.8/site-packages/flask/app.py", line 1499, in dispatch_request
    return self.ensure_sync(self.view_functions[rule.endpoint])(**req.view_args)
  File "/Users/piat/s5/cp1/New/app/views/main_views.py", line 11, in index
    with bp.app_context():
AttributeError: 'Blueprint' object has no attribute 'app_context'
[2022-04-29 02:20:32,495] INFO in _internal: 127.0.0.1 - - [29/Apr/2022 02:20:32] "[35m[1mGET / HTTP/1.1[0m" 500 -
[2022-04-29 02:20:33,180] ERROR in app: Exception on / [GET]
Traceback (most recent call last):
  File "/Users/piat/opt/anaconda3/envs/cp1/lib/python3.8/site-packages/flask/app.py", line 2070, in wsgi_app
    response = self.full_dispatch_request()
  File "/Users/piat/opt/anaconda3/envs/cp1/lib/python3.8/site-packages/flask/app.py", line 1515, in full_dispatch_request
    rv = self.handle_user_exception(e)
  File "/Users/piat/opt/anaconda3/envs/cp1/lib/python3.8/site-packages/flask/app.py", line 1513, in full_dispatch_request
    rv = self.dispatch_request()
  File "/Users/piat/opt/anaconda3/envs/cp1/lib/python3.8/site-packages/flask/app.py", line 1499, in dispatch_request
    return self.ensure_sync(self.view_functions[rule.endpoint])(**req.view_args)
  File "/Users/piat/s5/cp1/New/app/views/main_views.py", line 11, in index
    with bp.app_context():
AttributeError: 'Blueprint' object has no attribute 'app_context'
[2022-04-29 02:20:33,181] INFO in _internal: 127.0.0.1 - - [29/Apr/2022 02:20:33] "[35m[1mGET / HTTP/1.1[0m" 500 -
[2022-04-29 02:20:58,668] INFO in __init__: INFO Î†àÎ≤®Î°ú Ï∂úÎ†•
[2022-04-29 02:20:58,750] INFO in _internal:  * Running on http://127.0.0.1:5000/ (Press CTRL+C to quit)
[2022-04-29 02:21:02,243] INFO in main_views: INFO Î†àÎ≤®Î°ú Ï∂úÎ†•
[2022-04-29 02:21:02,247] INFO in _internal: 127.0.0.1 - - [29/Apr/2022 02:21:02] "GET / HTTP/1.1" 200 -
[2022-04-29 02:21:02,258] INFO in _internal: 127.0.0.1 - - [29/Apr/2022 02:21:02] "[36mGET /static/img/riot.png HTTP/1.1[0m" 304 -
[2022-04-29 02:21:06,342] DEBUG in connectionpool: Starting new HTTPS connection (1): kr.api.riotgames.com:443
[2022-04-29 02:21:06,635] DEBUG in connectionpool: https://kr.api.riotgames.com:443 "GET /lol/summoner/v4/summoners/by-name/%ED%95%AB%EC%83%81%EB%B2%94 HTTP/1.1" 200 None
[2022-04-29 02:21:06,643] DEBUG in connectionpool: Starting new HTTPS connection (1): kr.api.riotgames.com:443
[2022-04-29 02:21:06,922] DEBUG in connectionpool: https://kr.api.riotgames.com:443 "GET /lol/summoner/v4/summoners/by-name/%ED%95%AB%EC%83%81%EB%B2%94 HTTP/1.1" 200 None
[2022-04-29 02:21:06,937] DEBUG in connectionpool: Starting new HTTPS connection (1): kr.api.riotgames.com:443
[2022-04-29 02:21:07,248] DEBUG in connectionpool: https://kr.api.riotgames.com:443 "GET /lol/champion-mastery/v4/champion-masteries/by-summoner/XnhdEBDrdxzLMqJVhZBnhh6PI5WHJcbU7JZMncss1JBPiw HTTP/1.1" 200 None
[2022-04-29 02:21:08,059] DEBUG in connectionpool: Starting new HTTPS connection (1): kr.api.riotgames.com:443
[2022-04-29 02:21:08,339] DEBUG in connectionpool: https://kr.api.riotgames.com:443 "GET /lol/summoner/v4/summoners/by-name/%ED%95%AB%EC%83%81%EB%B2%94 HTTP/1.1" 200 None
[2022-04-29 02:21:08,343] DEBUG in connectionpool: Starting new HTTPS connection (1): kr.api.riotgames.com:443
[2022-04-29 02:21:11,713] DEBUG in connectionpool: https://kr.api.riotgames.com:443 "GET /lol/spectator/v4/active-games/by-summoner/XnhdEBDrdxzLMqJVhZBnhh6PI5WHJcbU7JZMncss1JBPiw HTTP/1.1" 503 None
[2022-04-29 02:21:12,073] INFO in _internal: 127.0.0.1 - - [29/Apr/2022 02:21:12] "GET /result?username=Ìï´ÏÉÅÎ≤î HTTP/1.1" 200 -
[2022-04-29 02:21:12,096] INFO in _internal: 127.0.0.1 - - [29/Apr/2022 02:21:12] "[36mGET /static/img/riot.png HTTP/1.1[0m" 304 -
[2022-04-29 02:21:34,304] INFO in _internal:  * Running on http://127.0.0.1:5000/ (Press CTRL+C to quit)
[2022-04-29 02:21:41,116] INFO in main_views: INFO Î†àÎ≤®Î°ú Ï∂úÎ†•
[2022-04-29 02:21:41,127] INFO in _internal: 127.0.0.1 - - [29/Apr/2022 02:21:41] "GET / HTTP/1.1" 200 -
[2022-04-29 02:21:41,141] INFO in _internal: 127.0.0.1 - - [29/Apr/2022 02:21:41] "[36mGET /static/img/riot.png HTTP/1.1[0m" 304 -
[2022-04-29 02:23:28,228] INFO in _internal:  * Running on http://127.0.0.1:5000/ (Press CTRL+C to quit)
[2022-04-29 02:23:32,867] INFO in main_views: INFO Î†àÎ≤®Î°ú Ï∂úÎ†•
[2022-04-29 02:23:32,879] INFO in _internal: 127.0.0.1 - - [29/Apr/2022 02:23:32] "GET / HTTP/1.1" 200 -
[2022-04-29 02:23:32,909] INFO in _internal: 127.0.0.1 - - [29/Apr/2022 02:23:32] "[36mGET /static/img/riot.png HTTP/1.1[0m" 304 -
[2022-04-29 02:23:44,022] INFO in _internal:  * Running on http://127.0.0.1:5000/ (Press CTRL+C to quit)
[2022-04-29 02:23:49,481] INFO in _internal:  * Running on http://127.0.0.1:5000/ (Press CTRL+C to quit)
[2022-04-29 02:24:01,094] INFO in main_views: INFO Î†àÎ≤®Î°ú Ï∂úÎ†•
[2022-04-29 02:24:01,098] INFO in _internal: 127.0.0.1 - - [29/Apr/2022 02:24:01] "GET / HTTP/1.1" 200 -
[2022-04-29 02:24:01,108] INFO in _internal: 127.0.0.1 - - [29/Apr/2022 02:24:01] "[36mGET /static/img/riot.png HTTP/1.1[0m" 304 -
[2022-04-29 02:24:01,647] INFO in main_views: INFO Î†àÎ≤®Î°ú Ï∂úÎ†•
[2022-04-29 02:24:01,648] INFO in _internal: 127.0.0.1 - - [29/Apr/2022 02:24:01] "GET / HTTP/1.1" 200 -
[2022-04-29 02:24:01,655] INFO in _internal: 127.0.0.1 - - [29/Apr/2022 02:24:01] "[36mGET /static/img/riot.png HTTP/1.1[0m" 304 -
[2022-04-29 02:24:04,273] DEBUG in connectionpool: Starting new HTTPS connection (1): kr.api.riotgames.com:443
[2022-04-29 02:24:04,566] DEBUG in connectionpool: https://kr.api.riotgames.com:443 "GET /lol/summoner/v4/summoners/by-name/%ED%95%AB%EC%83%81%EB%B2%94 HTTP/1.1" 200 None
[2022-04-29 02:24:04,576] DEBUG in connectionpool: Starting new HTTPS connection (1): kr.api.riotgames.com:443
[2022-04-29 02:24:04,861] DEBUG in connectionpool: https://kr.api.riotgames.com:443 "GET /lol/summoner/v4/summoners/by-name/%ED%95%AB%EC%83%81%EB%B2%94 HTTP/1.1" 200 None
[2022-04-29 02:24:04,878] DEBUG in connectionpool: Starting new HTTPS connection (1): kr.api.riotgames.com:443
[2022-04-29 02:24:05,217] DEBUG in connectionpool: https://kr.api.riotgames.com:443 "GET /lol/champion-mastery/v4/champion-masteries/by-summoner/XnhdEBDrdxzLMqJVhZBnhh6PI5WHJcbU7JZMncss1JBPiw HTTP/1.1" 200 None
[2022-04-29 02:24:06,040] DEBUG in connectionpool: Starting new HTTPS connection (1): kr.api.riotgames.com:443
[2022-04-29 02:24:06,317] DEBUG in connectionpool: https://kr.api.riotgames.com:443 "GET /lol/summoner/v4/summoners/by-name/%ED%95%AB%EC%83%81%EB%B2%94 HTTP/1.1" 200 None
[2022-04-29 02:24:06,332] DEBUG in connectionpool: Starting new HTTPS connection (1): kr.api.riotgames.com:443
[2022-04-29 02:24:09,788] DEBUG in connectionpool: https://kr.api.riotgames.com:443 "GET /lol/spectator/v4/active-games/by-summoner/XnhdEBDrdxzLMqJVhZBnhh6PI5WHJcbU7JZMncss1JBPiw HTTP/1.1" 503 None
[2022-04-29 02:24:10,141] INFO in _internal: 127.0.0.1 - - [29/Apr/2022 02:24:10] "GET /result?username=Ìï´ÏÉÅÎ≤î HTTP/1.1" 200 -
[2022-04-29 02:24:10,162] INFO in _internal: 127.0.0.1 - - [29/Apr/2022 02:24:10] "[36mGET /static/img/riot.png HTTP/1.1[0m" 304 -
[2022-04-29 02:25:42,695] INFO in _internal:  * Running on http://127.0.0.1:5000/ (Press CTRL+C to quit)
[2022-04-29 02:25:48,247] DEBUG in connectionpool: Starting new HTTPS connection (1): kr.api.riotgames.com:443
[2022-04-29 02:25:48,532] DEBUG in connectionpool: https://kr.api.riotgames.com:443 "GET /lol/summoner/v4/summoners/by-name/%ED%95%AB%EC%83%81%EB%B2%94 HTTP/1.1" 200 None
[2022-04-29 02:25:48,544] DEBUG in connectionpool: Starting new HTTPS connection (1): kr.api.riotgames.com:443
[2022-04-29 02:25:48,804] DEBUG in connectionpool: https://kr.api.riotgames.com:443 "GET /lol/summoner/v4/summoners/by-name/%ED%95%AB%EC%83%81%EB%B2%94 HTTP/1.1" 200 None
[2022-04-29 02:25:48,818] DEBUG in connectionpool: Starting new HTTPS connection (1): kr.api.riotgames.com:443
[2022-04-29 02:25:49,152] DEBUG in connectionpool: https://kr.api.riotgames.com:443 "GET /lol/champion-mastery/v4/champion-masteries/by-summoner/XnhdEBDrdxzLMqJVhZBnhh6PI5WHJcbU7JZMncss1JBPiw HTTP/1.1" 200 None
[2022-04-29 02:25:49,985] DEBUG in connectionpool: Starting new HTTPS connection (1): kr.api.riotgames.com:443
[2022-04-29 02:25:50,259] DEBUG in connectionpool: https://kr.api.riotgames.com:443 "GET /lol/summoner/v4/summoners/by-name/%ED%95%AB%EC%83%81%EB%B2%94 HTTP/1.1" 200 None
[2022-04-29 02:25:50,269] DEBUG in connectionpool: Starting new HTTPS connection (1): kr.api.riotgames.com:443
[2022-04-29 02:25:53,528] DEBUG in connectionpool: https://kr.api.riotgames.com:443 "GET /lol/spectator/v4/active-games/by-summoner/XnhdEBDrdxzLMqJVhZBnhh6PI5WHJcbU7JZMncss1JBPiw HTTP/1.1" 503 None
[2022-04-29 02:25:53,859] INFO in _internal: 127.0.0.1 - - [29/Apr/2022 02:25:53] "GET /result?username=Ìï´ÏÉÅÎ≤î HTTP/1.1" 200 -
[2022-04-29 02:25:53,883] INFO in _internal: 127.0.0.1 - - [29/Apr/2022 02:25:53] "[36mGET /static/img/riot.png HTTP/1.1[0m" 304 -
[2022-04-29 02:26:24,521] INFO in _internal:  * Running on http://127.0.0.1:5000/ (Press CTRL+C to quit)
[2022-04-29 02:26:30,340] DEBUG in connectionpool: Starting new HTTPS connection (1): kr.api.riotgames.com:443
[2022-04-29 02:26:30,633] DEBUG in connectionpool: https://kr.api.riotgames.com:443 "GET /lol/summoner/v4/summoners/by-name/%ED%95%AB%EC%83%81%EB%B2%94 HTTP/1.1" 200 None
[2022-04-29 02:26:30,644] DEBUG in connectionpool: Starting new HTTPS connection (1): kr.api.riotgames.com:443
[2022-04-29 02:26:30,958] DEBUG in connectionpool: https://kr.api.riotgames.com:443 "GET /lol/summoner/v4/summoners/by-name/%ED%95%AB%EC%83%81%EB%B2%94 HTTP/1.1" 200 None
[2022-04-29 02:26:30,970] DEBUG in connectionpool: Starting new HTTPS connection (1): kr.api.riotgames.com:443
[2022-04-29 02:26:31,273] DEBUG in connectionpool: https://kr.api.riotgames.com:443 "GET /lol/champion-mastery/v4/champion-masteries/by-summoner/XnhdEBDrdxzLMqJVhZBnhh6PI5WHJcbU7JZMncss1JBPiw HTTP/1.1" 200 None
[2022-04-29 02:26:32,040] DEBUG in connectionpool: Starting new HTTPS connection (1): kr.api.riotgames.com:443
[2022-04-29 02:26:32,357] DEBUG in connectionpool: https://kr.api.riotgames.com:443 "GET /lol/summoner/v4/summoners/by-name/%ED%95%AB%EC%83%81%EB%B2%94 HTTP/1.1" 200 None
[2022-04-29 02:26:32,369] DEBUG in connectionpool: Starting new HTTPS connection (1): kr.api.riotgames.com:443
[2022-04-29 02:26:35,813] DEBUG in connectionpool: https://kr.api.riotgames.com:443 "GET /lol/spectator/v4/active-games/by-summoner/XnhdEBDrdxzLMqJVhZBnhh6PI5WHJcbU7JZMncss1JBPiw HTTP/1.1" 503 None
[2022-04-29 02:26:36,130] INFO in _internal: 127.0.0.1 - - [29/Apr/2022 02:26:36] "GET /result?username=Ìï´ÏÉÅÎ≤î HTTP/1.1" 200 -
[2022-04-29 02:26:36,153] INFO in _internal: 127.0.0.1 - - [29/Apr/2022 02:26:36] "[36mGET /static/img/riot.png HTTP/1.1[0m" 304 -
[2022-04-29 02:27:18,052] INFO in main_views: INFO Î†àÎ≤®Î°ú Ï∂úÎ†•
[2022-04-29 02:27:18,056] INFO in _internal: 127.0.0.1 - - [29/Apr/2022 02:27:18] "GET / HTTP/1.1" 200 -
[2022-04-29 02:27:18,066] INFO in _internal: 127.0.0.1 - - [29/Apr/2022 02:27:18] "[36mGET /static/img/riot.png HTTP/1.1[0m" 304 -
[2022-04-29 02:27:19,114] INFO in main_views: INFO Î†àÎ≤®Î°ú Ï∂úÎ†•
[2022-04-29 02:27:19,116] INFO in _internal: 127.0.0.1 - - [29/Apr/2022 02:27:19] "GET / HTTP/1.1" 200 -
[2022-04-29 02:27:19,126] INFO in _internal: 127.0.0.1 - - [29/Apr/2022 02:27:19] "[36mGET /static/img/riot.png HTTP/1.1[0m" 304 -
[2022-04-29 02:35:17,340] INFO in _internal:  * Running on http://127.0.0.1:5000/ (Press CTRL+C to quit)
[2022-04-29 02:35:20,895] INFO in main_views: INFO Î†àÎ≤®Î°ú Ï∂úÎ†•
[2022-04-29 02:35:20,904] INFO in _internal: 127.0.0.1 - - [29/Apr/2022 02:35:20] "GET / HTTP/1.1" 200 -
[2022-04-29 02:35:20,924] INFO in _internal: 127.0.0.1 - - [29/Apr/2022 02:35:20] "[36mGET /static/img/riot.png HTTP/1.1[0m" 304 -
[2022-04-29 02:35:23,621] DEBUG in connectionpool: Starting new HTTPS connection (1): kr.api.riotgames.com:443
[2022-04-29 02:35:23,902] DEBUG in connectionpool: https://kr.api.riotgames.com:443 "GET /lol/summoner/v4/summoners/by-name/%ED%95%AB%EC%83%81%EB%B2%94 HTTP/1.1" 200 None
[2022-04-29 02:35:23,912] DEBUG in connectionpool: Starting new HTTPS connection (1): kr.api.riotgames.com:443
[2022-04-29 02:35:24,177] DEBUG in connectionpool: https://kr.api.riotgames.com:443 "GET /lol/summoner/v4/summoners/by-name/%ED%95%AB%EC%83%81%EB%B2%94 HTTP/1.1" 200 None
[2022-04-29 02:35:24,190] DEBUG in connectionpool: Starting new HTTPS connection (1): kr.api.riotgames.com:443
[2022-04-29 02:35:24,487] DEBUG in connectionpool: https://kr.api.riotgames.com:443 "GET /lol/champion-mastery/v4/champion-masteries/by-summoner/XnhdEBDrdxzLMqJVhZBnhh6PI5WHJcbU7JZMncss1JBPiw HTTP/1.1" 200 None
[2022-04-29 02:35:25,343] DEBUG in connectionpool: Starting new HTTPS connection (1): kr.api.riotgames.com:443
[2022-04-29 02:35:25,618] DEBUG in connectionpool: https://kr.api.riotgames.com:443 "GET /lol/summoner/v4/summoners/by-name/%ED%95%AB%EC%83%81%EB%B2%94 HTTP/1.1" 200 None
[2022-04-29 02:35:25,629] DEBUG in connectionpool: Starting new HTTPS connection (1): kr.api.riotgames.com:443
[2022-04-29 02:35:28,909] DEBUG in connectionpool: https://kr.api.riotgames.com:443 "GET /lol/spectator/v4/active-games/by-summoner/XnhdEBDrdxzLMqJVhZBnhh6PI5WHJcbU7JZMncss1JBPiw HTTP/1.1" 503 None
[2022-04-29 02:35:29,237] INFO in _internal: 127.0.0.1 - - [29/Apr/2022 02:35:29] "GET /result?username=Ìï´ÏÉÅÎ≤î HTTP/1.1" 200 -
[2022-04-29 02:35:29,257] INFO in _internal: 127.0.0.1 - - [29/Apr/2022 02:35:29] "[36mGET /static/img/riot.png HTTP/1.1[0m" 304 -
[2022-04-29 02:35:34,006] INFO in _internal:  * Running on http://127.0.0.1:5000/ (Press CTRL+C to quit)
[2022-04-29 02:35:36,032] INFO in main_views: INFO Î†àÎ≤®Î°ú Ï∂úÎ†•
[2022-04-29 02:35:36,042] INFO in _internal: 127.0.0.1 - - [29/Apr/2022 02:35:36] "GET / HTTP/1.1" 200 -
[2022-04-29 02:35:36,061] INFO in _internal: 127.0.0.1 - - [29/Apr/2022 02:35:36] "[36mGET /static/img/riot.png HTTP/1.1[0m" 304 -
[2022-04-29 02:35:37,700] DEBUG in connectionpool: Starting new HTTPS connection (1): kr.api.riotgames.com:443
[2022-04-29 02:35:37,927] DEBUG in connectionpool: https://kr.api.riotgames.com:443 "GET /lol/summoner/v4/summoners/by-name/ HTTP/1.1" 403 None
[2022-04-29 02:35:37,934] ERROR in app: Exception on /result [GET]
Traceback (most recent call last):
  File "/Users/piat/opt/anaconda3/envs/cp1/lib/python3.8/site-packages/flask/app.py", line 2070, in wsgi_app
    response = self.full_dispatch_request()
  File "/Users/piat/opt/anaconda3/envs/cp1/lib/python3.8/site-packages/flask/app.py", line 1515, in full_dispatch_request
    rv = self.handle_user_exception(e)
  File "/Users/piat/opt/anaconda3/envs/cp1/lib/python3.8/site-packages/flask/app.py", line 1513, in full_dispatch_request
    rv = self.dispatch_request()
  File "/Users/piat/opt/anaconda3/envs/cp1/lib/python3.8/site-packages/flask/app.py", line 1499, in dispatch_request
    return self.ensure_sync(self.view_functions[rule.endpoint])(**req.view_args)
  File "/Users/piat/s5/cp1/New/app/views/main_views.py", line 72, in result
    val = [count+1, nick]
NameError: name 'count' is not defined
[2022-04-29 02:35:37,939] INFO in _internal: 127.0.0.1 - - [29/Apr/2022 02:35:37] "[35m[1mGET /result?username= HTTP/1.1[0m" 500 -
[2022-04-29 02:36:05,598] INFO in _internal:  * Running on http://127.0.0.1:5000/ (Press CTRL+C to quit)
[2022-04-29 02:36:11,407] INFO in main_views: INFO Î†àÎ≤®Î°ú Ï∂úÎ†•
[2022-04-29 02:36:11,412] INFO in _internal: 127.0.0.1 - - [29/Apr/2022 02:36:11] "GET / HTTP/1.1" 200 -
[2022-04-29 02:36:11,420] INFO in _internal: 127.0.0.1 - - [29/Apr/2022 02:36:11] "[36mGET /static/img/riot.png HTTP/1.1[0m" 304 -
[2022-04-29 02:36:12,061] INFO in main_views: INFO Î†àÎ≤®Î°ú Ï∂úÎ†•
[2022-04-29 02:36:12,062] INFO in _internal: 127.0.0.1 - - [29/Apr/2022 02:36:12] "GET / HTTP/1.1" 200 -
[2022-04-29 02:36:12,075] INFO in _internal: 127.0.0.1 - - [29/Apr/2022 02:36:12] "[36mGET /static/img/riot.png HTTP/1.1[0m" 304 -
[2022-04-29 02:36:14,431] INFO in _internal: 127.0.0.1 - - [29/Apr/2022 02:36:14] "[33mGET /result?username=Ìï´ÏÉÅÎ≤î HTTP/1.1[0m" 404 -
[2022-04-29 02:37:02,828] INFO in _internal:  * Running on http://127.0.0.1:5000/ (Press CTRL+C to quit)
[2022-04-29 02:37:05,233] INFO in _internal: 127.0.0.1 - - [29/Apr/2022 02:37:05] "[33mGET /result?username=Ìï´ÏÉÅÎ≤î HTTP/1.1[0m" 404 -
[2022-04-29 02:37:10,299] INFO in _internal: 127.0.0.1 - - [29/Apr/2022 02:37:10] "[33mGET /result?username= HTTP/1.1[0m" 404 -
[2022-04-29 02:56:19,009] INFO in _internal:  * Running on http://127.0.0.1:5000/ (Press CTRL+C to quit)
[2022-04-29 02:56:24,467] INFO in _internal: 127.0.0.1 - - [29/Apr/2022 02:56:24] "[33mGET /result?username=Ìï´ÏÉÅÎ≤î HTTP/1.1[0m" 404 -
INFO:werkzeug: * Running on http://127.0.0.1:5000/ (Press CTRL+C to quit)
INFO:werkzeug:127.0.0.1 - - [29/Apr/2022 02:58:50] "[33mGET /result?username=Ìï´ÏÉÅÎ≤î HTTP/1.1[0m" 404 -
INFO:werkzeug:127.0.0.1 - - [29/Apr/2022 03:04:58] "[33mGET /result?username= HTTP/1.1[0m" 404 -
INFO:werkzeug: * Running on http://127.0.0.1:5000/ (Press CTRL+C to quit)
INFO:werkzeug:127.0.0.1 - - [29/Apr/2022 03:06:08] "[33mGET /result?username=Ìï´ÏÉÅÎ≤î HTTP/1.1[0m" 404 -
INFO:werkzeug: * Running on http://127.0.0.1:5000/ (Press CTRL+C to quit)
INFO:werkzeug:127.0.0.1 - - [29/Apr/2022 03:06:29] "[33mGET /result?username=Ìï´ÏÉÅÎ≤î HTTP/1.1[0m" 404 -
INFO:werkzeug: * Running on http://127.0.0.1:5000/ (Press CTRL+C to quit)
INFO:app:INFO Î†àÎ≤®Î°ú Ï∂úÎ†•
INFO:werkzeug:127.0.0.1 - - [29/Apr/2022 03:17:40] "GET / HTTP/1.1" 200 -
INFO:werkzeug:127.0.0.1 - - [29/Apr/2022 03:17:40] "[36mGET /static/img/riot.png HTTP/1.1[0m" 304 -
ERROR:app:Exception on /result/result [GET]
Traceback (most recent call last):
  File "/Users/piat/opt/anaconda3/envs/cp1/lib/python3.8/site-packages/flask/app.py", line 2070, in wsgi_app
    response = self.full_dispatch_request()
  File "/Users/piat/opt/anaconda3/envs/cp1/lib/python3.8/site-packages/flask/app.py", line 1515, in full_dispatch_request
    rv = self.handle_user_exception(e)
  File "/Users/piat/opt/anaconda3/envs/cp1/lib/python3.8/site-packages/flask/app.py", line 1513, in full_dispatch_request
    rv = self.dispatch_request()
  File "/Users/piat/opt/anaconda3/envs/cp1/lib/python3.8/site-packages/flask/app.py", line 1499, in dispatch_request
    return self.ensure_sync(self.view_functions[rule.endpoint])(**req.view_args)
  File "/Users/piat/s5/cp1/New/app/views/result_view.py", line 122, in result
    return render_template('result.html', nick = sel_nick, champ=sel_champ, num = num, username = nick, m = m)
UnboundLocalError: local variable 'sel_nick' referenced before assignment
INFO:werkzeug:127.0.0.1 - - [29/Apr/2022 03:17:43] "[35m[1mGET /result/result?username= HTTP/1.1[0m" 500 -
INFO:werkzeug: * Running on http://127.0.0.1:5000/ (Press CTRL+C to quit)
ERROR:app:Exception on /result/result [GET]
Traceback (most recent call last):
  File "/Users/piat/opt/anaconda3/envs/cp1/lib/python3.8/site-packages/flask/app.py", line 2070, in wsgi_app
    response = self.full_dispatch_request()
  File "/Users/piat/opt/anaconda3/envs/cp1/lib/python3.8/site-packages/flask/app.py", line 1515, in full_dispatch_request
    rv = self.handle_user_exception(e)
  File "/Users/piat/opt/anaconda3/envs/cp1/lib/python3.8/site-packages/flask/app.py", line 1513, in full_dispatch_request
    rv = self.dispatch_request()
  File "/Users/piat/opt/anaconda3/envs/cp1/lib/python3.8/site-packages/flask/app.py", line 1499, in dispatch_request
    return self.ensure_sync(self.view_functions[rule.endpoint])(**req.view_args)
  File "/Users/piat/s5/cp1/New/app/views/result_view.py", line 122, in result
    return render_template('result.html', nick = sel_nick, champ=sel_champ, num = num, username = nick, m = m)
UnboundLocalError: local variable 'sel_nick' referenced before assignment
INFO:werkzeug:127.0.0.1 - - [29/Apr/2022 03:18:36] "[35m[1mGET /result/result?username= HTTP/1.1[0m" 500 -
INFO:werkzeug: * Running on http://127.0.0.1:5000/ (Press CTRL+C to quit)
ERROR:app:Exception on /result/result [GET]
Traceback (most recent call last):
  File "/Users/piat/opt/anaconda3/envs/cp1/lib/python3.8/site-packages/flask/app.py", line 2070, in wsgi_app
    response = self.full_dispatch_request()
  File "/Users/piat/opt/anaconda3/envs/cp1/lib/python3.8/site-packages/flask/app.py", line 1515, in full_dispatch_request
    rv = self.handle_user_exception(e)
  File "/Users/piat/opt/anaconda3/envs/cp1/lib/python3.8/site-packages/flask/app.py", line 1513, in full_dispatch_request
    rv = self.dispatch_request()
  File "/Users/piat/opt/anaconda3/envs/cp1/lib/python3.8/site-packages/flask/app.py", line 1499, in dispatch_request
    return self.ensure_sync(self.view_functions[rule.endpoint])(**req.view_args)
  File "/Users/piat/s5/cp1/New/app/views/result_view.py", line 122, in result
    return render_template('result.html', nick = sel_nick, champ=sel_champ, num = num, username = nick, m = m)
UnboundLocalError: local variable 'sel_nick' referenced before assignment
INFO:werkzeug:127.0.0.1 - - [29/Apr/2022 03:20:34] "[35m[1mGET /result/result?username= HTTP/1.1[0m" 500 -
INFO:werkzeug: * Running on http://127.0.0.1:5000/ (Press CTRL+C to quit)
INFO:app:INFO Î†àÎ≤®Î°ú Ï∂úÎ†•
ERROR:app:Exception on / [GET]
Traceback (most recent call last):
  File "/Users/piat/opt/anaconda3/envs/cp1/lib/python3.8/site-packages/flask/app.py", line 2070, in wsgi_app
    response = self.full_dispatch_request()
  File "/Users/piat/opt/anaconda3/envs/cp1/lib/python3.8/site-packages/flask/app.py", line 1515, in full_dispatch_request
    rv = self.handle_user_exception(e)
  File "/Users/piat/opt/anaconda3/envs/cp1/lib/python3.8/site-packages/flask/app.py", line 1513, in full_dispatch_request
    rv = self.dispatch_request()
  File "/Users/piat/opt/anaconda3/envs/cp1/lib/python3.8/site-packages/flask/app.py", line 1499, in dispatch_request
    return self.ensure_sync(self.view_functions[rule.endpoint])(**req.view_args)
  File "/Users/piat/s5/cp1/New/app/views/main_views.py", line 14, in index
    return render_template('index.html',  name = name, champ1=champ1)
  File "/Users/piat/opt/anaconda3/envs/cp1/lib/python3.8/site-packages/flask/templating.py", line 147, in render_template
    return _render(
  File "/Users/piat/opt/anaconda3/envs/cp1/lib/python3.8/site-packages/flask/templating.py", line 128, in _render
    rv = template.render(context)
  File "/Users/piat/opt/anaconda3/envs/cp1/lib/python3.8/site-packages/jinja2/environment.py", line 1304, in render
    self.environment.handle_exception()
  File "/Users/piat/opt/anaconda3/envs/cp1/lib/python3.8/site-packages/jinja2/environment.py", line 925, in handle_exception
    raise rewrite_traceback_stack(source=source)
  File "/Users/piat/s5/cp1/New/app/templates/index.html", line 15, in top-level template code
    <form method="POST" action="{{url_for('result')}}">
  File "/Users/piat/opt/anaconda3/envs/cp1/lib/python3.8/site-packages/flask/helpers.py", line 338, in url_for
    return appctx.app.handle_url_build_error(error, endpoint, values)
  File "/Users/piat/opt/anaconda3/envs/cp1/lib/python3.8/site-packages/flask/helpers.py", line 325, in url_for
    rv = url_adapter.build(
  File "/Users/piat/opt/anaconda3/envs/cp1/lib/python3.8/site-packages/werkzeug/routing.py", line 2305, in build
    raise BuildError(endpoint, values, method, self)
werkzeug.routing.BuildError: Could not build url for endpoint 'result'. Did you mean 'result.result' instead?
INFO:werkzeug:127.0.0.1 - - [29/Apr/2022 03:20:49] "[35m[1mGET / HTTP/1.1[0m" 500 -
INFO:werkzeug: * Running on http://127.0.0.1:5000/ (Press CTRL+C to quit)
INFO:app:INFO Î†àÎ≤®Î°ú Ï∂úÎ†•
INFO:werkzeug:127.0.0.1 - - [29/Apr/2022 03:22:00] "GET / HTTP/1.1" 200 -
INFO:werkzeug:127.0.0.1 - - [29/Apr/2022 03:22:00] "[36mGET /static/img/riot.png HTTP/1.1[0m" 304 -
ERROR:app:Exception on /result/result [POST]
Traceback (most recent call last):
  File "/Users/piat/opt/anaconda3/envs/cp1/lib/python3.8/site-packages/flask/app.py", line 2070, in wsgi_app
    response = self.full_dispatch_request()
  File "/Users/piat/opt/anaconda3/envs/cp1/lib/python3.8/site-packages/flask/app.py", line 1515, in full_dispatch_request
    rv = self.handle_user_exception(e)
  File "/Users/piat/opt/anaconda3/envs/cp1/lib/python3.8/site-packages/flask/app.py", line 1513, in full_dispatch_request
    rv = self.dispatch_request()
  File "/Users/piat/opt/anaconda3/envs/cp1/lib/python3.8/site-packages/flask/app.py", line 1499, in dispatch_request
    return self.ensure_sync(self.view_functions[rule.endpoint])(**req.view_args)
  File "/Users/piat/s5/cp1/New/app/views/result_view.py", line 51, in result
    nick = nick.replace(" ", "")
AttributeError: 'NoneType' object has no attribute 'replace'
INFO:werkzeug:127.0.0.1 - - [29/Apr/2022 03:22:07] "[35m[1mPOST /result/result HTTP/1.1[0m" 500 -
ERROR:app:Exception on /result/result [POST]
Traceback (most recent call last):
  File "/Users/piat/opt/anaconda3/envs/cp1/lib/python3.8/site-packages/flask/app.py", line 2070, in wsgi_app
    response = self.full_dispatch_request()
  File "/Users/piat/opt/anaconda3/envs/cp1/lib/python3.8/site-packages/flask/app.py", line 1515, in full_dispatch_request
    rv = self.handle_user_exception(e)
  File "/Users/piat/opt/anaconda3/envs/cp1/lib/python3.8/site-packages/flask/app.py", line 1513, in full_dispatch_request
    rv = self.dispatch_request()
  File "/Users/piat/opt/anaconda3/envs/cp1/lib/python3.8/site-packages/flask/app.py", line 1499, in dispatch_request
    return self.ensure_sync(self.view_functions[rule.endpoint])(**req.view_args)
  File "/Users/piat/s5/cp1/New/app/views/result_view.py", line 51, in result
    nick = nick.replace(" ", "")
AttributeError: 'NoneType' object has no attribute 'replace'
INFO:werkzeug:127.0.0.1 - - [29/Apr/2022 03:23:17] "[35m[1mPOST /result/result HTTP/1.1[0m" 500 -
INFO:werkzeug: * Running on http://127.0.0.1:5000/ (Press CTRL+C to quit)
INFO:werkzeug:127.0.0.1 - - [29/Apr/2022 03:23:23] "[33mPOST /result/result HTTP/1.1[0m" 404 -
INFO:werkzeug: * Running on http://127.0.0.1:5000/ (Press CTRL+C to quit)
INFO:werkzeug:127.0.0.1 - - [29/Apr/2022 03:23:41] "[33mPOST /result/result HTTP/1.1[0m" 404 -
INFO:werkzeug:127.0.0.1 - - [29/Apr/2022 03:23:46] "[33mPOST /result/result HTTP/1.1[0m" 404 -
INFO:werkzeug:127.0.0.1 - - [29/Apr/2022 03:24:11] "[33mPOST /result/result HTTP/1.1[0m" 404 -
INFO:werkzeug: * Running on http://127.0.0.1:5000/ (Press CTRL+C to quit)
INFO:werkzeug:127.0.0.1 - - [29/Apr/2022 03:25:13] "[33mPOST /result/result HTTP/1.1[0m" 404 -
INFO:werkzeug: * Running on http://127.0.0.1:5000/ (Press CTRL+C to quit)
INFO:werkzeug:127.0.0.1 - - [29/Apr/2022 03:25:54] "[33mPOST /result/result HTTP/1.1[0m" 404 -
INFO:werkzeug:127.0.0.1 - - [29/Apr/2022 03:25:57] "[33mPOST /result/result HTTP/1.1[0m" 404 -
INFO:werkzeug: * Running on http://127.0.0.1:5000/ (Press CTRL+C to quit)
INFO:werkzeug:127.0.0.1 - - [29/Apr/2022 03:33:17] "[33mPOST /result/result HTTP/1.1[0m" 404 -
INFO:app:INFO Î†àÎ≤®Î°ú Ï∂úÎ†•
INFO:werkzeug:127.0.0.1 - - [29/Apr/2022 03:34:01] "GET / HTTP/1.1" 200 -
INFO:werkzeug:127.0.0.1 - - [29/Apr/2022 03:34:01] "[36mGET /static/img/riot.png HTTP/1.1[0m" 304 -
ERROR:app:Exception on /result [POST]
Traceback (most recent call last):
  File "/Users/piat/opt/anaconda3/envs/cp1/lib/python3.8/site-packages/flask/app.py", line 2070, in wsgi_app
    response = self.full_dispatch_request()
  File "/Users/piat/opt/anaconda3/envs/cp1/lib/python3.8/site-packages/flask/app.py", line 1515, in full_dispatch_request
    rv = self.handle_user_exception(e)
  File "/Users/piat/opt/anaconda3/envs/cp1/lib/python3.8/site-packages/flask/app.py", line 1513, in full_dispatch_request
    rv = self.dispatch_request()
  File "/Users/piat/opt/anaconda3/envs/cp1/lib/python3.8/site-packages/flask/app.py", line 1499, in dispatch_request
    return self.ensure_sync(self.view_functions[rule.endpoint])(**req.view_args)
  File "/Users/piat/s5/cp1/New/app/views/result_view.py", line 51, in result
    nick = nick.replace(" ", "")
AttributeError: 'NoneType' object has no attribute 'replace'
INFO:werkzeug:127.0.0.1 - - [29/Apr/2022 03:34:03] "[35m[1mPOST /result HTTP/1.1[0m" 500 -
ERROR:app:Exception on /result [POST]
Traceback (most recent call last):
  File "/Users/piat/opt/anaconda3/envs/cp1/lib/python3.8/site-packages/flask/app.py", line 2070, in wsgi_app
    response = self.full_dispatch_request()
  File "/Users/piat/opt/anaconda3/envs/cp1/lib/python3.8/site-packages/flask/app.py", line 1515, in full_dispatch_request
    rv = self.handle_user_exception(e)
  File "/Users/piat/opt/anaconda3/envs/cp1/lib/python3.8/site-packages/flask/app.py", line 1513, in full_dispatch_request
    rv = self.dispatch_request()
  File "/Users/piat/opt/anaconda3/envs/cp1/lib/python3.8/site-packages/flask/app.py", line 1499, in dispatch_request
    return self.ensure_sync(self.view_functions[rule.endpoint])(**req.view_args)
  File "/Users/piat/s5/cp1/New/app/views/result_view.py", line 51, in result
    nick = nick.replace(" ", "")
AttributeError: 'NoneType' object has no attribute 'replace'
INFO:werkzeug:127.0.0.1 - - [29/Apr/2022 03:34:23] "[35m[1mPOST /result HTTP/1.1[0m" 500 -
INFO:app:INFO Î†àÎ≤®Î°ú Ï∂úÎ†•
INFO:werkzeug:127.0.0.1 - - [29/Apr/2022 03:34:38] "GET / HTTP/1.1" 200 -
INFO:werkzeug:127.0.0.1 - - [29/Apr/2022 03:34:38] "[36mGET /static/img/riot.png HTTP/1.1[0m" 304 -
ERROR:app:Exception on /result [POST]
Traceback (most recent call last):
  File "/Users/piat/opt/anaconda3/envs/cp1/lib/python3.8/site-packages/flask/app.py", line 2070, in wsgi_app
    response = self.full_dispatch_request()
  File "/Users/piat/opt/anaconda3/envs/cp1/lib/python3.8/site-packages/flask/app.py", line 1515, in full_dispatch_request
    rv = self.handle_user_exception(e)
  File "/Users/piat/opt/anaconda3/envs/cp1/lib/python3.8/site-packages/flask/app.py", line 1513, in full_dispatch_request
    rv = self.dispatch_request()
  File "/Users/piat/opt/anaconda3/envs/cp1/lib/python3.8/site-packages/flask/app.py", line 1499, in dispatch_request
    return self.ensure_sync(self.view_functions[rule.endpoint])(**req.view_args)
  File "/Users/piat/s5/cp1/New/app/views/result_view.py", line 51, in result
    nick = nick.replace(" ", "")
AttributeError: 'NoneType' object has no attribute 'replace'
INFO:werkzeug:127.0.0.1 - - [29/Apr/2022 03:34:47] "[35m[1mPOST /result HTTP/1.1[0m" 500 -
INFO:werkzeug: * Running on http://127.0.0.1:5000/ (Press CTRL+C to quit)
INFO:app:INFO Î†àÎ≤®Î°ú Ï∂úÎ†•
INFO:werkzeug:127.0.0.1 - - [29/Apr/2022 03:38:11] "GET / HTTP/1.1" 200 -
INFO:werkzeug:127.0.0.1 - - [29/Apr/2022 03:38:11] "[36mGET /static/img/riot.png HTTP/1.1[0m" 304 -
ERROR:app:Exception on /result [POST]
Traceback (most recent call last):
  File "/Users/piat/opt/anaconda3/envs/cp1/lib/python3.8/site-packages/flask/app.py", line 2070, in wsgi_app
    response = self.full_dispatch_request()
  File "/Users/piat/opt/anaconda3/envs/cp1/lib/python3.8/site-packages/flask/app.py", line 1515, in full_dispatch_request
    rv = self.handle_user_exception(e)
  File "/Users/piat/opt/anaconda3/envs/cp1/lib/python3.8/site-packages/flask/app.py", line 1513, in full_dispatch_request
    rv = self.dispatch_request()
  File "/Users/piat/opt/anaconda3/envs/cp1/lib/python3.8/site-packages/flask/app.py", line 1499, in dispatch_request
    return self.ensure_sync(self.view_functions[rule.endpoint])(**req.view_args)
  File "/Users/piat/s5/cp1/New/app/views/result_view.py", line 51, in result
    nick = nick.replace(" ", "")
AttributeError: 'NoneType' object has no attribute 'replace'
INFO:werkzeug:127.0.0.1 - - [29/Apr/2022 03:38:13] "[35m[1mPOST /result HTTP/1.1[0m" 500 -
INFO:werkzeug: * Running on http://127.0.0.1:5000/ (Press CTRL+C to quit)
ERROR:app:Exception on /result [POST]
Traceback (most recent call last):
  File "/Users/piat/opt/anaconda3/envs/cp1/lib/python3.8/site-packages/flask/app.py", line 2070, in wsgi_app
    response = self.full_dispatch_request()
  File "/Users/piat/opt/anaconda3/envs/cp1/lib/python3.8/site-packages/flask/app.py", line 1515, in full_dispatch_request
    rv = self.handle_user_exception(e)
  File "/Users/piat/opt/anaconda3/envs/cp1/lib/python3.8/site-packages/flask/app.py", line 1513, in full_dispatch_request
    rv = self.dispatch_request()
  File "/Users/piat/opt/anaconda3/envs/cp1/lib/python3.8/site-packages/flask/app.py", line 1499, in dispatch_request
    return self.ensure_sync(self.view_functions[rule.endpoint])(**req.view_args)
  File "/Users/piat/s5/cp1/New/app/views/result_view.py", line 51, in result
    nick = nick.replace(" ", "")
AttributeError: 'NoneType' object has no attribute 'replace'
INFO:werkzeug:127.0.0.1 - - [29/Apr/2022 03:38:59] "[35m[1mPOST /result HTTP/1.1[0m" 500 -
INFO:werkzeug: * Running on http://127.0.0.1:5000/ (Press CTRL+C to quit)
INFO:app:INFO Î†àÎ≤®Î°ú Ï∂úÎ†•
INFO:werkzeug:127.0.0.1 - - [29/Apr/2022 03:40:25] "GET / HTTP/1.1" 200 -
INFO:werkzeug:127.0.0.1 - - [29/Apr/2022 03:40:25] "[36mGET /static/img/riot.png HTTP/1.1[0m" 304 -
DEBUG:urllib3.connectionpool:Starting new HTTPS connection (1): kr.api.riotgames.com:443
DEBUG:urllib3.connectionpool:https://kr.api.riotgames.com:443 "GET /lol/summoner/v4/summoners/by-name/%ED%95%AB%EC%83%81%EB%B2%94 HTTP/1.1" 200 None
DEBUG:urllib3.connectionpool:Starting new HTTPS connection (1): kr.api.riotgames.com:443
DEBUG:urllib3.connectionpool:https://kr.api.riotgames.com:443 "GET /lol/summoner/v4/summoners/by-name/%ED%95%AB%EC%83%81%EB%B2%94 HTTP/1.1" 200 None
DEBUG:urllib3.connectionpool:Starting new HTTPS connection (1): kr.api.riotgames.com:443
DEBUG:urllib3.connectionpool:https://kr.api.riotgames.com:443 "GET /lol/champion-mastery/v4/champion-masteries/by-summoner/XnhdEBDrdxzLMqJVhZBnhh6PI5WHJcbU7JZMncss1JBPiw HTTP/1.1" 200 None
DEBUG:urllib3.connectionpool:Starting new HTTPS connection (1): kr.api.riotgames.com:443
DEBUG:urllib3.connectionpool:https://kr.api.riotgames.com:443 "GET /lol/summoner/v4/summoners/by-name/%ED%95%AB%EC%83%81%EB%B2%94 HTTP/1.1" 200 None
DEBUG:urllib3.connectionpool:Starting new HTTPS connection (1): kr.api.riotgames.com:443
DEBUG:urllib3.connectionpool:https://kr.api.riotgames.com:443 "GET /lol/spectator/v4/active-games/by-summoner/XnhdEBDrdxzLMqJVhZBnhh6PI5WHJcbU7JZMncss1JBPiw HTTP/1.1" 503 None
ERROR:app:Exception on /result [POST]
Traceback (most recent call last):
  File "/Users/piat/opt/anaconda3/envs/cp1/lib/python3.8/site-packages/flask/app.py", line 2070, in wsgi_app
    response = self.full_dispatch_request()
  File "/Users/piat/opt/anaconda3/envs/cp1/lib/python3.8/site-packages/flask/app.py", line 1515, in full_dispatch_request
    rv = self.handle_user_exception(e)
  File "/Users/piat/opt/anaconda3/envs/cp1/lib/python3.8/site-packages/flask/app.py", line 1513, in full_dispatch_request
    rv = self.dispatch_request()
  File "/Users/piat/opt/anaconda3/envs/cp1/lib/python3.8/site-packages/flask/app.py", line 1499, in dispatch_request
    return self.ensure_sync(self.view_functions[rule.endpoint])(**req.view_args)
  File "/Users/piat/s5/cp1/New/app/views/result_view.py", line 89, in result
    save_log(log_class.doc)
NameError: name 'save_log' is not defined
INFO:werkzeug:127.0.0.1 - - [29/Apr/2022 03:40:34] "[35m[1mPOST /result HTTP/1.1[0m" 500 -
INFO:werkzeug: * Running on http://127.0.0.1:5000/ (Press CTRL+C to quit)
DEBUG:urllib3.connectionpool:Starting new HTTPS connection (1): kr.api.riotgames.com:443
DEBUG:urllib3.connectionpool:https://kr.api.riotgames.com:443 "GET /lol/summoner/v4/summoners/by-name/%ED%95%AB%EC%83%81%EB%B2%94 HTTP/1.1" 200 None
DEBUG:urllib3.connectionpool:Starting new HTTPS connection (1): kr.api.riotgames.com:443
DEBUG:urllib3.connectionpool:https://kr.api.riotgames.com:443 "GET /lol/summoner/v4/summoners/by-name/%ED%95%AB%EC%83%81%EB%B2%94 HTTP/1.1" 200 None
DEBUG:urllib3.connectionpool:Starting new HTTPS connection (1): kr.api.riotgames.com:443
DEBUG:urllib3.connectionpool:https://kr.api.riotgames.com:443 "GET /lol/champion-mastery/v4/champion-masteries/by-summoner/XnhdEBDrdxzLMqJVhZBnhh6PI5WHJcbU7JZMncss1JBPiw HTTP/1.1" 200 None
DEBUG:urllib3.connectionpool:Starting new HTTPS connection (1): kr.api.riotgames.com:443
DEBUG:urllib3.connectionpool:https://kr.api.riotgames.com:443 "GET /lol/summoner/v4/summoners/by-name/%ED%95%AB%EC%83%81%EB%B2%94 HTTP/1.1" 200 None
DEBUG:urllib3.connectionpool:Starting new HTTPS connection (1): kr.api.riotgames.com:443
DEBUG:urllib3.connectionpool:https://kr.api.riotgames.com:443 "GET /lol/spectator/v4/active-games/by-summoner/XnhdEBDrdxzLMqJVhZBnhh6PI5WHJcbU7JZMncss1JBPiw HTTP/1.1" 404 None
INFO:werkzeug:127.0.0.1 - - [29/Apr/2022 03:42:26] "POST /result HTTP/1.1" 200 -
INFO:werkzeug:127.0.0.1 - - [29/Apr/2022 03:42:26] "[36mGET /static/img/riot.png HTTP/1.1[0m" 304 -
INFO:werkzeug:127.0.0.1 - - [29/Apr/2022 03:42:28] "[31m[1mPOST / HTTP/1.1[0m" 405 -
INFO:werkzeug: * Running on http://127.0.0.1:5000/ (Press CTRL+C to quit)
INFO:app:INFO Î†àÎ≤®Î°ú Ï∂úÎ†•
INFO:werkzeug:127.0.0.1 - - [29/Apr/2022 03:43:40] "GET / HTTP/1.1" 200 -
INFO:werkzeug:127.0.0.1 - - [29/Apr/2022 03:43:40] "[36mGET /static/img/riot.png HTTP/1.1[0m" 304 -
DEBUG:urllib3.connectionpool:Starting new HTTPS connection (1): kr.api.riotgames.com:443
DEBUG:urllib3.connectionpool:https://kr.api.riotgames.com:443 "GET /lol/summoner/v4/summoners/by-name/ HTTP/1.1" 403 None
ERROR:app:Exception on /result [POST]
Traceback (most recent call last):
  File "/Users/piat/opt/anaconda3/envs/cp1/lib/python3.8/site-packages/flask/app.py", line 2070, in wsgi_app
    response = self.full_dispatch_request()
  File "/Users/piat/opt/anaconda3/envs/cp1/lib/python3.8/site-packages/flask/app.py", line 1515, in full_dispatch_request
    rv = self.handle_user_exception(e)
  File "/Users/piat/opt/anaconda3/envs/cp1/lib/python3.8/site-packages/flask/app.py", line 1513, in full_dispatch_request
    rv = self.dispatch_request()
  File "/Users/piat/opt/anaconda3/envs/cp1/lib/python3.8/site-packages/flask/app.py", line 1499, in dispatch_request
    return self.ensure_sync(self.view_functions[rule.endpoint])(**req.view_args)
  File "/Users/piat/s5/cp1/New/app/views/result_view.py", line 60, in result
    val = [count+1, nick]
NameError: name 'count' is not defined
INFO:werkzeug:127.0.0.1 - - [29/Apr/2022 03:43:42] "[35m[1mPOST /result HTTP/1.1[0m" 500 -
INFO:werkzeug: * Running on http://127.0.0.1:5000/ (Press CTRL+C to quit)
DEBUG:urllib3.connectionpool:Starting new HTTPS connection (1): kr.api.riotgames.com:443
DEBUG:urllib3.connectionpool:https://kr.api.riotgames.com:443 "GET /lol/summoner/v4/summoners/by-name/ HTTP/1.1" 403 None
INFO:werkzeug:127.0.0.1 - - [29/Apr/2022 03:44:47] "POST /result HTTP/1.1" 200 -
INFO:werkzeug:127.0.0.1 - - [29/Apr/2022 03:44:47] "[36mGET /static/img/riot.png HTTP/1.1[0m" 304 -
INFO:werkzeug:127.0.0.1 - - [29/Apr/2022 03:45:02] "[31m[1mPOST / HTTP/1.1[0m" 405 -
INFO:app:INFO Î†àÎ≤®Î°ú Ï∂úÎ†•
INFO:werkzeug:127.0.0.1 - - [29/Apr/2022 03:45:22] "GET / HTTP/1.1" 200 -
INFO:werkzeug:127.0.0.1 - - [29/Apr/2022 03:45:22] "[36mGET /static/img/riot.png HTTP/1.1[0m" 304 -
INFO:werkzeug: * Running on http://127.0.0.1:5000/ (Press CTRL+C to quit)
DEBUG:urllib3.connectionpool:Starting new HTTPS connection (1): kr.api.riotgames.com:443
DEBUG:urllib3.connectionpool:https://kr.api.riotgames.com:443 "GET /lol/summoner/v4/summoners/by-name/ HTTP/1.1" 403 None
INFO:werkzeug:127.0.0.1 - - [29/Apr/2022 03:46:53] "POST /result HTTP/1.1" 200 -
INFO:werkzeug:127.0.0.1 - - [29/Apr/2022 03:46:53] "[36mGET /static/img/riot.png HTTP/1.1[0m" 304 -
INFO:app:INFO Î†àÎ≤®Î°ú Ï∂úÎ†•
INFO:werkzeug:127.0.0.1 - - [29/Apr/2022 03:46:54] "POST / HTTP/1.1" 200 -
INFO:werkzeug:127.0.0.1 - - [29/Apr/2022 03:46:54] "[36mGET /static/img/riot.png HTTP/1.1[0m" 304 -
DEBUG:urllib3.connectionpool:Starting new HTTPS connection (1): kr.api.riotgames.com:443
DEBUG:urllib3.connectionpool:https://kr.api.riotgames.com:443 "GET /lol/summoner/v4/summoners/by-name/%ED%95%AB%EC%83%81%EB%B2%94 HTTP/1.1" 200 None
DEBUG:urllib3.connectionpool:Starting new HTTPS connection (1): kr.api.riotgames.com:443
DEBUG:urllib3.connectionpool:https://kr.api.riotgames.com:443 "GET /lol/summoner/v4/summoners/by-name/%ED%95%AB%EC%83%81%EB%B2%94 HTTP/1.1" 200 None
DEBUG:urllib3.connectionpool:Starting new HTTPS connection (1): kr.api.riotgames.com:443
DEBUG:urllib3.connectionpool:https://kr.api.riotgames.com:443 "GET /lol/champion-mastery/v4/champion-masteries/by-summoner/XnhdEBDrdxzLMqJVhZBnhh6PI5WHJcbU7JZMncss1JBPiw HTTP/1.1" 200 None
DEBUG:urllib3.connectionpool:Starting new HTTPS connection (1): kr.api.riotgames.com:443
DEBUG:urllib3.connectionpool:https://kr.api.riotgames.com:443 "GET /lol/summoner/v4/summoners/by-name/%ED%95%AB%EC%83%81%EB%B2%94 HTTP/1.1" 200 None
DEBUG:urllib3.connectionpool:Starting new HTTPS connection (1): kr.api.riotgames.com:443
DEBUG:urllib3.connectionpool:https://kr.api.riotgames.com:443 "GET /lol/spectator/v4/active-games/by-summoner/XnhdEBDrdxzLMqJVhZBnhh6PI5WHJcbU7JZMncss1JBPiw HTTP/1.1" 503 None
INFO:werkzeug:127.0.0.1 - - [29/Apr/2022 03:47:03] "POST /result HTTP/1.1" 200 -
INFO:werkzeug:127.0.0.1 - - [29/Apr/2022 03:47:03] "[36mGET /static/img/riot.png HTTP/1.1[0m" 304 -
INFO:app:INFO Î†àÎ≤®Î°ú Ï∂úÎ†•
INFO:werkzeug:127.0.0.1 - - [29/Apr/2022 03:47:07] "POST / HTTP/1.1" 200 -
INFO:werkzeug:127.0.0.1 - - [29/Apr/2022 03:47:07] "[36mGET /static/img/riot.png HTTP/1.1[0m" 304 -
DEBUG:urllib3.connectionpool:Starting new HTTPS connection (1): kr.api.riotgames.com:443
DEBUG:urllib3.connectionpool:https://kr.api.riotgames.com:443 "GET /lol/summoner/v4/summoners/by-name/sdfefqefqwefasdf HTTP/1.1" 404 None
INFO:werkzeug:127.0.0.1 - - [29/Apr/2022 03:47:14] "POST /result HTTP/1.1" 200 -
INFO:werkzeug:127.0.0.1 - - [29/Apr/2022 03:47:14] "[36mGET /static/img/riot.png HTTP/1.1[0m" 304 -
INFO:app:INFO Î†àÎ≤®Î°ú Ï∂úÎ†•
INFO:werkzeug:127.0.0.1 - - [29/Apr/2022 03:47:15] "POST / HTTP/1.1" 200 -
INFO:werkzeug:127.0.0.1 - - [29/Apr/2022 03:47:15] "[36mGET /static/img/riot.png HTTP/1.1[0m" 304 -
DEBUG:urllib3.connectionpool:Starting new HTTPS connection (1): kr.api.riotgames.com:443
DEBUG:urllib3.connectionpool:https://kr.api.riotgames.com:443 "GET /lol/summoner/v4/summoners/by-name/%ED%95%AB%EC%83%81%EB%B2%94 HTTP/1.1" 200 None
DEBUG:urllib3.connectionpool:Starting new HTTPS connection (1): kr.api.riotgames.com:443
DEBUG:urllib3.connectionpool:https://kr.api.riotgames.com:443 "GET /lol/summoner/v4/summoners/by-name/%ED%95%AB%EC%83%81%EB%B2%94 HTTP/1.1" 200 None
DEBUG:urllib3.connectionpool:Starting new HTTPS connection (1): kr.api.riotgames.com:443
DEBUG:urllib3.connectionpool:https://kr.api.riotgames.com:443 "GET /lol/champion-mastery/v4/champion-masteries/by-summoner/XnhdEBDrdxzLMqJVhZBnhh6PI5WHJcbU7JZMncss1JBPiw HTTP/1.1" 200 None
DEBUG:urllib3.connectionpool:Starting new HTTPS connection (1): kr.api.riotgames.com:443
DEBUG:urllib3.connectionpool:https://kr.api.riotgames.com:443 "GET /lol/summoner/v4/summoners/by-name/%ED%95%AB%EC%83%81%EB%B2%94 HTTP/1.1" 200 None
DEBUG:urllib3.connectionpool:Starting new HTTPS connection (1): kr.api.riotgames.com:443
DEBUG:urllib3.connectionpool:https://kr.api.riotgames.com:443 "GET /lol/spectator/v4/active-games/by-summoner/XnhdEBDrdxzLMqJVhZBnhh6PI5WHJcbU7JZMncss1JBPiw HTTP/1.1" 503 None
INFO:werkzeug:127.0.0.1 - - [29/Apr/2022 03:47:23] "POST /result HTTP/1.1" 200 -
INFO:werkzeug:127.0.0.1 - - [29/Apr/2022 03:47:23] "[36mGET /static/img/riot.png HTTP/1.1[0m" 304 -
INFO:werkzeug: * Running on http://127.0.0.1:5000/ (Press CTRL+C to quit)
INFO:app:INFO Î†àÎ≤®Î°ú Ï∂úÎ†•
INFO:werkzeug:127.0.0.1 - - [29/Apr/2022 03:48:01] "POST / HTTP/1.1" 200 -
INFO:werkzeug:127.0.0.1 - - [29/Apr/2022 03:48:01] "[36mGET /static/img/riot.png HTTP/1.1[0m" 304 -
DEBUG:urllib3.connectionpool:Starting new HTTPS connection (1): kr.api.riotgames.com:443
DEBUG:urllib3.connectionpool:https://kr.api.riotgames.com:443 "GET /lol/summoner/v4/summoners/by-name/%ED%95%AB%EC%83%81%EB%B2%94 HTTP/1.1" 200 None
DEBUG:urllib3.connectionpool:Starting new HTTPS connection (1): kr.api.riotgames.com:443
DEBUG:urllib3.connectionpool:https://kr.api.riotgames.com:443 "GET /lol/summoner/v4/summoners/by-name/%ED%95%AB%EC%83%81%EB%B2%94 HTTP/1.1" 200 None
DEBUG:urllib3.connectionpool:Starting new HTTPS connection (1): kr.api.riotgames.com:443
DEBUG:urllib3.connectionpool:https://kr.api.riotgames.com:443 "GET /lol/champion-mastery/v4/champion-masteries/by-summoner/XnhdEBDrdxzLMqJVhZBnhh6PI5WHJcbU7JZMncss1JBPiw HTTP/1.1" 200 None
DEBUG:urllib3.connectionpool:Starting new HTTPS connection (1): kr.api.riotgames.com:443
DEBUG:urllib3.connectionpool:https://kr.api.riotgames.com:443 "GET /lol/summoner/v4/summoners/by-name/%ED%95%AB%EC%83%81%EB%B2%94 HTTP/1.1" 200 None
DEBUG:urllib3.connectionpool:Starting new HTTPS connection (1): kr.api.riotgames.com:443
DEBUG:urllib3.connectionpool:https://kr.api.riotgames.com:443 "GET /lol/spectator/v4/active-games/by-summoner/XnhdEBDrdxzLMqJVhZBnhh6PI5WHJcbU7JZMncss1JBPiw HTTP/1.1" 503 None
INFO:werkzeug:127.0.0.1 - - [29/Apr/2022 03:48:12] "POST /result HTTP/1.1" 200 -
INFO:werkzeug:127.0.0.1 - - [29/Apr/2022 03:48:12] "[36mGET /static/img/riot.png HTTP/1.1[0m" 304 -
INFO:werkzeug: * Running on http://127.0.0.1:5000/ (Press CTRL+C to quit)
INFO:app:INFO Î†àÎ≤®Î°ú Ï∂úÎ†•
INFO:werkzeug:127.0.0.1 - - [29/Apr/2022 03:48:57] "POST / HTTP/1.1" 200 -
INFO:werkzeug:127.0.0.1 - - [29/Apr/2022 03:48:57] "[36mGET /static/img/riot.png HTTP/1.1[0m" 304 -
DEBUG:urllib3.connectionpool:Starting new HTTPS connection (1): kr.api.riotgames.com:443
DEBUG:urllib3.connectionpool:https://kr.api.riotgames.com:443 "GET /lol/summoner/v4/summoners/by-name/%ED%95%AB%EC%83%81%EB%B2%94 HTTP/1.1" 200 None
DEBUG:urllib3.connectionpool:Starting new HTTPS connection (1): kr.api.riotgames.com:443
DEBUG:urllib3.connectionpool:https://kr.api.riotgames.com:443 "GET /lol/summoner/v4/summoners/by-name/%ED%95%AB%EC%83%81%EB%B2%94 HTTP/1.1" 200 None
DEBUG:urllib3.connectionpool:Starting new HTTPS connection (1): kr.api.riotgames.com:443
DEBUG:urllib3.connectionpool:https://kr.api.riotgames.com:443 "GET /lol/champion-mastery/v4/champion-masteries/by-summoner/XnhdEBDrdxzLMqJVhZBnhh6PI5WHJcbU7JZMncss1JBPiw HTTP/1.1" 200 None
DEBUG:urllib3.connectionpool:Starting new HTTPS connection (1): kr.api.riotgames.com:443
DEBUG:urllib3.connectionpool:https://kr.api.riotgames.com:443 "GET /lol/summoner/v4/summoners/by-name/%ED%95%AB%EC%83%81%EB%B2%94 HTTP/1.1" 200 None
DEBUG:urllib3.connectionpool:Starting new HTTPS connection (1): kr.api.riotgames.com:443
DEBUG:urllib3.connectionpool:https://kr.api.riotgames.com:443 "GET /lol/spectator/v4/active-games/by-summoner/XnhdEBDrdxzLMqJVhZBnhh6PI5WHJcbU7JZMncss1JBPiw HTTP/1.1" 503 None
INFO:werkzeug:127.0.0.1 - - [29/Apr/2022 03:49:04] "POST /result HTTP/1.1" 200 -
INFO:werkzeug:127.0.0.1 - - [29/Apr/2022 03:49:04] "[36mGET /static/img/riot.png HTTP/1.1[0m" 304 -
INFO:app:INFO Î†àÎ≤®Î°ú Ï∂úÎ†•
INFO:werkzeug:127.0.0.1 - - [29/Apr/2022 03:49:06] "POST / HTTP/1.1" 200 -
INFO:werkzeug:127.0.0.1 - - [29/Apr/2022 03:49:06] "[36mGET /static/img/riot.png HTTP/1.1[0m" 304 -
[2022-04-29 03:49:45,870] INFO in _internal:  * Running on http://127.0.0.1:5000/ (Press CTRL+C to quit)
[2022-04-29 03:49:53,447] INFO in main_views: INFO Î†àÎ≤®Î°ú Ï∂úÎ†•
[2022-04-29 03:49:53,458] INFO in _internal: 127.0.0.1 - - [29/Apr/2022 03:49:53] "POST / HTTP/1.1" 200 -
[2022-04-29 03:49:53,470] INFO in _internal: 127.0.0.1 - - [29/Apr/2022 03:49:53] "[36mGET /static/img/riot.png HTTP/1.1[0m" 304 -
[2022-04-29 03:49:58,612] INFO in main_views: INFO Î†àÎ≤®Î°ú Ï∂úÎ†•
[2022-04-29 03:49:58,613] INFO in _internal: 127.0.0.1 - - [29/Apr/2022 03:49:58] "POST / HTTP/1.1" 200 -
[2022-04-29 03:49:58,625] INFO in _internal: 127.0.0.1 - - [29/Apr/2022 03:49:58] "[36mGET /static/img/riot.png HTTP/1.1[0m" 304 -
[2022-04-29 03:50:02,791] DEBUG in connectionpool: Starting new HTTPS connection (1): kr.api.riotgames.com:443
[2022-04-29 03:50:03,068] DEBUG in connectionpool: https://kr.api.riotgames.com:443 "GET /lol/summoner/v4/summoners/by-name/%ED%95%AB%EC%83%81%EB%B2%94 HTTP/1.1" 200 None
[2022-04-29 03:50:03,082] DEBUG in connectionpool: Starting new HTTPS connection (1): kr.api.riotgames.com:443
[2022-04-29 03:50:03,358] DEBUG in connectionpool: https://kr.api.riotgames.com:443 "GET /lol/summoner/v4/summoners/by-name/%ED%95%AB%EC%83%81%EB%B2%94 HTTP/1.1" 200 None
[2022-04-29 03:50:03,373] DEBUG in connectionpool: Starting new HTTPS connection (1): kr.api.riotgames.com:443
[2022-04-29 03:50:03,659] DEBUG in connectionpool: https://kr.api.riotgames.com:443 "GET /lol/champion-mastery/v4/champion-masteries/by-summoner/XnhdEBDrdxzLMqJVhZBnhh6PI5WHJcbU7JZMncss1JBPiw HTTP/1.1" 200 None
[2022-04-29 03:50:04,529] DEBUG in connectionpool: Starting new HTTPS connection (1): kr.api.riotgames.com:443
[2022-04-29 03:50:05,004] DEBUG in connectionpool: https://kr.api.riotgames.com:443 "GET /lol/summoner/v4/summoners/by-name/%ED%95%AB%EC%83%81%EB%B2%94 HTTP/1.1" 200 None
[2022-04-29 03:50:05,016] DEBUG in connectionpool: Starting new HTTPS connection (1): kr.api.riotgames.com:443
[2022-04-29 03:50:08,362] DEBUG in connectionpool: https://kr.api.riotgames.com:443 "GET /lol/spectator/v4/active-games/by-summoner/XnhdEBDrdxzLMqJVhZBnhh6PI5WHJcbU7JZMncss1JBPiw HTTP/1.1" 503 None
[2022-04-29 03:50:08,754] INFO in _internal: 127.0.0.1 - - [29/Apr/2022 03:50:08] "POST /result HTTP/1.1" 200 -
[2022-04-29 03:50:08,776] INFO in _internal: 127.0.0.1 - - [29/Apr/2022 03:50:08] "[36mGET /static/img/riot.png HTTP/1.1[0m" 304 -
